<mujoco model="panda">
  <compiler angle="radian" meshdir="assets" autolimits="true" />

  <option integrator="implicit" />
  <size nconmax="1000" njmax="10000" nstack="1e9" />

  <default>
    <default class="panda">
      <material specular="0.5" shininess="0.25" />
      <joint armature="0.1" damping="1" axis="0 0 1" range="-2.8973 2.8973" />
      <general dyntype="none" biastype="affine" ctrlrange="-2.8973 2.8973" forcerange="-87 87" />
      <default class="finger">
        <joint axis="0 1 0" type="slide" range="0 0.04" />
      </default>

      <default class="visual">
        <geom type="mesh" contype="0" conaffinity="0" group="2" />
      </default>
      <default class="collision">
        <geom type="mesh" group="3" />
      </default>

      <default class="ik">
        <site type="sphere" size="1e-3" rgba="0.5 0.5 0.5 0.5" group="0" />
      </default>
      <site rgba="0.5 0.5 0.5 0.3" group="1" />
    </default>
  </default>

  <asset>
    <material class="panda" name="white" rgba="1 1 1 1" />
    <material class="panda" name="off_white" rgba="0.901961 0.921569 0.929412 1" />
    <material class="panda" name="black" rgba="0.25 0.25 0.25 1" />
    <material class="panda" name="green" rgba="0 1 0 1" />
    <material class="panda" name="light_blue" rgba="0.039216 0.541176 0.780392 1" />


    <mesh name="link0_c" file="link0.stl" />
    <mesh name="link1_c" file="link1.stl" />
    <mesh name="link2_c" file="link2.stl" />
    <mesh name="link3_c" file="link3.stl" />
    <mesh name="link4_c" file="link4.stl" />
    <mesh name="link5_c0" file="link5_collision_0.obj" />
    <mesh name="link5_c1" file="link5_collision_1.obj" />
    <mesh name="link5_c2" file="link5_collision_2.obj" />
    <mesh name="link6_c" file="link6.stl" />
    <mesh name="link7_c" file="link7.stl" />
    <mesh name="tactile_sensor_base" file="tactile_sensor_base.obj" />


    <mesh file="link0_0.obj" />
    <mesh file="link0_1.obj" />
    <mesh file="link0_2.obj" />
    <mesh file="link0_3.obj" />
    <mesh file="link0_4.obj" />
    <mesh file="link0_5.obj" />
    <mesh file="link0_7.obj" />
    <mesh file="link0_8.obj" />
    <mesh file="link0_9.obj" />
    <mesh file="link0_10.obj" />
    <mesh file="link0_11.obj" />
    <mesh file="link1.obj" />
    <mesh file="link2.obj" />
    <mesh file="link3_0.obj" />
    <mesh file="link3_1.obj" />
    <mesh file="link3_2.obj" />
    <mesh file="link3_3.obj" />
    <mesh file="link4_0.obj" />
    <mesh file="link4_1.obj" />
    <mesh file="link4_2.obj" />
    <mesh file="link4_3.obj" />
    <mesh file="link5_0.obj" />
    <mesh file="link5_1.obj" />
    <mesh file="link5_2.obj" />
    <mesh file="link6_0.obj" />
    <mesh file="link6_1.obj" />
    <mesh file="link6_2.obj" />
    <mesh file="link6_3.obj" />
    <mesh file="link6_4.obj" />
    <mesh file="link6_5.obj" />
    <mesh file="link6_6.obj" />
    <mesh file="link6_7.obj" />
    <mesh file="link6_8.obj" />
    <mesh file="link6_9.obj" />
    <mesh file="link6_10.obj" />
    <mesh file="link6_11.obj" />
    <mesh file="link6_12.obj" />
    <mesh file="link6_13.obj" />
    <mesh file="link6_14.obj" />
    <mesh file="link6_15.obj" />
    <mesh file="link6_16.obj" />
    <mesh file="link7_0.obj" />
    <mesh file="link7_1.obj" />
    <mesh file="link7_2.obj" />
    <mesh file="link7_3.obj" />
    <mesh file="link7_4.obj" />
    <mesh file="link7_5.obj" />
    <mesh file="link7_6.obj" />
    <mesh file="link7_7.obj" />
  </asset>

  <worldbody>
    <light name="top" pos="0 0 2" mode="trackcom" />
    <body name="link0" childclass="panda">
      <inertial mass="0.629769" pos="-0.041018 -0.00014 0.049974" fullinertia="0.00315 0.00388 0.004285 8.2904e-7 0.00015 8.2299e-6" />
      <geom mesh="link0_0" material="off_white" class="visual" />
      <geom mesh="link0_1" material="black" class="visual" />
      <geom mesh="link0_2" material="off_white" class="visual" />
      <geom mesh="link0_3" material="black" class="visual" />
      <geom mesh="link0_4" material="off_white" class="visual" />
      <geom mesh="link0_5" material="black" class="visual" />
      <geom mesh="link0_7" material="white" class="visual" />
      <geom mesh="link0_8" material="white" class="visual" />
      <geom mesh="link0_9" material="black" class="visual" />
      <geom mesh="link0_10" material="off_white" class="visual" />
      <geom mesh="link0_11" material="white" class="visual" />
      <geom mesh="link0_c" class="collision" />
      <body name="link1" pos="0 0 0.333">
        <inertial mass="4.970684" pos="0.003875 0.002081 -0.04762" fullinertia="0.70337 0.70661 0.0091170 -0.00013900 0.0067720 0.019169" />
        <joint name="joint1" />
        <geom material="white" mesh="link1" class="visual" />
        <geom mesh="link1_c" class="collision" />
        <body name="link2" quat="1 -1 0 0">
          <inertial mass="0.646926" pos="-0.003141 -0.02872 0.003495" fullinertia="0.0079620 2.8110e-2 2.5995e-2 -3.925e-3 1.0254e-2 7.04e-4" />
          <joint name="joint2" range="-1.7628 1.7628" />
          <geom material="white" mesh="link2" class="visual" />
          <geom mesh="link2_c" class="collision" />
          <body name="link3" pos="0 -0.316 0" quat="1 1 0 0">
            <joint name="joint3" />
            <inertial mass="3.228604" pos="2.7518e-2 3.9252e-2 -6.6502e-2" fullinertia="3.7242e-2 3.6155e-2 1.083e-2 -4.761e-3 -1.1396e-2 -1.2805e-2" />
            <geom mesh="link3_0" material="white" class="visual" />
            <geom mesh="link3_1" material="white" class="visual" />
            <geom mesh="link3_2" material="white" class="visual" />
            <geom mesh="link3_3" material="black" class="visual" />
            <geom mesh="link3_c" class="collision" />
            <body name="link4" pos="0.0825 0 0" quat="1 1 0 0">
              <inertial mass="3.587895" pos="-5.317e-2 1.04419e-1 2.7454e-2" fullinertia="2.5853e-2 1.9552e-2 2.8323e-2 7.796e-3 -1.332e-3 8.641e-3" />
              <joint name="joint4" range="-3.0718 -0.0698" />
              <geom mesh="link4_0" material="white" class="visual" />
              <geom mesh="link4_1" material="white" class="visual" />
              <geom mesh="link4_2" material="black" class="visual" />
              <geom mesh="link4_3" material="white" class="visual" />
              <geom mesh="link4_c" class="collision" />
              <body name="link5" pos="-0.0825 0.384 0" quat="1 -1 0 0">
                <inertial mass="1.225946" pos="-1.1953e-2 4.1065e-2 -3.8437e-2" fullinertia="3.5549e-2 2.9474e-2 8.627e-3 -2.117e-3 -4.037e-3 2.29e-4" />
                <joint name="joint5" />
                <geom mesh="link5_0" material="black" class="visual" />
                <geom mesh="link5_1" material="white" class="visual" />
                <geom mesh="link5_2" material="white" class="visual" />
                <geom mesh="link5_c0" class="collision" />
                <geom mesh="link5_c1" class="collision" />
                <geom mesh="link5_c2" class="collision" />
                <body name="link6" quat="1 1 0 0">
                  <inertial mass="1.666555" pos="6.0149e-2 -1.4117e-2 -1.0517e-2" fullinertia="1.964e-3 4.354e-3 5.433e-3 1.09e-4 -1.158e-3 3.41e-4" />
                  <joint name="joint6" range="-0.0175 3.7525" />
                  <geom mesh="link6_0" material="off_white" class="visual" />
                  <geom mesh="link6_1" material="white" class="visual" />
                  <geom mesh="link6_2" material="black" class="visual" />
                  <geom mesh="link6_3" material="white" class="visual" />
                  <geom mesh="link6_4" material="white" class="visual" />
                  <geom mesh="link6_5" material="white" class="visual" />
                  <geom mesh="link6_6" material="white" class="visual" />
                  <geom mesh="link6_7" material="light_blue" class="visual" />
                  <geom mesh="link6_8" material="light_blue" class="visual" />
                  <geom mesh="link6_9" material="black" class="visual" />
                  <geom mesh="link6_10" material="black" class="visual" />
                  <geom mesh="link6_11" material="white" class="visual" />
                  <geom mesh="link6_12" material="green" class="visual" />
                  <geom mesh="link6_13" material="white" class="visual" />
                  <geom mesh="link6_14" material="black" class="visual" />
                  <geom mesh="link6_15" material="black" class="visual" />
                  <geom mesh="link6_16" material="white" class="visual" />
                  <geom mesh="link6_c" class="collision" />
                  <body name="link7" pos="0.088 0 0" quat="1 1 0 0">
                    <inertial mass="7.35522e-01" pos="1.0517e-2 -4.252e-3 6.1597e-2" fullinertia="1.2516e-2 1.0027e-2 4.815e-3 -4.28e-4 -1.196e-3 -7.41e-4" />
                    <joint name="joint7" />
                    <geom mesh="link7_0" material="white" class="visual" />
                    <geom mesh="link7_1" material="black" class="visual" />
                    <geom mesh="link7_2" material="black" class="visual" />
                    <geom mesh="link7_3" material="black" class="visual" />
                    <geom mesh="link7_4" material="black" class="visual" />
                    <geom mesh="link7_5" material="black" class="visual" />
                    <geom mesh="link7_6" material="black" class="visual" />
                    <geom mesh="link7_7" material="white" class="visual" />
                    <geom mesh="link7_c" class="collision" />
                    <body name="tactile_sensor" pos="0 0 0.145" euler="3.141593 0 0.785398">
                      <body name="sensor_base" pos="0 0 0" euler="1.570796 0 0">
                        <inertial mass="1e-3" pos="0 0 0" />
                        <geom mesh="tactile_sensor_base" material="white" class="visual" />
                        <geom mesh="tactile_sensor_base" class="collision" />
                        <body name="sensor_pad" pos="0 -0.0045 0" euler="1.570796 0 0">

                          <body name="taxel1" pos="-0.014500 -0.014500 0.000000">
                            <inertial mass="5e-08" pos="0 0 0" fullinertia="1e-6 1e-6 1e-6 0 0 0" />
                            <joint type="slide" axis="0 0 1" springdamper="1e-2 0.5" />
                            <geom type="sphere" size="0.0005" />
                          </body>
                          <body name="taxel2" pos="-0.014500 -0.011278 0.000000">
                            <inertial mass="5e-08" pos="0 0 0" fullinertia="1e-6 1e-6 1e-6 0 0 0" />
                            <joint type="slide" axis="0 0 1" springdamper="1e-2 0.5" />
                            <geom type="sphere" size="0.0005" />
                          </body>
                          <body name="taxel3" pos="-0.014500 -0.008056 0.000000">
                            <inertial mass="5e-08" pos="0 0 0" fullinertia="1e-6 1e-6 1e-6 0 0 0" />
                            <joint type="slide" axis="0 0 1" springdamper="1e-2 0.5" />
                            <geom type="sphere" size="0.0005" />
                          </body>
                          <body name="taxel4" pos="-0.014500 -0.004833 0.000000">
                            <inertial mass="5e-08" pos="0 0 0" fullinertia="1e-6 1e-6 1e-6 0 0 0" />
                            <joint type="slide" axis="0 0 1" springdamper="1e-2 0.5" />
                            <geom type="sphere" size="0.0005" />
                          </body>
                          <body name="taxel5" pos="-0.014500 -0.001611 0.000000">
                            <inertial mass="5e-08" pos="0 0 0" fullinertia="1e-6 1e-6 1e-6 0 0 0" />
                            <joint type="slide" axis="0 0 1" springdamper="1e-2 0.5" />
                            <geom type="sphere" size="0.0005" />
                          </body>
                          <body name="taxel6" pos="-0.014500 0.001611 0.000000">
                            <inertial mass="5e-08" pos="0 0 0" fullinertia="1e-6 1e-6 1e-6 0 0 0" />
                            <joint type="slide" axis="0 0 1" springdamper="1e-2 0.5" />
                            <geom type="sphere" size="0.0005" />
                          </body>
                          <body name="taxel7" pos="-0.014500 0.004833 0.000000">
                            <inertial mass="5e-08" pos="0 0 0" fullinertia="1e-6 1e-6 1e-6 0 0 0" />
                            <joint type="slide" axis="0 0 1" springdamper="1e-2 0.5" />
                            <geom type="sphere" size="0.0005" />
                          </body>
                          <body name="taxel8" pos="-0.014500 0.008056 0.000000">
                            <inertial mass="5e-08" pos="0 0 0" fullinertia="1e-6 1e-6 1e-6 0 0 0" />
                            <joint type="slide" axis="0 0 1" springdamper="1e-2 0.5" />
                            <geom type="sphere" size="0.0005" />
                          </body>
                          <body name="taxel9" pos="-0.014500 0.011278 0.000000">
                            <inertial mass="5e-08" pos="0 0 0" fullinertia="1e-6 1e-6 1e-6 0 0 0" />
                            <joint type="slide" axis="0 0 1" springdamper="1e-2 0.5" />
                            <geom type="sphere" size="0.0005" />
                          </body>
                          <body name="taxel10" pos="-0.014500 0.014500 0.000000">
                            <inertial mass="5e-08" pos="0 0 0" fullinertia="1e-6 1e-6 1e-6 0 0 0" />
                            <joint type="slide" axis="0 0 1" springdamper="1e-2 0.5" />
                            <geom type="sphere" size="0.0005" />
                          </body>
                          <body name="taxel11" pos="-0.011278 -0.014500 0.000000">
                            <inertial mass="5e-08" pos="0 0 0" fullinertia="1e-6 1e-6 1e-6 0 0 0" />
                            <joint type="slide" axis="0 0 1" springdamper="1e-2 0.5" />
                            <geom type="sphere" size="0.0005" />
                          </body>
                          <body name="taxel12" pos="-0.011278 -0.011278 0.000000">
                            <inertial mass="5e-08" pos="0 0 0" fullinertia="1e-6 1e-6 1e-6 0 0 0" />
                            <joint type="slide" axis="0 0 1" springdamper="1e-2 0.5" />
                            <geom type="sphere" size="0.0005" />
                          </body>
                          <body name="taxel13" pos="-0.011278 -0.008056 0.000000">
                            <inertial mass="5e-08" pos="0 0 0" fullinertia="1e-6 1e-6 1e-6 0 0 0" />
                            <joint type="slide" axis="0 0 1" springdamper="1e-2 0.5" />
                            <geom type="sphere" size="0.0005" />
                          </body>
                          <body name="taxel14" pos="-0.011278 -0.004833 0.000000">
                            <inertial mass="5e-08" pos="0 0 0" fullinertia="1e-6 1e-6 1e-6 0 0 0" />
                            <joint type="slide" axis="0 0 1" springdamper="1e-2 0.5" />
                            <geom type="sphere" size="0.0005" />
                          </body>
                          <body name="taxel15" pos="-0.011278 -0.001611 0.000000">
                            <inertial mass="5e-08" pos="0 0 0" fullinertia="1e-6 1e-6 1e-6 0 0 0" />
                            <joint type="slide" axis="0 0 1" springdamper="1e-2 0.5" />
                            <geom type="sphere" size="0.0005" />
                          </body>
                          <body name="taxel16" pos="-0.011278 0.001611 0.000000">
                            <inertial mass="5e-08" pos="0 0 0" fullinertia="1e-6 1e-6 1e-6 0 0 0" />
                            <joint type="slide" axis="0 0 1" springdamper="1e-2 0.5" />
                            <geom type="sphere" size="0.0005" />
                          </body>
                          <body name="taxel17" pos="-0.011278 0.004833 0.000000">
                            <inertial mass="5e-08" pos="0 0 0" fullinertia="1e-6 1e-6 1e-6 0 0 0" />
                            <joint type="slide" axis="0 0 1" springdamper="1e-2 0.5" />
                            <geom type="sphere" size="0.0005" />
                          </body>
                          <body name="taxel18" pos="-0.011278 0.008056 0.000000">
                            <inertial mass="5e-08" pos="0 0 0" fullinertia="1e-6 1e-6 1e-6 0 0 0" />
                            <joint type="slide" axis="0 0 1" springdamper="1e-2 0.5" />
                            <geom type="sphere" size="0.0005" />
                          </body>
                          <body name="taxel19" pos="-0.011278 0.011278 0.000000">
                            <inertial mass="5e-08" pos="0 0 0" fullinertia="1e-6 1e-6 1e-6 0 0 0" />
                            <joint type="slide" axis="0 0 1" springdamper="1e-2 0.5" />
                            <geom type="sphere" size="0.0005" />
                          </body>
                          <body name="taxel20" pos="-0.011278 0.014500 0.000000">
                            <inertial mass="5e-08" pos="0 0 0" fullinertia="1e-6 1e-6 1e-6 0 0 0" />
                            <joint type="slide" axis="0 0 1" springdamper="1e-2 0.5" />
                            <geom type="sphere" size="0.0005" />
                          </body>
                          <body name="taxel21" pos="-0.008056 -0.014500 0.000000">
                            <inertial mass="5e-08" pos="0 0 0" fullinertia="1e-6 1e-6 1e-6 0 0 0" />
                            <joint type="slide" axis="0 0 1" springdamper="1e-2 0.5" />
                            <geom type="sphere" size="0.0005" />
                          </body>
                          <body name="taxel22" pos="-0.008056 -0.011278 0.000000">
                            <inertial mass="5e-08" pos="0 0 0" fullinertia="1e-6 1e-6 1e-6 0 0 0" />
                            <joint type="slide" axis="0 0 1" springdamper="1e-2 0.5" />
                            <geom type="sphere" size="0.0005" />
                          </body>
                          <body name="taxel23" pos="-0.008056 -0.008056 0.000000">
                            <inertial mass="5e-08" pos="0 0 0" fullinertia="1e-6 1e-6 1e-6 0 0 0" />
                            <joint type="slide" axis="0 0 1" springdamper="1e-2 0.5" />
                            <geom type="sphere" size="0.0005" />
                          </body>
                          <body name="taxel24" pos="-0.008056 -0.004833 0.000000">
                            <inertial mass="5e-08" pos="0 0 0" fullinertia="1e-6 1e-6 1e-6 0 0 0" />
                            <joint type="slide" axis="0 0 1" springdamper="1e-2 0.5" />
                            <geom type="sphere" size="0.0005" />
                          </body>
                          <body name="taxel25" pos="-0.008056 -0.001611 0.000000">
                            <inertial mass="5e-08" pos="0 0 0" fullinertia="1e-6 1e-6 1e-6 0 0 0" />
                            <joint type="slide" axis="0 0 1" springdamper="1e-2 0.5" />
                            <geom type="sphere" size="0.0005" />
                          </body>
                          <body name="taxel26" pos="-0.008056 0.001611 0.000000">
                            <inertial mass="5e-08" pos="0 0 0" fullinertia="1e-6 1e-6 1e-6 0 0 0" />
                            <joint type="slide" axis="0 0 1" springdamper="1e-2 0.5" />
                            <geom type="sphere" size="0.0005" />
                          </body>
                          <body name="taxel27" pos="-0.008056 0.004833 0.000000">
                            <inertial mass="5e-08" pos="0 0 0" fullinertia="1e-6 1e-6 1e-6 0 0 0" />
                            <joint type="slide" axis="0 0 1" springdamper="1e-2 0.5" />
                            <geom type="sphere" size="0.0005" />
                          </body>
                          <body name="taxel28" pos="-0.008056 0.008056 0.000000">
                            <inertial mass="5e-08" pos="0 0 0" fullinertia="1e-6 1e-6 1e-6 0 0 0" />
                            <joint type="slide" axis="0 0 1" springdamper="1e-2 0.5" />
                            <geom type="sphere" size="0.0005" />
                          </body>
                          <body name="taxel29" pos="-0.008056 0.011278 0.000000">
                            <inertial mass="5e-08" pos="0 0 0" fullinertia="1e-6 1e-6 1e-6 0 0 0" />
                            <joint type="slide" axis="0 0 1" springdamper="1e-2 0.5" />
                            <geom type="sphere" size="0.0005" />
                          </body>
                          <body name="taxel30" pos="-0.008056 0.014500 0.000000">
                            <inertial mass="5e-08" pos="0 0 0" fullinertia="1e-6 1e-6 1e-6 0 0 0" />
                            <joint type="slide" axis="0 0 1" springdamper="1e-2 0.5" />
                            <geom type="sphere" size="0.0005" />
                          </body>
                          <body name="taxel31" pos="-0.004833 -0.014500 0.000000">
                            <inertial mass="5e-08" pos="0 0 0" fullinertia="1e-6 1e-6 1e-6 0 0 0" />
                            <joint type="slide" axis="0 0 1" springdamper="1e-2 0.5" />
                            <geom type="sphere" size="0.0005" />
                          </body>
                          <body name="taxel32" pos="-0.004833 -0.011278 0.000000">
                            <inertial mass="5e-08" pos="0 0 0" fullinertia="1e-6 1e-6 1e-6 0 0 0" />
                            <joint type="slide" axis="0 0 1" springdamper="1e-2 0.5" />
                            <geom type="sphere" size="0.0005" />
                          </body>
                          <body name="taxel33" pos="-0.004833 -0.008056 0.000000">
                            <inertial mass="5e-08" pos="0 0 0" fullinertia="1e-6 1e-6 1e-6 0 0 0" />
                            <joint type="slide" axis="0 0 1" springdamper="1e-2 0.5" />
                            <geom type="sphere" size="0.0005" />
                          </body>
                          <body name="taxel34" pos="-0.004833 -0.004833 0.000000">
                            <inertial mass="5e-08" pos="0 0 0" fullinertia="1e-6 1e-6 1e-6 0 0 0" />
                            <joint type="slide" axis="0 0 1" springdamper="1e-2 0.5" />
                            <geom type="sphere" size="0.0005" />
                          </body>
                          <body name="taxel35" pos="-0.004833 -0.001611 0.000000">
                            <inertial mass="5e-08" pos="0 0 0" fullinertia="1e-6 1e-6 1e-6 0 0 0" />
                            <joint type="slide" axis="0 0 1" springdamper="1e-2 0.5" />
                            <geom type="sphere" size="0.0005" />
                          </body>
                          <body name="taxel36" pos="-0.004833 0.001611 0.000000">
                            <inertial mass="5e-08" pos="0 0 0" fullinertia="1e-6 1e-6 1e-6 0 0 0" />
                            <joint type="slide" axis="0 0 1" springdamper="1e-2 0.5" />
                            <geom type="sphere" size="0.0005" />
                          </body>
                          <body name="taxel37" pos="-0.004833 0.004833 0.000000">
                            <inertial mass="5e-08" pos="0 0 0" fullinertia="1e-6 1e-6 1e-6 0 0 0" />
                            <joint type="slide" axis="0 0 1" springdamper="1e-2 0.5" />
                            <geom type="sphere" size="0.0005" />
                          </body>
                          <body name="taxel38" pos="-0.004833 0.008056 0.000000">
                            <inertial mass="5e-08" pos="0 0 0" fullinertia="1e-6 1e-6 1e-6 0 0 0" />
                            <joint type="slide" axis="0 0 1" springdamper="1e-2 0.5" />
                            <geom type="sphere" size="0.0005" />
                          </body>
                          <body name="taxel39" pos="-0.004833 0.011278 0.000000">
                            <inertial mass="5e-08" pos="0 0 0" fullinertia="1e-6 1e-6 1e-6 0 0 0" />
                            <joint type="slide" axis="0 0 1" springdamper="1e-2 0.5" />
                            <geom type="sphere" size="0.0005" />
                          </body>
                          <body name="taxel40" pos="-0.004833 0.014500 0.000000">
                            <inertial mass="5e-08" pos="0 0 0" fullinertia="1e-6 1e-6 1e-6 0 0 0" />
                            <joint type="slide" axis="0 0 1" springdamper="1e-2 0.5" />
                            <geom type="sphere" size="0.0005" />
                          </body>
                          <body name="taxel41" pos="-0.001611 -0.014500 0.000000">
                            <inertial mass="5e-08" pos="0 0 0" fullinertia="1e-6 1e-6 1e-6 0 0 0" />
                            <joint type="slide" axis="0 0 1" springdamper="1e-2 0.5" />
                            <geom type="sphere" size="0.0005" />
                          </body>
                          <body name="taxel42" pos="-0.001611 -0.011278 0.000000">
                            <inertial mass="5e-08" pos="0 0 0" fullinertia="1e-6 1e-6 1e-6 0 0 0" />
                            <joint type="slide" axis="0 0 1" springdamper="1e-2 0.5" />
                            <geom type="sphere" size="0.0005" />
                          </body>
                          <body name="taxel43" pos="-0.001611 -0.008056 0.000000">
                            <inertial mass="5e-08" pos="0 0 0" fullinertia="1e-6 1e-6 1e-6 0 0 0" />
                            <joint type="slide" axis="0 0 1" springdamper="1e-2 0.5" />
                            <geom type="sphere" size="0.0005" />
                          </body>
                          <body name="taxel44" pos="-0.001611 -0.004833 0.000000">
                            <inertial mass="5e-08" pos="0 0 0" fullinertia="1e-6 1e-6 1e-6 0 0 0" />
                            <joint type="slide" axis="0 0 1" springdamper="1e-2 0.5" />
                            <geom type="sphere" size="0.0005" />
                          </body>
                          <body name="taxel45" pos="-0.001611 -0.001611 0.000000">
                            <inertial mass="5e-08" pos="0 0 0" fullinertia="1e-6 1e-6 1e-6 0 0 0" />
                            <joint type="slide" axis="0 0 1" springdamper="1e-2 0.5" />
                            <geom type="sphere" size="0.0005" />
                          </body>
                          <body name="taxel46" pos="-0.001611 0.001611 0.000000">
                            <inertial mass="5e-08" pos="0 0 0" fullinertia="1e-6 1e-6 1e-6 0 0 0" />
                            <joint type="slide" axis="0 0 1" springdamper="1e-2 0.5" />
                            <geom type="sphere" size="0.0005" />
                          </body>
                          <body name="taxel47" pos="-0.001611 0.004833 0.000000">
                            <inertial mass="5e-08" pos="0 0 0" fullinertia="1e-6 1e-6 1e-6 0 0 0" />
                            <joint type="slide" axis="0 0 1" springdamper="1e-2 0.5" />
                            <geom type="sphere" size="0.0005" />
                          </body>
                          <body name="taxel48" pos="-0.001611 0.008056 0.000000">
                            <inertial mass="5e-08" pos="0 0 0" fullinertia="1e-6 1e-6 1e-6 0 0 0" />
                            <joint type="slide" axis="0 0 1" springdamper="1e-2 0.5" />
                            <geom type="sphere" size="0.0005" />
                          </body>
                          <body name="taxel49" pos="-0.001611 0.011278 0.000000">
                            <inertial mass="5e-08" pos="0 0 0" fullinertia="1e-6 1e-6 1e-6 0 0 0" />
                            <joint type="slide" axis="0 0 1" springdamper="1e-2 0.5" />
                            <geom type="sphere" size="0.0005" />
                          </body>
                          <body name="taxel50" pos="-0.001611 0.014500 0.000000">
                            <inertial mass="5e-08" pos="0 0 0" fullinertia="1e-6 1e-6 1e-6 0 0 0" />
                            <joint type="slide" axis="0 0 1" springdamper="1e-2 0.5" />
                            <geom type="sphere" size="0.0005" />
                          </body>
                          <body name="taxel51" pos="0.001611 -0.014500 0.000000">
                            <inertial mass="5e-08" pos="0 0 0" fullinertia="1e-6 1e-6 1e-6 0 0 0" />
                            <joint type="slide" axis="0 0 1" springdamper="1e-2 0.5" />
                            <geom type="sphere" size="0.0005" />
                          </body>
                          <body name="taxel52" pos="0.001611 -0.011278 0.000000">
                            <inertial mass="5e-08" pos="0 0 0" fullinertia="1e-6 1e-6 1e-6 0 0 0" />
                            <joint type="slide" axis="0 0 1" springdamper="1e-2 0.5" />
                            <geom type="sphere" size="0.0005" />
                          </body>
                          <body name="taxel53" pos="0.001611 -0.008056 0.000000">
                            <inertial mass="5e-08" pos="0 0 0" fullinertia="1e-6 1e-6 1e-6 0 0 0" />
                            <joint type="slide" axis="0 0 1" springdamper="1e-2 0.5" />
                            <geom type="sphere" size="0.0005" />
                          </body>
                          <body name="taxel54" pos="0.001611 -0.004833 0.000000">
                            <inertial mass="5e-08" pos="0 0 0" fullinertia="1e-6 1e-6 1e-6 0 0 0" />
                            <joint type="slide" axis="0 0 1" springdamper="1e-2 0.5" />
                            <geom type="sphere" size="0.0005" />
                          </body>
                          <body name="taxel55" pos="0.001611 -0.001611 0.000000">
                            <inertial mass="5e-08" pos="0 0 0" fullinertia="1e-6 1e-6 1e-6 0 0 0" />
                            <joint type="slide" axis="0 0 1" springdamper="1e-2 0.5" />
                            <geom type="sphere" size="0.0005" />
                          </body>
                          <body name="taxel56" pos="0.001611 0.001611 0.000000">
                            <inertial mass="5e-08" pos="0 0 0" fullinertia="1e-6 1e-6 1e-6 0 0 0" />
                            <joint type="slide" axis="0 0 1" springdamper="1e-2 0.5" />
                            <geom type="sphere" size="0.0005" />
                          </body>
                          <body name="taxel57" pos="0.001611 0.004833 0.000000">
                            <inertial mass="5e-08" pos="0 0 0" fullinertia="1e-6 1e-6 1e-6 0 0 0" />
                            <joint type="slide" axis="0 0 1" springdamper="1e-2 0.5" />
                            <geom type="sphere" size="0.0005" />
                          </body>
                          <body name="taxel58" pos="0.001611 0.008056 0.000000">
                            <inertial mass="5e-08" pos="0 0 0" fullinertia="1e-6 1e-6 1e-6 0 0 0" />
                            <joint type="slide" axis="0 0 1" springdamper="1e-2 0.5" />
                            <geom type="sphere" size="0.0005" />
                          </body>
                          <body name="taxel59" pos="0.001611 0.011278 0.000000">
                            <inertial mass="5e-08" pos="0 0 0" fullinertia="1e-6 1e-6 1e-6 0 0 0" />
                            <joint type="slide" axis="0 0 1" springdamper="1e-2 0.5" />
                            <geom type="sphere" size="0.0005" />
                          </body>
                          <body name="taxel60" pos="0.001611 0.014500 0.000000">
                            <inertial mass="5e-08" pos="0 0 0" fullinertia="1e-6 1e-6 1e-6 0 0 0" />
                            <joint type="slide" axis="0 0 1" springdamper="1e-2 0.5" />
                            <geom type="sphere" size="0.0005" />
                          </body>
                          <body name="taxel61" pos="0.004833 -0.014500 0.000000">
                            <inertial mass="5e-08" pos="0 0 0" fullinertia="1e-6 1e-6 1e-6 0 0 0" />
                            <joint type="slide" axis="0 0 1" springdamper="1e-2 0.5" />
                            <geom type="sphere" size="0.0005" />
                          </body>
                          <body name="taxel62" pos="0.004833 -0.011278 0.000000">
                            <inertial mass="5e-08" pos="0 0 0" fullinertia="1e-6 1e-6 1e-6 0 0 0" />
                            <joint type="slide" axis="0 0 1" springdamper="1e-2 0.5" />
                            <geom type="sphere" size="0.0005" />
                          </body>
                          <body name="taxel63" pos="0.004833 -0.008056 0.000000">
                            <inertial mass="5e-08" pos="0 0 0" fullinertia="1e-6 1e-6 1e-6 0 0 0" />
                            <joint type="slide" axis="0 0 1" springdamper="1e-2 0.5" />
                            <geom type="sphere" size="0.0005" />
                          </body>
                          <body name="taxel64" pos="0.004833 -0.004833 0.000000">
                            <inertial mass="5e-08" pos="0 0 0" fullinertia="1e-6 1e-6 1e-6 0 0 0" />
                            <joint type="slide" axis="0 0 1" springdamper="1e-2 0.5" />
                            <geom type="sphere" size="0.0005" />
                          </body>
                          <body name="taxel65" pos="0.004833 -0.001611 0.000000">
                            <inertial mass="5e-08" pos="0 0 0" fullinertia="1e-6 1e-6 1e-6 0 0 0" />
                            <joint type="slide" axis="0 0 1" springdamper="1e-2 0.5" />
                            <geom type="sphere" size="0.0005" />
                          </body>
                          <body name="taxel66" pos="0.004833 0.001611 0.000000">
                            <inertial mass="5e-08" pos="0 0 0" fullinertia="1e-6 1e-6 1e-6 0 0 0" />
                            <joint type="slide" axis="0 0 1" springdamper="1e-2 0.5" />
                            <geom type="sphere" size="0.0005" />
                          </body>
                          <body name="taxel67" pos="0.004833 0.004833 0.000000">
                            <inertial mass="5e-08" pos="0 0 0" fullinertia="1e-6 1e-6 1e-6 0 0 0" />
                            <joint type="slide" axis="0 0 1" springdamper="1e-2 0.5" />
                            <geom type="sphere" size="0.0005" />
                          </body>
                          <body name="taxel68" pos="0.004833 0.008056 0.000000">
                            <inertial mass="5e-08" pos="0 0 0" fullinertia="1e-6 1e-6 1e-6 0 0 0" />
                            <joint type="slide" axis="0 0 1" springdamper="1e-2 0.5" />
                            <geom type="sphere" size="0.0005" />
                          </body>
                          <body name="taxel69" pos="0.004833 0.011278 0.000000">
                            <inertial mass="5e-08" pos="0 0 0" fullinertia="1e-6 1e-6 1e-6 0 0 0" />
                            <joint type="slide" axis="0 0 1" springdamper="1e-2 0.5" />
                            <geom type="sphere" size="0.0005" />
                          </body>
                          <body name="taxel70" pos="0.004833 0.014500 0.000000">
                            <inertial mass="5e-08" pos="0 0 0" fullinertia="1e-6 1e-6 1e-6 0 0 0" />
                            <joint type="slide" axis="0 0 1" springdamper="1e-2 0.5" />
                            <geom type="sphere" size="0.0005" />
                          </body>
                          <body name="taxel71" pos="0.008056 -0.014500 0.000000">
                            <inertial mass="5e-08" pos="0 0 0" fullinertia="1e-6 1e-6 1e-6 0 0 0" />
                            <joint type="slide" axis="0 0 1" springdamper="1e-2 0.5" />
                            <geom type="sphere" size="0.0005" />
                          </body>
                          <body name="taxel72" pos="0.008056 -0.011278 0.000000">
                            <inertial mass="5e-08" pos="0 0 0" fullinertia="1e-6 1e-6 1e-6 0 0 0" />
                            <joint type="slide" axis="0 0 1" springdamper="1e-2 0.5" />
                            <geom type="sphere" size="0.0005" />
                          </body>
                          <body name="taxel73" pos="0.008056 -0.008056 0.000000">
                            <inertial mass="5e-08" pos="0 0 0" fullinertia="1e-6 1e-6 1e-6 0 0 0" />
                            <joint type="slide" axis="0 0 1" springdamper="1e-2 0.5" />
                            <geom type="sphere" size="0.0005" />
                          </body>
                          <body name="taxel74" pos="0.008056 -0.004833 0.000000">
                            <inertial mass="5e-08" pos="0 0 0" fullinertia="1e-6 1e-6 1e-6 0 0 0" />
                            <joint type="slide" axis="0 0 1" springdamper="1e-2 0.5" />
                            <geom type="sphere" size="0.0005" />
                          </body>
                          <body name="taxel75" pos="0.008056 -0.001611 0.000000">
                            <inertial mass="5e-08" pos="0 0 0" fullinertia="1e-6 1e-6 1e-6 0 0 0" />
                            <joint type="slide" axis="0 0 1" springdamper="1e-2 0.5" />
                            <geom type="sphere" size="0.0005" />
                          </body>
                          <body name="taxel76" pos="0.008056 0.001611 0.000000">
                            <inertial mass="5e-08" pos="0 0 0" fullinertia="1e-6 1e-6 1e-6 0 0 0" />
                            <joint type="slide" axis="0 0 1" springdamper="1e-2 0.5" />
                            <geom type="sphere" size="0.0005" />
                          </body>
                          <body name="taxel77" pos="0.008056 0.004833 0.000000">
                            <inertial mass="5e-08" pos="0 0 0" fullinertia="1e-6 1e-6 1e-6 0 0 0" />
                            <joint type="slide" axis="0 0 1" springdamper="1e-2 0.5" />
                            <geom type="sphere" size="0.0005" />
                          </body>
                          <body name="taxel78" pos="0.008056 0.008056 0.000000">
                            <inertial mass="5e-08" pos="0 0 0" fullinertia="1e-6 1e-6 1e-6 0 0 0" />
                            <joint type="slide" axis="0 0 1" springdamper="1e-2 0.5" />
                            <geom type="sphere" size="0.0005" />
                          </body>
                          <body name="taxel79" pos="0.008056 0.011278 0.000000">
                            <inertial mass="5e-08" pos="0 0 0" fullinertia="1e-6 1e-6 1e-6 0 0 0" />
                            <joint type="slide" axis="0 0 1" springdamper="1e-2 0.5" />
                            <geom type="sphere" size="0.0005" />
                          </body>
                          <body name="taxel80" pos="0.008056 0.014500 0.000000">
                            <inertial mass="5e-08" pos="0 0 0" fullinertia="1e-6 1e-6 1e-6 0 0 0" />
                            <joint type="slide" axis="0 0 1" springdamper="1e-2 0.5" />
                            <geom type="sphere" size="0.0005" />
                          </body>
                          <body name="taxel81" pos="0.011278 -0.014500 0.000000">
                            <inertial mass="5e-08" pos="0 0 0" fullinertia="1e-6 1e-6 1e-6 0 0 0" />
                            <joint type="slide" axis="0 0 1" springdamper="1e-2 0.5" />
                            <geom type="sphere" size="0.0005" />
                          </body>
                          <body name="taxel82" pos="0.011278 -0.011278 0.000000">
                            <inertial mass="5e-08" pos="0 0 0" fullinertia="1e-6 1e-6 1e-6 0 0 0" />
                            <joint type="slide" axis="0 0 1" springdamper="1e-2 0.5" />
                            <geom type="sphere" size="0.0005" />
                          </body>
                          <body name="taxel83" pos="0.011278 -0.008056 0.000000">
                            <inertial mass="5e-08" pos="0 0 0" fullinertia="1e-6 1e-6 1e-6 0 0 0" />
                            <joint type="slide" axis="0 0 1" springdamper="1e-2 0.5" />
                            <geom type="sphere" size="0.0005" />
                          </body>
                          <body name="taxel84" pos="0.011278 -0.004833 0.000000">
                            <inertial mass="5e-08" pos="0 0 0" fullinertia="1e-6 1e-6 1e-6 0 0 0" />
                            <joint type="slide" axis="0 0 1" springdamper="1e-2 0.5" />
                            <geom type="sphere" size="0.0005" />
                          </body>
                          <body name="taxel85" pos="0.011278 -0.001611 0.000000">
                            <inertial mass="5e-08" pos="0 0 0" fullinertia="1e-6 1e-6 1e-6 0 0 0" />
                            <joint type="slide" axis="0 0 1" springdamper="1e-2 0.5" />
                            <geom type="sphere" size="0.0005" />
                          </body>
                          <body name="taxel86" pos="0.011278 0.001611 0.000000">
                            <inertial mass="5e-08" pos="0 0 0" fullinertia="1e-6 1e-6 1e-6 0 0 0" />
                            <joint type="slide" axis="0 0 1" springdamper="1e-2 0.5" />
                            <geom type="sphere" size="0.0005" />
                          </body>
                          <body name="taxel87" pos="0.011278 0.004833 0.000000">
                            <inertial mass="5e-08" pos="0 0 0" fullinertia="1e-6 1e-6 1e-6 0 0 0" />
                            <joint type="slide" axis="0 0 1" springdamper="1e-2 0.5" />
                            <geom type="sphere" size="0.0005" />
                          </body>
                          <body name="taxel88" pos="0.011278 0.008056 0.000000">
                            <inertial mass="5e-08" pos="0 0 0" fullinertia="1e-6 1e-6 1e-6 0 0 0" />
                            <joint type="slide" axis="0 0 1" springdamper="1e-2 0.5" />
                            <geom type="sphere" size="0.0005" />
                          </body>
                          <body name="taxel89" pos="0.011278 0.011278 0.000000">
                            <inertial mass="5e-08" pos="0 0 0" fullinertia="1e-6 1e-6 1e-6 0 0 0" />
                            <joint type="slide" axis="0 0 1" springdamper="1e-2 0.5" />
                            <geom type="sphere" size="0.0005" />
                          </body>
                          <body name="taxel90" pos="0.011278 0.014500 0.000000">
                            <inertial mass="5e-08" pos="0 0 0" fullinertia="1e-6 1e-6 1e-6 0 0 0" />
                            <joint type="slide" axis="0 0 1" springdamper="1e-2 0.5" />
                            <geom type="sphere" size="0.0005" />
                          </body>
                          <body name="taxel91" pos="0.014500 -0.014500 0.000000">
                            <inertial mass="5e-08" pos="0 0 0" fullinertia="1e-6 1e-6 1e-6 0 0 0" />
                            <joint type="slide" axis="0 0 1" springdamper="1e-2 0.5" />
                            <geom type="sphere" size="0.0005" />
                          </body>
                          <body name="taxel92" pos="0.014500 -0.011278 0.000000">
                            <inertial mass="5e-08" pos="0 0 0" fullinertia="1e-6 1e-6 1e-6 0 0 0" />
                            <joint type="slide" axis="0 0 1" springdamper="1e-2 0.5" />
                            <geom type="sphere" size="0.0005" />
                          </body>
                          <body name="taxel93" pos="0.014500 -0.008056 0.000000">
                            <inertial mass="5e-08" pos="0 0 0" fullinertia="1e-6 1e-6 1e-6 0 0 0" />
                            <joint type="slide" axis="0 0 1" springdamper="1e-2 0.5" />
                            <geom type="sphere" size="0.0005" />
                          </body>
                          <body name="taxel94" pos="0.014500 -0.004833 0.000000">
                            <inertial mass="5e-08" pos="0 0 0" fullinertia="1e-6 1e-6 1e-6 0 0 0" />
                            <joint type="slide" axis="0 0 1" springdamper="1e-2 0.5" />
                            <geom type="sphere" size="0.0005" />
                          </body>
                          <body name="taxel95" pos="0.014500 -0.001611 0.000000">
                            <inertial mass="5e-08" pos="0 0 0" fullinertia="1e-6 1e-6 1e-6 0 0 0" />
                            <joint type="slide" axis="0 0 1" springdamper="1e-2 0.5" />
                            <geom type="sphere" size="0.0005" />
                          </body>
                          <body name="taxel96" pos="0.014500 0.001611 0.000000">
                            <inertial mass="5e-08" pos="0 0 0" fullinertia="1e-6 1e-6 1e-6 0 0 0" />
                            <joint type="slide" axis="0 0 1" springdamper="1e-2 0.5" />
                            <geom type="sphere" size="0.0005" />
                          </body>
                          <body name="taxel97" pos="0.014500 0.004833 0.000000">
                            <inertial mass="5e-08" pos="0 0 0" fullinertia="1e-6 1e-6 1e-6 0 0 0" />
                            <joint type="slide" axis="0 0 1" springdamper="1e-2 0.5" />
                            <geom type="sphere" size="0.0005" />
                          </body>
                          <body name="taxel98" pos="0.014500 0.008056 0.000000">
                            <inertial mass="5e-08" pos="0 0 0" fullinertia="1e-6 1e-6 1e-6 0 0 0" />
                            <joint type="slide" axis="0 0 1" springdamper="1e-2 0.5" />
                            <geom type="sphere" size="0.0005" />
                          </body>
                          <body name="taxel99" pos="0.014500 0.011278 0.000000">
                            <inertial mass="5e-08" pos="0 0 0" fullinertia="1e-6 1e-6 1e-6 0 0 0" />
                            <joint type="slide" axis="0 0 1" springdamper="1e-2 0.5" />
                            <geom type="sphere" size="0.0005" />
                          </body>
                          <body name="taxel100" pos="0.014500 0.014500 0.000000">
                            <inertial mass="5e-08" pos="0 0 0" fullinertia="1e-6 1e-6 1e-6 0 0 0" />
                            <joint type="slide" axis="0 0 1" springdamper="1e-2 0.5" />
                            <geom type="sphere" size="0.0005" />
                          </body>
                        </body>
                      </body>
                      <site name="attachment_site" pos="0 0 -1.5e-3" class="ik" />
                    </body>
                  </body>
                </body>
              </body>
            </body>
          </body>
        </body>
      </body>
    </body>
  </worldbody>

  <actuator>
    <general class="panda" name="actuator1" joint="joint1" gainprm="4500" biasprm="0 -4500 -450" />
    <general class="panda" name="actuator2" joint="joint2" gainprm="4500" biasprm="0 -4500 -450" ctrlrange="-1.7628 1.7628" />
    <general class="panda" name="actuator3" joint="joint3" gainprm="3500" biasprm="0 -3500 -350" />
    <general class="panda" name="actuator4" joint="joint4" gainprm="3500" biasprm="0 -3500 -350" ctrlrange="-3.0718 -0.0698" />
    <general class="panda" name="actuator5" joint="joint5" gainprm="2000" biasprm="0 -2000 -200" forcerange="-12 12" />
    <general class="panda" name="actuator6" joint="joint6" gainprm="2000" biasprm="0 -2000 -200" forcerange="-12 12" ctrlrange="-0.0175 3.7525" />
    <general class="panda" name="actuator7" joint="joint7" gainprm="2000" biasprm="0 -2000 -200" forcerange="-12 12" />
  </actuator>

  <sensor />
</mujoco>