<mujoco model="panda">
  <compiler angle="radian" meshdir="assets" autolimits="true" />

  <option integrator="implicit" />
  <size nconmax="1000" njmax="10000" nstack="1e9" />

  <default>
    <default class="panda">
      <material specular="0.5" shininess="0.25" />
      <joint armature="0.1" damping="1" axis="0 0 1" range="-2.8973 2.8973" />
      <general dyntype="none" biastype="affine" ctrlrange="-2.8973 2.8973" forcerange="-87 87" />
      <default class="finger">
        <joint axis="0 1 0" type="slide" range="0 0.04" />
      </default>

      <default class="visual">
        <geom type="mesh" contype="0" conaffinity="0" group="2" />
      </default>
      <default class="collision">
        <geom type="mesh" group="3" />
      </default>

      <default class="ik">
        <site type="sphere" size="1e-3" rgba="0.5 0.5 0.5 0.5" group="0" />
      </default>
      <site rgba="0.5 0.5 0.5 0.3" group="1" />
    </default>
  </default>

  <asset>
    <material class="panda" name="white" rgba="1 1 1 1" />
    <material class="panda" name="off_white" rgba="0.901961 0.921569 0.929412 1" />
    <material class="panda" name="black" rgba="0.25 0.25 0.25 1" />
    <material class="panda" name="green" rgba="0 1 0 1" />
    <material class="panda" name="light_blue" rgba="0.039216 0.541176 0.780392 1" />


    <mesh name="link0_c" file="link0.stl" />
    <mesh name="link1_c" file="link1.stl" />
    <mesh name="link2_c" file="link2.stl" />
    <mesh name="link3_c" file="link3.stl" />
    <mesh name="link4_c" file="link4.stl" />
    <mesh name="link5_c0" file="link5_collision_0.obj" />
    <mesh name="link5_c1" file="link5_collision_1.obj" />
    <mesh name="link5_c2" file="link5_collision_2.obj" />
    <mesh name="link6_c" file="link6.stl" />
    <mesh name="link7_c" file="link7.stl" />
    <mesh name="tactile_sensor_base" file="tactile_sensor_base.obj" />


    <mesh file="link0_0.obj" />
    <mesh file="link0_1.obj" />
    <mesh file="link0_2.obj" />
    <mesh file="link0_3.obj" />
    <mesh file="link0_4.obj" />
    <mesh file="link0_5.obj" />
    <mesh file="link0_7.obj" />
    <mesh file="link0_8.obj" />
    <mesh file="link0_9.obj" />
    <mesh file="link0_10.obj" />
    <mesh file="link0_11.obj" />
    <mesh file="link1.obj" />
    <mesh file="link2.obj" />
    <mesh file="link3_0.obj" />
    <mesh file="link3_1.obj" />
    <mesh file="link3_2.obj" />
    <mesh file="link3_3.obj" />
    <mesh file="link4_0.obj" />
    <mesh file="link4_1.obj" />
    <mesh file="link4_2.obj" />
    <mesh file="link4_3.obj" />
    <mesh file="link5_0.obj" />
    <mesh file="link5_1.obj" />
    <mesh file="link5_2.obj" />
    <mesh file="link6_0.obj" />
    <mesh file="link6_1.obj" />
    <mesh file="link6_2.obj" />
    <mesh file="link6_3.obj" />
    <mesh file="link6_4.obj" />
    <mesh file="link6_5.obj" />
    <mesh file="link6_6.obj" />
    <mesh file="link6_7.obj" />
    <mesh file="link6_8.obj" />
    <mesh file="link6_9.obj" />
    <mesh file="link6_10.obj" />
    <mesh file="link6_11.obj" />
    <mesh file="link6_12.obj" />
    <mesh file="link6_13.obj" />
    <mesh file="link6_14.obj" />
    <mesh file="link6_15.obj" />
    <mesh file="link6_16.obj" />
    <mesh file="link7_0.obj" />
    <mesh file="link7_1.obj" />
    <mesh file="link7_2.obj" />
    <mesh file="link7_3.obj" />
    <mesh file="link7_4.obj" />
    <mesh file="link7_5.obj" />
    <mesh file="link7_6.obj" />
    <mesh file="link7_7.obj" />
  </asset>

  <worldbody>
    <light name="top" pos="0 0 2" mode="trackcom" />
    <body name="link0" childclass="panda">
      <inertial mass="0.629769" pos="-0.041018 -0.00014 0.049974" fullinertia="0.00315 0.00388 0.004285 8.2904e-7 0.00015 8.2299e-6" />
      <geom mesh="link0_0" material="off_white" class="visual" />
      <geom mesh="link0_1" material="black" class="visual" />
      <geom mesh="link0_2" material="off_white" class="visual" />
      <geom mesh="link0_3" material="black" class="visual" />
      <geom mesh="link0_4" material="off_white" class="visual" />
      <geom mesh="link0_5" material="black" class="visual" />
      <geom mesh="link0_7" material="white" class="visual" />
      <geom mesh="link0_8" material="white" class="visual" />
      <geom mesh="link0_9" material="black" class="visual" />
      <geom mesh="link0_10" material="off_white" class="visual" />
      <geom mesh="link0_11" material="white" class="visual" />
      <geom mesh="link0_c" class="collision" />
      <body name="link1" pos="0 0 0.333">
        <inertial mass="4.970684" pos="0.003875 0.002081 -0.04762" fullinertia="0.70337 0.70661 0.0091170 -0.00013900 0.0067720 0.019169" />
        <joint name="joint1" />
        <geom material="white" mesh="link1" class="visual" />
        <geom mesh="link1_c" class="collision" />
        <body name="link2" quat="1 -1 0 0">
          <inertial mass="0.646926" pos="-0.003141 -0.02872 0.003495" fullinertia="0.0079620 2.8110e-2 2.5995e-2 -3.925e-3 1.0254e-2 7.04e-4" />
          <joint name="joint2" range="-1.7628 1.7628" />
          <geom material="white" mesh="link2" class="visual" />
          <geom mesh="link2_c" class="collision" />
          <body name="link3" pos="0 -0.316 0" quat="1 1 0 0">
            <joint name="joint3" />
            <inertial mass="3.228604" pos="2.7518e-2 3.9252e-2 -6.6502e-2" fullinertia="3.7242e-2 3.6155e-2 1.083e-2 -4.761e-3 -1.1396e-2 -1.2805e-2" />
            <geom mesh="link3_0" material="white" class="visual" />
            <geom mesh="link3_1" material="white" class="visual" />
            <geom mesh="link3_2" material="white" class="visual" />
            <geom mesh="link3_3" material="black" class="visual" />
            <geom mesh="link3_c" class="collision" />
            <body name="link4" pos="0.0825 0 0" quat="1 1 0 0">
              <inertial mass="3.587895" pos="-5.317e-2 1.04419e-1 2.7454e-2" fullinertia="2.5853e-2 1.9552e-2 2.8323e-2 7.796e-3 -1.332e-3 8.641e-3" />
              <joint name="joint4" range="-3.0718 -0.0698" />
              <geom mesh="link4_0" material="white" class="visual" />
              <geom mesh="link4_1" material="white" class="visual" />
              <geom mesh="link4_2" material="black" class="visual" />
              <geom mesh="link4_3" material="white" class="visual" />
              <geom mesh="link4_c" class="collision" />
              <body name="link5" pos="-0.0825 0.384 0" quat="1 -1 0 0">
                <inertial mass="1.225946" pos="-1.1953e-2 4.1065e-2 -3.8437e-2" fullinertia="3.5549e-2 2.9474e-2 8.627e-3 -2.117e-3 -4.037e-3 2.29e-4" />
                <joint name="joint5" />
                <geom mesh="link5_0" material="black" class="visual" />
                <geom mesh="link5_1" material="white" class="visual" />
                <geom mesh="link5_2" material="white" class="visual" />
                <geom mesh="link5_c0" class="collision" />
                <geom mesh="link5_c1" class="collision" />
                <geom mesh="link5_c2" class="collision" />
                <body name="link6" quat="1 1 0 0">
                  <inertial mass="1.666555" pos="6.0149e-2 -1.4117e-2 -1.0517e-2" fullinertia="1.964e-3 4.354e-3 5.433e-3 1.09e-4 -1.158e-3 3.41e-4" />
                  <joint name="joint6" range="-0.0175 3.7525" />
                  <geom mesh="link6_0" material="off_white" class="visual" />
                  <geom mesh="link6_1" material="white" class="visual" />
                  <geom mesh="link6_2" material="black" class="visual" />
                  <geom mesh="link6_3" material="white" class="visual" />
                  <geom mesh="link6_4" material="white" class="visual" />
                  <geom mesh="link6_5" material="white" class="visual" />
                  <geom mesh="link6_6" material="white" class="visual" />
                  <geom mesh="link6_7" material="light_blue" class="visual" />
                  <geom mesh="link6_8" material="light_blue" class="visual" />
                  <geom mesh="link6_9" material="black" class="visual" />
                  <geom mesh="link6_10" material="black" class="visual" />
                  <geom mesh="link6_11" material="white" class="visual" />
                  <geom mesh="link6_12" material="green" class="visual" />
                  <geom mesh="link6_13" material="white" class="visual" />
                  <geom mesh="link6_14" material="black" class="visual" />
                  <geom mesh="link6_15" material="black" class="visual" />
                  <geom mesh="link6_16" material="white" class="visual" />
                  <geom mesh="link6_c" class="collision" />
                  <body name="link7" pos="0.088 0 0" quat="1 1 0 0">
                    <inertial mass="7.35522e-01" pos="1.0517e-2 -4.252e-3 6.1597e-2" fullinertia="1.2516e-2 1.0027e-2 4.815e-3 -4.28e-4 -1.196e-3 -7.41e-4" />
                    <joint name="joint7" />
                    <geom mesh="link7_0" material="white" class="visual" />
                    <geom mesh="link7_1" material="black" class="visual" />
                    <geom mesh="link7_2" material="black" class="visual" />
                    <geom mesh="link7_3" material="black" class="visual" />
                    <geom mesh="link7_4" material="black" class="visual" />
                    <geom mesh="link7_5" material="black" class="visual" />
                    <geom mesh="link7_6" material="black" class="visual" />
                    <geom mesh="link7_7" material="white" class="visual" />
                    <geom mesh="link7_c" class="collision" />
                    <body name="tactile_sensor" pos="0 0 0.145" euler="3.141593 0 0.785398">
                      <body name="sensor_base" pos="0 0 0" euler="1.570796 0 0">
                        <inertial mass="1e-3" pos="0 0 0" />
                        <geom mesh="tactile_sensor_base" material="white" class="visual" />
                        <geom mesh="tactile_sensor_base" class="collision" />
                        <body name="sensor_pad" pos="0 -0.0045 0" euler="1.570796 0 0">
                          <geom name="pad" type="box" pos="0 0 -5e-4" size="1.5e-2 1.5e-2 2e-3" contype="0" conaffinity="0" group="2" rgba="0.5 0.3 0.2 0.9" />
                          <body name="taxel1" pos="-0.014500 -0.014500 0.000000"><inertial mass="5e-08" pos="0 0 0" fullinertia="1e-6 1e-6 1e-6 0 0 0" /><joint type="slide" axis="0 0 1" springdamper="1e-2 0.5" /><geom name="ball1" type="sphere" size="0.0005" class="collision" /><site name="tendon_site1" type="sphere" size="1e-4" /></body><body name="taxel2" pos="-0.014500 -0.011278 0.000000"><inertial mass="5e-08" pos="0 0 0" fullinertia="1e-6 1e-6 1e-6 0 0 0" /><joint type="slide" axis="0 0 1" springdamper="1e-2 0.5" /><geom name="ball2" type="sphere" size="0.0005" class="collision" /><site name="tendon_site2" type="sphere" size="1e-4" /></body><body name="taxel3" pos="-0.014500 -0.008056 0.000000"><inertial mass="5e-08" pos="0 0 0" fullinertia="1e-6 1e-6 1e-6 0 0 0" /><joint type="slide" axis="0 0 1" springdamper="1e-2 0.5" /><geom name="ball3" type="sphere" size="0.0005" class="collision" /><site name="tendon_site3" type="sphere" size="1e-4" /></body><body name="taxel4" pos="-0.014500 -0.004833 0.000000"><inertial mass="5e-08" pos="0 0 0" fullinertia="1e-6 1e-6 1e-6 0 0 0" /><joint type="slide" axis="0 0 1" springdamper="1e-2 0.5" /><geom name="ball4" type="sphere" size="0.0005" class="collision" /><site name="tendon_site4" type="sphere" size="1e-4" /></body><body name="taxel5" pos="-0.014500 -0.001611 0.000000"><inertial mass="5e-08" pos="0 0 0" fullinertia="1e-6 1e-6 1e-6 0 0 0" /><joint type="slide" axis="0 0 1" springdamper="1e-2 0.5" /><geom name="ball5" type="sphere" size="0.0005" class="collision" /><site name="tendon_site5" type="sphere" size="1e-4" /></body><body name="taxel6" pos="-0.014500 0.001611 0.000000"><inertial mass="5e-08" pos="0 0 0" fullinertia="1e-6 1e-6 1e-6 0 0 0" /><joint type="slide" axis="0 0 1" springdamper="1e-2 0.5" /><geom name="ball6" type="sphere" size="0.0005" class="collision" /><site name="tendon_site6" type="sphere" size="1e-4" /></body><body name="taxel7" pos="-0.014500 0.004833 0.000000"><inertial mass="5e-08" pos="0 0 0" fullinertia="1e-6 1e-6 1e-6 0 0 0" /><joint type="slide" axis="0 0 1" springdamper="1e-2 0.5" /><geom name="ball7" type="sphere" size="0.0005" class="collision" /><site name="tendon_site7" type="sphere" size="1e-4" /></body><body name="taxel8" pos="-0.014500 0.008056 0.000000"><inertial mass="5e-08" pos="0 0 0" fullinertia="1e-6 1e-6 1e-6 0 0 0" /><joint type="slide" axis="0 0 1" springdamper="1e-2 0.5" /><geom name="ball8" type="sphere" size="0.0005" class="collision" /><site name="tendon_site8" type="sphere" size="1e-4" /></body><body name="taxel9" pos="-0.014500 0.011278 0.000000"><inertial mass="5e-08" pos="0 0 0" fullinertia="1e-6 1e-6 1e-6 0 0 0" /><joint type="slide" axis="0 0 1" springdamper="1e-2 0.5" /><geom name="ball9" type="sphere" size="0.0005" class="collision" /><site name="tendon_site9" type="sphere" size="1e-4" /></body><body name="taxel10" pos="-0.014500 0.014500 0.000000"><inertial mass="5e-08" pos="0 0 0" fullinertia="1e-6 1e-6 1e-6 0 0 0" /><joint type="slide" axis="0 0 1" springdamper="1e-2 0.5" /><geom name="ball10" type="sphere" size="0.0005" class="collision" /><site name="tendon_site10" type="sphere" size="1e-4" /></body><body name="taxel11" pos="-0.011278 -0.014500 0.000000"><inertial mass="5e-08" pos="0 0 0" fullinertia="1e-6 1e-6 1e-6 0 0 0" /><joint type="slide" axis="0 0 1" springdamper="1e-2 0.5" /><geom name="ball11" type="sphere" size="0.0005" class="collision" /><site name="tendon_site11" type="sphere" size="1e-4" /></body><body name="taxel12" pos="-0.011278 -0.011278 0.000000"><inertial mass="5e-08" pos="0 0 0" fullinertia="1e-6 1e-6 1e-6 0 0 0" /><joint type="slide" axis="0 0 1" springdamper="1e-2 0.5" /><geom name="ball12" type="sphere" size="0.0005" class="collision" /><site name="tendon_site12" type="sphere" size="1e-4" /></body><body name="taxel13" pos="-0.011278 -0.008056 0.000000"><inertial mass="5e-08" pos="0 0 0" fullinertia="1e-6 1e-6 1e-6 0 0 0" /><joint type="slide" axis="0 0 1" springdamper="1e-2 0.5" /><geom name="ball13" type="sphere" size="0.0005" class="collision" /><site name="tendon_site13" type="sphere" size="1e-4" /></body><body name="taxel14" pos="-0.011278 -0.004833 0.000000"><inertial mass="5e-08" pos="0 0 0" fullinertia="1e-6 1e-6 1e-6 0 0 0" /><joint type="slide" axis="0 0 1" springdamper="1e-2 0.5" /><geom name="ball14" type="sphere" size="0.0005" class="collision" /><site name="tendon_site14" type="sphere" size="1e-4" /></body><body name="taxel15" pos="-0.011278 -0.001611 0.000000"><inertial mass="5e-08" pos="0 0 0" fullinertia="1e-6 1e-6 1e-6 0 0 0" /><joint type="slide" axis="0 0 1" springdamper="1e-2 0.5" /><geom name="ball15" type="sphere" size="0.0005" class="collision" /><site name="tendon_site15" type="sphere" size="1e-4" /></body><body name="taxel16" pos="-0.011278 0.001611 0.000000"><inertial mass="5e-08" pos="0 0 0" fullinertia="1e-6 1e-6 1e-6 0 0 0" /><joint type="slide" axis="0 0 1" springdamper="1e-2 0.5" /><geom name="ball16" type="sphere" size="0.0005" class="collision" /><site name="tendon_site16" type="sphere" size="1e-4" /></body><body name="taxel17" pos="-0.011278 0.004833 0.000000"><inertial mass="5e-08" pos="0 0 0" fullinertia="1e-6 1e-6 1e-6 0 0 0" /><joint type="slide" axis="0 0 1" springdamper="1e-2 0.5" /><geom name="ball17" type="sphere" size="0.0005" class="collision" /><site name="tendon_site17" type="sphere" size="1e-4" /></body><body name="taxel18" pos="-0.011278 0.008056 0.000000"><inertial mass="5e-08" pos="0 0 0" fullinertia="1e-6 1e-6 1e-6 0 0 0" /><joint type="slide" axis="0 0 1" springdamper="1e-2 0.5" /><geom name="ball18" type="sphere" size="0.0005" class="collision" /><site name="tendon_site18" type="sphere" size="1e-4" /></body><body name="taxel19" pos="-0.011278 0.011278 0.000000"><inertial mass="5e-08" pos="0 0 0" fullinertia="1e-6 1e-6 1e-6 0 0 0" /><joint type="slide" axis="0 0 1" springdamper="1e-2 0.5" /><geom name="ball19" type="sphere" size="0.0005" class="collision" /><site name="tendon_site19" type="sphere" size="1e-4" /></body><body name="taxel20" pos="-0.011278 0.014500 0.000000"><inertial mass="5e-08" pos="0 0 0" fullinertia="1e-6 1e-6 1e-6 0 0 0" /><joint type="slide" axis="0 0 1" springdamper="1e-2 0.5" /><geom name="ball20" type="sphere" size="0.0005" class="collision" /><site name="tendon_site20" type="sphere" size="1e-4" /></body><body name="taxel21" pos="-0.008056 -0.014500 0.000000"><inertial mass="5e-08" pos="0 0 0" fullinertia="1e-6 1e-6 1e-6 0 0 0" /><joint type="slide" axis="0 0 1" springdamper="1e-2 0.5" /><geom name="ball21" type="sphere" size="0.0005" class="collision" /><site name="tendon_site21" type="sphere" size="1e-4" /></body><body name="taxel22" pos="-0.008056 -0.011278 0.000000"><inertial mass="5e-08" pos="0 0 0" fullinertia="1e-6 1e-6 1e-6 0 0 0" /><joint type="slide" axis="0 0 1" springdamper="1e-2 0.5" /><geom name="ball22" type="sphere" size="0.0005" class="collision" /><site name="tendon_site22" type="sphere" size="1e-4" /></body><body name="taxel23" pos="-0.008056 -0.008056 0.000000"><inertial mass="5e-08" pos="0 0 0" fullinertia="1e-6 1e-6 1e-6 0 0 0" /><joint type="slide" axis="0 0 1" springdamper="1e-2 0.5" /><geom name="ball23" type="sphere" size="0.0005" class="collision" /><site name="tendon_site23" type="sphere" size="1e-4" /></body><body name="taxel24" pos="-0.008056 -0.004833 0.000000"><inertial mass="5e-08" pos="0 0 0" fullinertia="1e-6 1e-6 1e-6 0 0 0" /><joint type="slide" axis="0 0 1" springdamper="1e-2 0.5" /><geom name="ball24" type="sphere" size="0.0005" class="collision" /><site name="tendon_site24" type="sphere" size="1e-4" /></body><body name="taxel25" pos="-0.008056 -0.001611 0.000000"><inertial mass="5e-08" pos="0 0 0" fullinertia="1e-6 1e-6 1e-6 0 0 0" /><joint type="slide" axis="0 0 1" springdamper="1e-2 0.5" /><geom name="ball25" type="sphere" size="0.0005" class="collision" /><site name="tendon_site25" type="sphere" size="1e-4" /></body><body name="taxel26" pos="-0.008056 0.001611 0.000000"><inertial mass="5e-08" pos="0 0 0" fullinertia="1e-6 1e-6 1e-6 0 0 0" /><joint type="slide" axis="0 0 1" springdamper="1e-2 0.5" /><geom name="ball26" type="sphere" size="0.0005" class="collision" /><site name="tendon_site26" type="sphere" size="1e-4" /></body><body name="taxel27" pos="-0.008056 0.004833 0.000000"><inertial mass="5e-08" pos="0 0 0" fullinertia="1e-6 1e-6 1e-6 0 0 0" /><joint type="slide" axis="0 0 1" springdamper="1e-2 0.5" /><geom name="ball27" type="sphere" size="0.0005" class="collision" /><site name="tendon_site27" type="sphere" size="1e-4" /></body><body name="taxel28" pos="-0.008056 0.008056 0.000000"><inertial mass="5e-08" pos="0 0 0" fullinertia="1e-6 1e-6 1e-6 0 0 0" /><joint type="slide" axis="0 0 1" springdamper="1e-2 0.5" /><geom name="ball28" type="sphere" size="0.0005" class="collision" /><site name="tendon_site28" type="sphere" size="1e-4" /></body><body name="taxel29" pos="-0.008056 0.011278 0.000000"><inertial mass="5e-08" pos="0 0 0" fullinertia="1e-6 1e-6 1e-6 0 0 0" /><joint type="slide" axis="0 0 1" springdamper="1e-2 0.5" /><geom name="ball29" type="sphere" size="0.0005" class="collision" /><site name="tendon_site29" type="sphere" size="1e-4" /></body><body name="taxel30" pos="-0.008056 0.014500 0.000000"><inertial mass="5e-08" pos="0 0 0" fullinertia="1e-6 1e-6 1e-6 0 0 0" /><joint type="slide" axis="0 0 1" springdamper="1e-2 0.5" /><geom name="ball30" type="sphere" size="0.0005" class="collision" /><site name="tendon_site30" type="sphere" size="1e-4" /></body><body name="taxel31" pos="-0.004833 -0.014500 0.000000"><inertial mass="5e-08" pos="0 0 0" fullinertia="1e-6 1e-6 1e-6 0 0 0" /><joint type="slide" axis="0 0 1" springdamper="1e-2 0.5" /><geom name="ball31" type="sphere" size="0.0005" class="collision" /><site name="tendon_site31" type="sphere" size="1e-4" /></body><body name="taxel32" pos="-0.004833 -0.011278 0.000000"><inertial mass="5e-08" pos="0 0 0" fullinertia="1e-6 1e-6 1e-6 0 0 0" /><joint type="slide" axis="0 0 1" springdamper="1e-2 0.5" /><geom name="ball32" type="sphere" size="0.0005" class="collision" /><site name="tendon_site32" type="sphere" size="1e-4" /></body><body name="taxel33" pos="-0.004833 -0.008056 0.000000"><inertial mass="5e-08" pos="0 0 0" fullinertia="1e-6 1e-6 1e-6 0 0 0" /><joint type="slide" axis="0 0 1" springdamper="1e-2 0.5" /><geom name="ball33" type="sphere" size="0.0005" class="collision" /><site name="tendon_site33" type="sphere" size="1e-4" /></body><body name="taxel34" pos="-0.004833 -0.004833 0.000000"><inertial mass="5e-08" pos="0 0 0" fullinertia="1e-6 1e-6 1e-6 0 0 0" /><joint type="slide" axis="0 0 1" springdamper="1e-2 0.5" /><geom name="ball34" type="sphere" size="0.0005" class="collision" /><site name="tendon_site34" type="sphere" size="1e-4" /></body><body name="taxel35" pos="-0.004833 -0.001611 0.000000"><inertial mass="5e-08" pos="0 0 0" fullinertia="1e-6 1e-6 1e-6 0 0 0" /><joint type="slide" axis="0 0 1" springdamper="1e-2 0.5" /><geom name="ball35" type="sphere" size="0.0005" class="collision" /><site name="tendon_site35" type="sphere" size="1e-4" /></body><body name="taxel36" pos="-0.004833 0.001611 0.000000"><inertial mass="5e-08" pos="0 0 0" fullinertia="1e-6 1e-6 1e-6 0 0 0" /><joint type="slide" axis="0 0 1" springdamper="1e-2 0.5" /><geom name="ball36" type="sphere" size="0.0005" class="collision" /><site name="tendon_site36" type="sphere" size="1e-4" /></body><body name="taxel37" pos="-0.004833 0.004833 0.000000"><inertial mass="5e-08" pos="0 0 0" fullinertia="1e-6 1e-6 1e-6 0 0 0" /><joint type="slide" axis="0 0 1" springdamper="1e-2 0.5" /><geom name="ball37" type="sphere" size="0.0005" class="collision" /><site name="tendon_site37" type="sphere" size="1e-4" /></body><body name="taxel38" pos="-0.004833 0.008056 0.000000"><inertial mass="5e-08" pos="0 0 0" fullinertia="1e-6 1e-6 1e-6 0 0 0" /><joint type="slide" axis="0 0 1" springdamper="1e-2 0.5" /><geom name="ball38" type="sphere" size="0.0005" class="collision" /><site name="tendon_site38" type="sphere" size="1e-4" /></body><body name="taxel39" pos="-0.004833 0.011278 0.000000"><inertial mass="5e-08" pos="0 0 0" fullinertia="1e-6 1e-6 1e-6 0 0 0" /><joint type="slide" axis="0 0 1" springdamper="1e-2 0.5" /><geom name="ball39" type="sphere" size="0.0005" class="collision" /><site name="tendon_site39" type="sphere" size="1e-4" /></body><body name="taxel40" pos="-0.004833 0.014500 0.000000"><inertial mass="5e-08" pos="0 0 0" fullinertia="1e-6 1e-6 1e-6 0 0 0" /><joint type="slide" axis="0 0 1" springdamper="1e-2 0.5" /><geom name="ball40" type="sphere" size="0.0005" class="collision" /><site name="tendon_site40" type="sphere" size="1e-4" /></body><body name="taxel41" pos="-0.001611 -0.014500 0.000000"><inertial mass="5e-08" pos="0 0 0" fullinertia="1e-6 1e-6 1e-6 0 0 0" /><joint type="slide" axis="0 0 1" springdamper="1e-2 0.5" /><geom name="ball41" type="sphere" size="0.0005" class="collision" /><site name="tendon_site41" type="sphere" size="1e-4" /></body><body name="taxel42" pos="-0.001611 -0.011278 0.000000"><inertial mass="5e-08" pos="0 0 0" fullinertia="1e-6 1e-6 1e-6 0 0 0" /><joint type="slide" axis="0 0 1" springdamper="1e-2 0.5" /><geom name="ball42" type="sphere" size="0.0005" class="collision" /><site name="tendon_site42" type="sphere" size="1e-4" /></body><body name="taxel43" pos="-0.001611 -0.008056 0.000000"><inertial mass="5e-08" pos="0 0 0" fullinertia="1e-6 1e-6 1e-6 0 0 0" /><joint type="slide" axis="0 0 1" springdamper="1e-2 0.5" /><geom name="ball43" type="sphere" size="0.0005" class="collision" /><site name="tendon_site43" type="sphere" size="1e-4" /></body><body name="taxel44" pos="-0.001611 -0.004833 0.000000"><inertial mass="5e-08" pos="0 0 0" fullinertia="1e-6 1e-6 1e-6 0 0 0" /><joint type="slide" axis="0 0 1" springdamper="1e-2 0.5" /><geom name="ball44" type="sphere" size="0.0005" class="collision" /><site name="tendon_site44" type="sphere" size="1e-4" /></body><body name="taxel45" pos="-0.001611 -0.001611 0.000000"><inertial mass="5e-08" pos="0 0 0" fullinertia="1e-6 1e-6 1e-6 0 0 0" /><joint type="slide" axis="0 0 1" springdamper="1e-2 0.5" /><geom name="ball45" type="sphere" size="0.0005" class="collision" /><site name="tendon_site45" type="sphere" size="1e-4" /></body><body name="taxel46" pos="-0.001611 0.001611 0.000000"><inertial mass="5e-08" pos="0 0 0" fullinertia="1e-6 1e-6 1e-6 0 0 0" /><joint type="slide" axis="0 0 1" springdamper="1e-2 0.5" /><geom name="ball46" type="sphere" size="0.0005" class="collision" /><site name="tendon_site46" type="sphere" size="1e-4" /></body><body name="taxel47" pos="-0.001611 0.004833 0.000000"><inertial mass="5e-08" pos="0 0 0" fullinertia="1e-6 1e-6 1e-6 0 0 0" /><joint type="slide" axis="0 0 1" springdamper="1e-2 0.5" /><geom name="ball47" type="sphere" size="0.0005" class="collision" /><site name="tendon_site47" type="sphere" size="1e-4" /></body><body name="taxel48" pos="-0.001611 0.008056 0.000000"><inertial mass="5e-08" pos="0 0 0" fullinertia="1e-6 1e-6 1e-6 0 0 0" /><joint type="slide" axis="0 0 1" springdamper="1e-2 0.5" /><geom name="ball48" type="sphere" size="0.0005" class="collision" /><site name="tendon_site48" type="sphere" size="1e-4" /></body><body name="taxel49" pos="-0.001611 0.011278 0.000000"><inertial mass="5e-08" pos="0 0 0" fullinertia="1e-6 1e-6 1e-6 0 0 0" /><joint type="slide" axis="0 0 1" springdamper="1e-2 0.5" /><geom name="ball49" type="sphere" size="0.0005" class="collision" /><site name="tendon_site49" type="sphere" size="1e-4" /></body><body name="taxel50" pos="-0.001611 0.014500 0.000000"><inertial mass="5e-08" pos="0 0 0" fullinertia="1e-6 1e-6 1e-6 0 0 0" /><joint type="slide" axis="0 0 1" springdamper="1e-2 0.5" /><geom name="ball50" type="sphere" size="0.0005" class="collision" /><site name="tendon_site50" type="sphere" size="1e-4" /></body><body name="taxel51" pos="0.001611 -0.014500 0.000000"><inertial mass="5e-08" pos="0 0 0" fullinertia="1e-6 1e-6 1e-6 0 0 0" /><joint type="slide" axis="0 0 1" springdamper="1e-2 0.5" /><geom name="ball51" type="sphere" size="0.0005" class="collision" /><site name="tendon_site51" type="sphere" size="1e-4" /></body><body name="taxel52" pos="0.001611 -0.011278 0.000000"><inertial mass="5e-08" pos="0 0 0" fullinertia="1e-6 1e-6 1e-6 0 0 0" /><joint type="slide" axis="0 0 1" springdamper="1e-2 0.5" /><geom name="ball52" type="sphere" size="0.0005" class="collision" /><site name="tendon_site52" type="sphere" size="1e-4" /></body><body name="taxel53" pos="0.001611 -0.008056 0.000000"><inertial mass="5e-08" pos="0 0 0" fullinertia="1e-6 1e-6 1e-6 0 0 0" /><joint type="slide" axis="0 0 1" springdamper="1e-2 0.5" /><geom name="ball53" type="sphere" size="0.0005" class="collision" /><site name="tendon_site53" type="sphere" size="1e-4" /></body><body name="taxel54" pos="0.001611 -0.004833 0.000000"><inertial mass="5e-08" pos="0 0 0" fullinertia="1e-6 1e-6 1e-6 0 0 0" /><joint type="slide" axis="0 0 1" springdamper="1e-2 0.5" /><geom name="ball54" type="sphere" size="0.0005" class="collision" /><site name="tendon_site54" type="sphere" size="1e-4" /></body><body name="taxel55" pos="0.001611 -0.001611 0.000000"><inertial mass="5e-08" pos="0 0 0" fullinertia="1e-6 1e-6 1e-6 0 0 0" /><joint type="slide" axis="0 0 1" springdamper="1e-2 0.5" /><geom name="ball55" type="sphere" size="0.0005" class="collision" /><site name="tendon_site55" type="sphere" size="1e-4" /></body><body name="taxel56" pos="0.001611 0.001611 0.000000"><inertial mass="5e-08" pos="0 0 0" fullinertia="1e-6 1e-6 1e-6 0 0 0" /><joint type="slide" axis="0 0 1" springdamper="1e-2 0.5" /><geom name="ball56" type="sphere" size="0.0005" class="collision" /><site name="tendon_site56" type="sphere" size="1e-4" /></body><body name="taxel57" pos="0.001611 0.004833 0.000000"><inertial mass="5e-08" pos="0 0 0" fullinertia="1e-6 1e-6 1e-6 0 0 0" /><joint type="slide" axis="0 0 1" springdamper="1e-2 0.5" /><geom name="ball57" type="sphere" size="0.0005" class="collision" /><site name="tendon_site57" type="sphere" size="1e-4" /></body><body name="taxel58" pos="0.001611 0.008056 0.000000"><inertial mass="5e-08" pos="0 0 0" fullinertia="1e-6 1e-6 1e-6 0 0 0" /><joint type="slide" axis="0 0 1" springdamper="1e-2 0.5" /><geom name="ball58" type="sphere" size="0.0005" class="collision" /><site name="tendon_site58" type="sphere" size="1e-4" /></body><body name="taxel59" pos="0.001611 0.011278 0.000000"><inertial mass="5e-08" pos="0 0 0" fullinertia="1e-6 1e-6 1e-6 0 0 0" /><joint type="slide" axis="0 0 1" springdamper="1e-2 0.5" /><geom name="ball59" type="sphere" size="0.0005" class="collision" /><site name="tendon_site59" type="sphere" size="1e-4" /></body><body name="taxel60" pos="0.001611 0.014500 0.000000"><inertial mass="5e-08" pos="0 0 0" fullinertia="1e-6 1e-6 1e-6 0 0 0" /><joint type="slide" axis="0 0 1" springdamper="1e-2 0.5" /><geom name="ball60" type="sphere" size="0.0005" class="collision" /><site name="tendon_site60" type="sphere" size="1e-4" /></body><body name="taxel61" pos="0.004833 -0.014500 0.000000"><inertial mass="5e-08" pos="0 0 0" fullinertia="1e-6 1e-6 1e-6 0 0 0" /><joint type="slide" axis="0 0 1" springdamper="1e-2 0.5" /><geom name="ball61" type="sphere" size="0.0005" class="collision" /><site name="tendon_site61" type="sphere" size="1e-4" /></body><body name="taxel62" pos="0.004833 -0.011278 0.000000"><inertial mass="5e-08" pos="0 0 0" fullinertia="1e-6 1e-6 1e-6 0 0 0" /><joint type="slide" axis="0 0 1" springdamper="1e-2 0.5" /><geom name="ball62" type="sphere" size="0.0005" class="collision" /><site name="tendon_site62" type="sphere" size="1e-4" /></body><body name="taxel63" pos="0.004833 -0.008056 0.000000"><inertial mass="5e-08" pos="0 0 0" fullinertia="1e-6 1e-6 1e-6 0 0 0" /><joint type="slide" axis="0 0 1" springdamper="1e-2 0.5" /><geom name="ball63" type="sphere" size="0.0005" class="collision" /><site name="tendon_site63" type="sphere" size="1e-4" /></body><body name="taxel64" pos="0.004833 -0.004833 0.000000"><inertial mass="5e-08" pos="0 0 0" fullinertia="1e-6 1e-6 1e-6 0 0 0" /><joint type="slide" axis="0 0 1" springdamper="1e-2 0.5" /><geom name="ball64" type="sphere" size="0.0005" class="collision" /><site name="tendon_site64" type="sphere" size="1e-4" /></body><body name="taxel65" pos="0.004833 -0.001611 0.000000"><inertial mass="5e-08" pos="0 0 0" fullinertia="1e-6 1e-6 1e-6 0 0 0" /><joint type="slide" axis="0 0 1" springdamper="1e-2 0.5" /><geom name="ball65" type="sphere" size="0.0005" class="collision" /><site name="tendon_site65" type="sphere" size="1e-4" /></body><body name="taxel66" pos="0.004833 0.001611 0.000000"><inertial mass="5e-08" pos="0 0 0" fullinertia="1e-6 1e-6 1e-6 0 0 0" /><joint type="slide" axis="0 0 1" springdamper="1e-2 0.5" /><geom name="ball66" type="sphere" size="0.0005" class="collision" /><site name="tendon_site66" type="sphere" size="1e-4" /></body><body name="taxel67" pos="0.004833 0.004833 0.000000"><inertial mass="5e-08" pos="0 0 0" fullinertia="1e-6 1e-6 1e-6 0 0 0" /><joint type="slide" axis="0 0 1" springdamper="1e-2 0.5" /><geom name="ball67" type="sphere" size="0.0005" class="collision" /><site name="tendon_site67" type="sphere" size="1e-4" /></body><body name="taxel68" pos="0.004833 0.008056 0.000000"><inertial mass="5e-08" pos="0 0 0" fullinertia="1e-6 1e-6 1e-6 0 0 0" /><joint type="slide" axis="0 0 1" springdamper="1e-2 0.5" /><geom name="ball68" type="sphere" size="0.0005" class="collision" /><site name="tendon_site68" type="sphere" size="1e-4" /></body><body name="taxel69" pos="0.004833 0.011278 0.000000"><inertial mass="5e-08" pos="0 0 0" fullinertia="1e-6 1e-6 1e-6 0 0 0" /><joint type="slide" axis="0 0 1" springdamper="1e-2 0.5" /><geom name="ball69" type="sphere" size="0.0005" class="collision" /><site name="tendon_site69" type="sphere" size="1e-4" /></body><body name="taxel70" pos="0.004833 0.014500 0.000000"><inertial mass="5e-08" pos="0 0 0" fullinertia="1e-6 1e-6 1e-6 0 0 0" /><joint type="slide" axis="0 0 1" springdamper="1e-2 0.5" /><geom name="ball70" type="sphere" size="0.0005" class="collision" /><site name="tendon_site70" type="sphere" size="1e-4" /></body><body name="taxel71" pos="0.008056 -0.014500 0.000000"><inertial mass="5e-08" pos="0 0 0" fullinertia="1e-6 1e-6 1e-6 0 0 0" /><joint type="slide" axis="0 0 1" springdamper="1e-2 0.5" /><geom name="ball71" type="sphere" size="0.0005" class="collision" /><site name="tendon_site71" type="sphere" size="1e-4" /></body><body name="taxel72" pos="0.008056 -0.011278 0.000000"><inertial mass="5e-08" pos="0 0 0" fullinertia="1e-6 1e-6 1e-6 0 0 0" /><joint type="slide" axis="0 0 1" springdamper="1e-2 0.5" /><geom name="ball72" type="sphere" size="0.0005" class="collision" /><site name="tendon_site72" type="sphere" size="1e-4" /></body><body name="taxel73" pos="0.008056 -0.008056 0.000000"><inertial mass="5e-08" pos="0 0 0" fullinertia="1e-6 1e-6 1e-6 0 0 0" /><joint type="slide" axis="0 0 1" springdamper="1e-2 0.5" /><geom name="ball73" type="sphere" size="0.0005" class="collision" /><site name="tendon_site73" type="sphere" size="1e-4" /></body><body name="taxel74" pos="0.008056 -0.004833 0.000000"><inertial mass="5e-08" pos="0 0 0" fullinertia="1e-6 1e-6 1e-6 0 0 0" /><joint type="slide" axis="0 0 1" springdamper="1e-2 0.5" /><geom name="ball74" type="sphere" size="0.0005" class="collision" /><site name="tendon_site74" type="sphere" size="1e-4" /></body><body name="taxel75" pos="0.008056 -0.001611 0.000000"><inertial mass="5e-08" pos="0 0 0" fullinertia="1e-6 1e-6 1e-6 0 0 0" /><joint type="slide" axis="0 0 1" springdamper="1e-2 0.5" /><geom name="ball75" type="sphere" size="0.0005" class="collision" /><site name="tendon_site75" type="sphere" size="1e-4" /></body><body name="taxel76" pos="0.008056 0.001611 0.000000"><inertial mass="5e-08" pos="0 0 0" fullinertia="1e-6 1e-6 1e-6 0 0 0" /><joint type="slide" axis="0 0 1" springdamper="1e-2 0.5" /><geom name="ball76" type="sphere" size="0.0005" class="collision" /><site name="tendon_site76" type="sphere" size="1e-4" /></body><body name="taxel77" pos="0.008056 0.004833 0.000000"><inertial mass="5e-08" pos="0 0 0" fullinertia="1e-6 1e-6 1e-6 0 0 0" /><joint type="slide" axis="0 0 1" springdamper="1e-2 0.5" /><geom name="ball77" type="sphere" size="0.0005" class="collision" /><site name="tendon_site77" type="sphere" size="1e-4" /></body><body name="taxel78" pos="0.008056 0.008056 0.000000"><inertial mass="5e-08" pos="0 0 0" fullinertia="1e-6 1e-6 1e-6 0 0 0" /><joint type="slide" axis="0 0 1" springdamper="1e-2 0.5" /><geom name="ball78" type="sphere" size="0.0005" class="collision" /><site name="tendon_site78" type="sphere" size="1e-4" /></body><body name="taxel79" pos="0.008056 0.011278 0.000000"><inertial mass="5e-08" pos="0 0 0" fullinertia="1e-6 1e-6 1e-6 0 0 0" /><joint type="slide" axis="0 0 1" springdamper="1e-2 0.5" /><geom name="ball79" type="sphere" size="0.0005" class="collision" /><site name="tendon_site79" type="sphere" size="1e-4" /></body><body name="taxel80" pos="0.008056 0.014500 0.000000"><inertial mass="5e-08" pos="0 0 0" fullinertia="1e-6 1e-6 1e-6 0 0 0" /><joint type="slide" axis="0 0 1" springdamper="1e-2 0.5" /><geom name="ball80" type="sphere" size="0.0005" class="collision" /><site name="tendon_site80" type="sphere" size="1e-4" /></body><body name="taxel81" pos="0.011278 -0.014500 0.000000"><inertial mass="5e-08" pos="0 0 0" fullinertia="1e-6 1e-6 1e-6 0 0 0" /><joint type="slide" axis="0 0 1" springdamper="1e-2 0.5" /><geom name="ball81" type="sphere" size="0.0005" class="collision" /><site name="tendon_site81" type="sphere" size="1e-4" /></body><body name="taxel82" pos="0.011278 -0.011278 0.000000"><inertial mass="5e-08" pos="0 0 0" fullinertia="1e-6 1e-6 1e-6 0 0 0" /><joint type="slide" axis="0 0 1" springdamper="1e-2 0.5" /><geom name="ball82" type="sphere" size="0.0005" class="collision" /><site name="tendon_site82" type="sphere" size="1e-4" /></body><body name="taxel83" pos="0.011278 -0.008056 0.000000"><inertial mass="5e-08" pos="0 0 0" fullinertia="1e-6 1e-6 1e-6 0 0 0" /><joint type="slide" axis="0 0 1" springdamper="1e-2 0.5" /><geom name="ball83" type="sphere" size="0.0005" class="collision" /><site name="tendon_site83" type="sphere" size="1e-4" /></body><body name="taxel84" pos="0.011278 -0.004833 0.000000"><inertial mass="5e-08" pos="0 0 0" fullinertia="1e-6 1e-6 1e-6 0 0 0" /><joint type="slide" axis="0 0 1" springdamper="1e-2 0.5" /><geom name="ball84" type="sphere" size="0.0005" class="collision" /><site name="tendon_site84" type="sphere" size="1e-4" /></body><body name="taxel85" pos="0.011278 -0.001611 0.000000"><inertial mass="5e-08" pos="0 0 0" fullinertia="1e-6 1e-6 1e-6 0 0 0" /><joint type="slide" axis="0 0 1" springdamper="1e-2 0.5" /><geom name="ball85" type="sphere" size="0.0005" class="collision" /><site name="tendon_site85" type="sphere" size="1e-4" /></body><body name="taxel86" pos="0.011278 0.001611 0.000000"><inertial mass="5e-08" pos="0 0 0" fullinertia="1e-6 1e-6 1e-6 0 0 0" /><joint type="slide" axis="0 0 1" springdamper="1e-2 0.5" /><geom name="ball86" type="sphere" size="0.0005" class="collision" /><site name="tendon_site86" type="sphere" size="1e-4" /></body><body name="taxel87" pos="0.011278 0.004833 0.000000"><inertial mass="5e-08" pos="0 0 0" fullinertia="1e-6 1e-6 1e-6 0 0 0" /><joint type="slide" axis="0 0 1" springdamper="1e-2 0.5" /><geom name="ball87" type="sphere" size="0.0005" class="collision" /><site name="tendon_site87" type="sphere" size="1e-4" /></body><body name="taxel88" pos="0.011278 0.008056 0.000000"><inertial mass="5e-08" pos="0 0 0" fullinertia="1e-6 1e-6 1e-6 0 0 0" /><joint type="slide" axis="0 0 1" springdamper="1e-2 0.5" /><geom name="ball88" type="sphere" size="0.0005" class="collision" /><site name="tendon_site88" type="sphere" size="1e-4" /></body><body name="taxel89" pos="0.011278 0.011278 0.000000"><inertial mass="5e-08" pos="0 0 0" fullinertia="1e-6 1e-6 1e-6 0 0 0" /><joint type="slide" axis="0 0 1" springdamper="1e-2 0.5" /><geom name="ball89" type="sphere" size="0.0005" class="collision" /><site name="tendon_site89" type="sphere" size="1e-4" /></body><body name="taxel90" pos="0.011278 0.014500 0.000000"><inertial mass="5e-08" pos="0 0 0" fullinertia="1e-6 1e-6 1e-6 0 0 0" /><joint type="slide" axis="0 0 1" springdamper="1e-2 0.5" /><geom name="ball90" type="sphere" size="0.0005" class="collision" /><site name="tendon_site90" type="sphere" size="1e-4" /></body><body name="taxel91" pos="0.014500 -0.014500 0.000000"><inertial mass="5e-08" pos="0 0 0" fullinertia="1e-6 1e-6 1e-6 0 0 0" /><joint type="slide" axis="0 0 1" springdamper="1e-2 0.5" /><geom name="ball91" type="sphere" size="0.0005" class="collision" /><site name="tendon_site91" type="sphere" size="1e-4" /></body><body name="taxel92" pos="0.014500 -0.011278 0.000000"><inertial mass="5e-08" pos="0 0 0" fullinertia="1e-6 1e-6 1e-6 0 0 0" /><joint type="slide" axis="0 0 1" springdamper="1e-2 0.5" /><geom name="ball92" type="sphere" size="0.0005" class="collision" /><site name="tendon_site92" type="sphere" size="1e-4" /></body><body name="taxel93" pos="0.014500 -0.008056 0.000000"><inertial mass="5e-08" pos="0 0 0" fullinertia="1e-6 1e-6 1e-6 0 0 0" /><joint type="slide" axis="0 0 1" springdamper="1e-2 0.5" /><geom name="ball93" type="sphere" size="0.0005" class="collision" /><site name="tendon_site93" type="sphere" size="1e-4" /></body><body name="taxel94" pos="0.014500 -0.004833 0.000000"><inertial mass="5e-08" pos="0 0 0" fullinertia="1e-6 1e-6 1e-6 0 0 0" /><joint type="slide" axis="0 0 1" springdamper="1e-2 0.5" /><geom name="ball94" type="sphere" size="0.0005" class="collision" /><site name="tendon_site94" type="sphere" size="1e-4" /></body><body name="taxel95" pos="0.014500 -0.001611 0.000000"><inertial mass="5e-08" pos="0 0 0" fullinertia="1e-6 1e-6 1e-6 0 0 0" /><joint type="slide" axis="0 0 1" springdamper="1e-2 0.5" /><geom name="ball95" type="sphere" size="0.0005" class="collision" /><site name="tendon_site95" type="sphere" size="1e-4" /></body><body name="taxel96" pos="0.014500 0.001611 0.000000"><inertial mass="5e-08" pos="0 0 0" fullinertia="1e-6 1e-6 1e-6 0 0 0" /><joint type="slide" axis="0 0 1" springdamper="1e-2 0.5" /><geom name="ball96" type="sphere" size="0.0005" class="collision" /><site name="tendon_site96" type="sphere" size="1e-4" /></body><body name="taxel97" pos="0.014500 0.004833 0.000000"><inertial mass="5e-08" pos="0 0 0" fullinertia="1e-6 1e-6 1e-6 0 0 0" /><joint type="slide" axis="0 0 1" springdamper="1e-2 0.5" /><geom name="ball97" type="sphere" size="0.0005" class="collision" /><site name="tendon_site97" type="sphere" size="1e-4" /></body><body name="taxel98" pos="0.014500 0.008056 0.000000"><inertial mass="5e-08" pos="0 0 0" fullinertia="1e-6 1e-6 1e-6 0 0 0" /><joint type="slide" axis="0 0 1" springdamper="1e-2 0.5" /><geom name="ball98" type="sphere" size="0.0005" class="collision" /><site name="tendon_site98" type="sphere" size="1e-4" /></body><body name="taxel99" pos="0.014500 0.011278 0.000000"><inertial mass="5e-08" pos="0 0 0" fullinertia="1e-6 1e-6 1e-6 0 0 0" /><joint type="slide" axis="0 0 1" springdamper="1e-2 0.5" /><geom name="ball99" type="sphere" size="0.0005" class="collision" /><site name="tendon_site99" type="sphere" size="1e-4" /></body><body name="taxel100" pos="0.014500 0.014500 0.000000"><inertial mass="5e-08" pos="0 0 0" fullinertia="1e-6 1e-6 1e-6 0 0 0" /><joint type="slide" axis="0 0 1" springdamper="1e-2 0.5" /><geom name="ball100" type="sphere" size="0.0005" class="collision" /><site name="tendon_site100" type="sphere" size="1e-4" /></body></body>
                      </body>
                      <site name="attachment_site" pos="0 0 -1.5e-3" class="ik" />
                    </body>
                  </body>
                </body>
              </body>
            </body>
          </body>
        </body>
      </body>
    </body>
  </worldbody>

  <tendon>
    <spatial name="tendom1" width="2e-4" limited="true" range="0 0.006444" stiffness="1.0"><site site="tendon_site1" /><site site="tendon_site2" /><site site="tendon_site3" /><site site="tendon_site4" /><site site="tendon_site5" /><site site="tendon_site6" /><site site="tendon_site7" /><site site="tendon_site8" /><site site="tendon_site9" /><site site="tendon_site10" /></spatial><spatial name="tendom2" width="2e-4" limited="true" range="0 0.006444" stiffness="1.0"><site site="tendon_site11" /><site site="tendon_site12" /><site site="tendon_site13" /><site site="tendon_site14" /><site site="tendon_site15" /><site site="tendon_site16" /><site site="tendon_site17" /><site site="tendon_site18" /><site site="tendon_site19" /><site site="tendon_site20" /></spatial><spatial name="tendom3" width="2e-4" limited="true" range="0 0.006444" stiffness="1.0"><site site="tendon_site21" /><site site="tendon_site22" /><site site="tendon_site23" /><site site="tendon_site24" /><site site="tendon_site25" /><site site="tendon_site26" /><site site="tendon_site27" /><site site="tendon_site28" /><site site="tendon_site29" /><site site="tendon_site30" /></spatial><spatial name="tendom4" width="2e-4" limited="true" range="0 0.006444" stiffness="1.0"><site site="tendon_site31" /><site site="tendon_site32" /><site site="tendon_site33" /><site site="tendon_site34" /><site site="tendon_site35" /><site site="tendon_site36" /><site site="tendon_site37" /><site site="tendon_site38" /><site site="tendon_site39" /><site site="tendon_site40" /></spatial><spatial name="tendom5" width="2e-4" limited="true" range="0 0.006444" stiffness="1.0"><site site="tendon_site41" /><site site="tendon_site42" /><site site="tendon_site43" /><site site="tendon_site44" /><site site="tendon_site45" /><site site="tendon_site46" /><site site="tendon_site47" /><site site="tendon_site48" /><site site="tendon_site49" /><site site="tendon_site50" /></spatial><spatial name="tendom6" width="2e-4" limited="true" range="0 0.006444" stiffness="1.0"><site site="tendon_site51" /><site site="tendon_site52" /><site site="tendon_site53" /><site site="tendon_site54" /><site site="tendon_site55" /><site site="tendon_site56" /><site site="tendon_site57" /><site site="tendon_site58" /><site site="tendon_site59" /><site site="tendon_site60" /></spatial><spatial name="tendom7" width="2e-4" limited="true" range="0 0.006444" stiffness="1.0"><site site="tendon_site61" /><site site="tendon_site62" /><site site="tendon_site63" /><site site="tendon_site64" /><site site="tendon_site65" /><site site="tendon_site66" /><site site="tendon_site67" /><site site="tendon_site68" /><site site="tendon_site69" /><site site="tendon_site70" /></spatial><spatial name="tendom8" width="2e-4" limited="true" range="0 0.006444" stiffness="1.0"><site site="tendon_site71" /><site site="tendon_site72" /><site site="tendon_site73" /><site site="tendon_site74" /><site site="tendon_site75" /><site site="tendon_site76" /><site site="tendon_site77" /><site site="tendon_site78" /><site site="tendon_site79" /><site site="tendon_site80" /></spatial><spatial name="tendom9" width="2e-4" limited="true" range="0 0.006444" stiffness="1.0"><site site="tendon_site81" /><site site="tendon_site82" /><site site="tendon_site83" /><site site="tendon_site84" /><site site="tendon_site85" /><site site="tendon_site86" /><site site="tendon_site87" /><site site="tendon_site88" /><site site="tendon_site89" /><site site="tendon_site90" /></spatial><spatial name="tendom10" width="2e-4" limited="true" range="0 0.006444" stiffness="1.0"><site site="tendon_site91" /><site site="tendon_site92" /><site site="tendon_site93" /><site site="tendon_site94" /><site site="tendon_site95" /><site site="tendon_site96" /><site site="tendon_site97" /><site site="tendon_site98" /><site site="tendon_site99" /><site site="tendon_site100" /></spatial></tendon>

  <actuator>
    <general class="panda" name="actuator1" joint="joint1" gainprm="4500" biasprm="0 -4500 -450" />
    <general class="panda" name="actuator2" joint="joint2" gainprm="4500" biasprm="0 -4500 -450" ctrlrange="-1.7628 1.7628" />
    <general class="panda" name="actuator3" joint="joint3" gainprm="3500" biasprm="0 -3500 -350" />
    <general class="panda" name="actuator4" joint="joint4" gainprm="3500" biasprm="0 -3500 -350" ctrlrange="-3.0718 -0.0698" />
    <general class="panda" name="actuator5" joint="joint5" gainprm="2000" biasprm="0 -2000 -200" forcerange="-12 12" />
    <general class="panda" name="actuator6" joint="joint6" gainprm="2000" biasprm="0 -2000 -200" forcerange="-12 12" ctrlrange="-0.0175 3.7525" />
    <general class="panda" name="actuator7" joint="joint7" gainprm="2000" biasprm="0 -2000 -200" forcerange="-12 12" />
  </actuator>

  <sensor />
</mujoco>