<mujoco model="panda">
  <compiler angle="radian" meshdir="assets" autolimits="true" />
  <option solver="CG" tolerance="1e-6" />
  <option integrator="implicit" />

  <size nconmax="500" njmax="5000" nstack="5000000" />

  <default>
    <default class="panda">
      <material specular="0.5" shininess="0.25" />
      <joint armature="0.1" damping="1" axis="0 0 1" range="-2.8973 2.8973" />
      <general dyntype="none" biastype="affine" ctrlrange="-2.8973 2.8973" forcerange="-87 87" />
      <default class="finger">
        <joint axis="0 1 0" type="slide" range="0 0.04" />
      </default>

      <default class="visual">
        <geom type="mesh" contype="0" conaffinity="0" group="2" />
      </default>
      <default class="collision">
        <geom type="mesh" group="3" />
      </default>

      <default class="ik">
        <site type="sphere" size="1e-3" rgba="0.5 0.5 0.5 0.5" group="0" />
      </default>
      <site rgba="0.5 0.5 0.5 0.3" group="1" />
    </default>
  </default>

  <asset>
    <material class="panda" name="white" rgba="1 1 1 1" />
    <material class="panda" name="off_white" rgba="0.901961 0.921569 0.929412 1" />
    <material class="panda" name="black" rgba="0.25 0.25 0.25 1" />
    <material class="panda" name="green" rgba="0 1 0 1" />
    <material class="panda" name="light_blue" rgba="0.039216 0.541176 0.780392 1" />


    <mesh name="link0_c" file="link0.stl" />
    <mesh name="link1_c" file="link1.stl" />
    <mesh name="link2_c" file="link2.stl" />
    <mesh name="link3_c" file="link3.stl" />
    <mesh name="link4_c" file="link4.stl" />
    <mesh name="link5_c0" file="link5_collision_0.obj" />
    <mesh name="link5_c1" file="link5_collision_1.obj" />
    <mesh name="link5_c2" file="link5_collision_2.obj" />
    <mesh name="link6_c" file="link6.stl" />
    <mesh name="link7_c" file="link7.stl" />
    <mesh name="tactile_sensor_base" file="tactile_sensor_base.obj" />


    <mesh file="link0_0.obj" />
    <mesh file="link0_1.obj" />
    <mesh file="link0_2.obj" />
    <mesh file="link0_3.obj" />
    <mesh file="link0_4.obj" />
    <mesh file="link0_5.obj" />
    <mesh file="link0_7.obj" />
    <mesh file="link0_8.obj" />
    <mesh file="link0_9.obj" />
    <mesh file="link0_10.obj" />
    <mesh file="link0_11.obj" />
    <mesh file="link1.obj" />
    <mesh file="link2.obj" />
    <mesh file="link3_0.obj" />
    <mesh file="link3_1.obj" />
    <mesh file="link3_2.obj" />
    <mesh file="link3_3.obj" />
    <mesh file="link4_0.obj" />
    <mesh file="link4_1.obj" />
    <mesh file="link4_2.obj" />
    <mesh file="link4_3.obj" />
    <mesh file="link5_0.obj" />
    <mesh file="link5_1.obj" />
    <mesh file="link5_2.obj" />
    <mesh file="link6_0.obj" />
    <mesh file="link6_1.obj" />
    <mesh file="link6_2.obj" />
    <mesh file="link6_3.obj" />
    <mesh file="link6_4.obj" />
    <mesh file="link6_5.obj" />
    <mesh file="link6_6.obj" />
    <mesh file="link6_7.obj" />
    <mesh file="link6_8.obj" />
    <mesh file="link6_9.obj" />
    <mesh file="link6_10.obj" />
    <mesh file="link6_11.obj" />
    <mesh file="link6_12.obj" />
    <mesh file="link6_13.obj" />
    <mesh file="link6_14.obj" />
    <mesh file="link6_15.obj" />
    <mesh file="link6_16.obj" />
    <mesh file="link7_0.obj" />
    <mesh file="link7_1.obj" />
    <mesh file="link7_2.obj" />
    <mesh file="link7_3.obj" />
    <mesh file="link7_4.obj" />
    <mesh file="link7_5.obj" />
    <mesh file="link7_6.obj" />
    <mesh file="link7_7.obj" />
  </asset>

  <worldbody>
    <light name="top" pos="0 0 2" mode="trackcom" />
    <body name="link0" childclass="panda">
      <inertial mass="0.629769" pos="-0.041018 -0.00014 0.049974" fullinertia="0.00315 0.00388 0.004285 8.2904e-7 0.00015 8.2299e-6" />
      <geom mesh="link0_0" material="off_white" class="visual" />
      <geom mesh="link0_1" material="black" class="visual" />
      <geom mesh="link0_2" material="off_white" class="visual" />
      <geom mesh="link0_3" material="black" class="visual" />
      <geom mesh="link0_4" material="off_white" class="visual" />
      <geom mesh="link0_5" material="black" class="visual" />
      <geom mesh="link0_7" material="white" class="visual" />
      <geom mesh="link0_8" material="white" class="visual" />
      <geom mesh="link0_9" material="black" class="visual" />
      <geom mesh="link0_10" material="off_white" class="visual" />
      <geom mesh="link0_11" material="white" class="visual" />
      <geom mesh="link0_c" class="collision" />
      <body name="link1" pos="0 0 0.333">
        <inertial mass="4.970684" pos="0.003875 0.002081 -0.04762" fullinertia="0.70337 0.70661 0.0091170 -0.00013900 0.0067720 0.019169" />
        <joint name="joint1" />
        <geom material="white" mesh="link1" class="visual" />
        <geom mesh="link1_c" class="collision" />
        <body name="link2" quat="1 -1 0 0">
          <inertial mass="0.646926" pos="-0.003141 -0.02872 0.003495" fullinertia="0.0079620 2.8110e-2 2.5995e-2 -3.925e-3 1.0254e-2 7.04e-4" />
          <joint name="joint2" range="-1.7628 1.7628" />
          <geom material="white" mesh="link2" class="visual" />
          <geom mesh="link2_c" class="collision" />
          <body name="link3" pos="0 -0.316 0" quat="1 1 0 0">
            <joint name="joint3" />
            <inertial mass="3.228604" pos="2.7518e-2 3.9252e-2 -6.6502e-2" fullinertia="3.7242e-2 3.6155e-2 1.083e-2 -4.761e-3 -1.1396e-2 -1.2805e-2" />
            <geom mesh="link3_0" material="white" class="visual" />
            <geom mesh="link3_1" material="white" class="visual" />
            <geom mesh="link3_2" material="white" class="visual" />
            <geom mesh="link3_3" material="black" class="visual" />
            <geom mesh="link3_c" class="collision" />
            <body name="link4" pos="0.0825 0 0" quat="1 1 0 0">
              <inertial mass="3.587895" pos="-5.317e-2 1.04419e-1 2.7454e-2" fullinertia="2.5853e-2 1.9552e-2 2.8323e-2 7.796e-3 -1.332e-3 8.641e-3" />
              <joint name="joint4" range="-3.0718 -0.0698" />
              <geom mesh="link4_0" material="white" class="visual" />
              <geom mesh="link4_1" material="white" class="visual" />
              <geom mesh="link4_2" material="black" class="visual" />
              <geom mesh="link4_3" material="white" class="visual" />
              <geom mesh="link4_c" class="collision" />
              <body name="link5" pos="-0.0825 0.384 0" quat="1 -1 0 0">
                <inertial mass="1.225946" pos="-1.1953e-2 4.1065e-2 -3.8437e-2" fullinertia="3.5549e-2 2.9474e-2 8.627e-3 -2.117e-3 -4.037e-3 2.29e-4" />
                <joint name="joint5" />
                <geom mesh="link5_0" material="black" class="visual" />
                <geom mesh="link5_1" material="white" class="visual" />
                <geom mesh="link5_2" material="white" class="visual" />
                <geom mesh="link5_c0" class="collision" />
                <geom mesh="link5_c1" class="collision" />
                <geom mesh="link5_c2" class="collision" />
                <body name="link6" quat="1 1 0 0">
                  <inertial mass="1.666555" pos="6.0149e-2 -1.4117e-2 -1.0517e-2" fullinertia="1.964e-3 4.354e-3 5.433e-3 1.09e-4 -1.158e-3 3.41e-4" />
                  <joint name="joint6" range="-0.0175 3.7525" />
                  <geom mesh="link6_0" material="off_white" class="visual" />
                  <geom mesh="link6_1" material="white" class="visual" />
                  <geom mesh="link6_2" material="black" class="visual" />
                  <geom mesh="link6_3" material="white" class="visual" />
                  <geom mesh="link6_4" material="white" class="visual" />
                  <geom mesh="link6_5" material="white" class="visual" />
                  <geom mesh="link6_6" material="white" class="visual" />
                  <geom mesh="link6_7" material="light_blue" class="visual" />
                  <geom mesh="link6_8" material="light_blue" class="visual" />
                  <geom mesh="link6_9" material="black" class="visual" />
                  <geom mesh="link6_10" material="black" class="visual" />
                  <geom mesh="link6_11" material="white" class="visual" />
                  <geom mesh="link6_12" material="green" class="visual" />
                  <geom mesh="link6_13" material="white" class="visual" />
                  <geom mesh="link6_14" material="black" class="visual" />
                  <geom mesh="link6_15" material="black" class="visual" />
                  <geom mesh="link6_16" material="white" class="visual" />
                  <geom mesh="link6_c" class="collision" />
                  <body name="link7" pos="0.088 0 0" quat="1 1 0 0">
                    <inertial mass="7.35522e-01" pos="1.0517e-2 -4.252e-3 6.1597e-2" fullinertia="1.2516e-2 1.0027e-2 4.815e-3 -4.28e-4 -1.196e-3 -7.41e-4" />
                    <joint name="joint7" />
                    <geom mesh="link7_0" material="white" class="visual" />
                    <geom mesh="link7_1" material="black" class="visual" />
                    <geom mesh="link7_2" material="black" class="visual" />
                    <geom mesh="link7_3" material="black" class="visual" />
                    <geom mesh="link7_4" material="black" class="visual" />
                    <geom mesh="link7_5" material="black" class="visual" />
                    <geom mesh="link7_6" material="black" class="visual" />
                    <geom mesh="link7_7" material="white" class="visual" />
                    <geom mesh="link7_c" class="collision" />
                    <body name="tactile_sensor" pos="0 0 0.145" euler="3.14159253 0 0.78539816">
                      <inertial mass="1e-3" pos="0 0 0" />
                      <body name="sensor_base" pos="0 0 0" euler="1.570796 0 0">
                        <geom mesh="tactile_sensor_base" material="white" class="visual" />
                        <geom mesh="tactile_sensor_base" class="collision" />
                        <body name="sensor_pad" pos="0 -5e-3 0" euler="1.570796 0 0">
                          <geom name="pad" type="box" pos="0 0 -1e-3" size="1.5e-2 1.5e-2 2e-3" contype="0" conaffinity="0" group="1" rgba="0.2 0.5 0.2 0.9" />
                          <body name="taxel1" pos="-1.450000e-02 -1.450000e-02 1.000000e-03" euler="0 0 0"><inertial mass="4.444444e-09" pos="0 0 0" fullinertia="8.888889e-13 8.888889e-13 8.888889e-13 0 0 0" /><joint name="slide_joint1" type="slide" axis="0 0 1" springdamper="0.002 0.9" frictionloss="1e-2" group="1" /><geom name="ball1" type="sphere" size="0.0005" class="collision" /><site name="tendon_site1" type="sphere" size="1e-5" group="1" /></body><body name="taxel2" pos="-1.450000e-02 -1.242857e-02 1.000000e-03" euler="0 0 0"><inertial mass="4.444444e-09" pos="0 0 0" fullinertia="8.888889e-13 8.888889e-13 8.888889e-13 0 0 0" /><joint name="slide_joint2" type="slide" axis="0 0 1" springdamper="0.002 0.9" frictionloss="1e-2" group="1" /><geom name="ball2" type="sphere" size="0.0005" class="collision" /><site name="tendon_site2" type="sphere" size="1e-5" group="1" /></body><body name="taxel3" pos="-1.450000e-02 -1.035714e-02 1.000000e-03" euler="0 0 0"><inertial mass="4.444444e-09" pos="0 0 0" fullinertia="8.888889e-13 8.888889e-13 8.888889e-13 0 0 0" /><joint name="slide_joint3" type="slide" axis="0 0 1" springdamper="0.002 0.9" frictionloss="1e-2" group="1" /><geom name="ball3" type="sphere" size="0.0005" class="collision" /><site name="tendon_site3" type="sphere" size="1e-5" group="1" /></body><body name="taxel4" pos="-1.450000e-02 -8.285714e-03 1.000000e-03" euler="0 0 0"><inertial mass="4.444444e-09" pos="0 0 0" fullinertia="8.888889e-13 8.888889e-13 8.888889e-13 0 0 0" /><joint name="slide_joint4" type="slide" axis="0 0 1" springdamper="0.002 0.9" frictionloss="1e-2" group="1" /><geom name="ball4" type="sphere" size="0.0005" class="collision" /><site name="tendon_site4" type="sphere" size="1e-5" group="1" /></body><body name="taxel5" pos="-1.450000e-02 -6.214286e-03 1.000000e-03" euler="0 0 0"><inertial mass="4.444444e-09" pos="0 0 0" fullinertia="8.888889e-13 8.888889e-13 8.888889e-13 0 0 0" /><joint name="slide_joint5" type="slide" axis="0 0 1" springdamper="0.002 0.9" frictionloss="1e-2" group="1" /><geom name="ball5" type="sphere" size="0.0005" class="collision" /><site name="tendon_site5" type="sphere" size="1e-5" group="1" /></body><body name="taxel6" pos="-1.450000e-02 -4.142857e-03 1.000000e-03" euler="0 0 0"><inertial mass="4.444444e-09" pos="0 0 0" fullinertia="8.888889e-13 8.888889e-13 8.888889e-13 0 0 0" /><joint name="slide_joint6" type="slide" axis="0 0 1" springdamper="0.002 0.9" frictionloss="1e-2" group="1" /><geom name="ball6" type="sphere" size="0.0005" class="collision" /><site name="tendon_site6" type="sphere" size="1e-5" group="1" /></body><body name="taxel7" pos="-1.450000e-02 -2.071429e-03 1.000000e-03" euler="0 0 0"><inertial mass="4.444444e-09" pos="0 0 0" fullinertia="8.888889e-13 8.888889e-13 8.888889e-13 0 0 0" /><joint name="slide_joint7" type="slide" axis="0 0 1" springdamper="0.002 0.9" frictionloss="1e-2" group="1" /><geom name="ball7" type="sphere" size="0.0005" class="collision" /><site name="tendon_site7" type="sphere" size="1e-5" group="1" /></body><body name="taxel8" pos="-1.450000e-02 0.000000e+00 1.000000e-03" euler="0 0 0"><inertial mass="4.444444e-09" pos="0 0 0" fullinertia="8.888889e-13 8.888889e-13 8.888889e-13 0 0 0" /><joint name="slide_joint8" type="slide" axis="0 0 1" springdamper="0.002 0.9" frictionloss="1e-2" group="1" /><geom name="ball8" type="sphere" size="0.0005" class="collision" /><site name="tendon_site8" type="sphere" size="1e-5" group="1" /></body><body name="taxel9" pos="-1.450000e-02 2.071429e-03 1.000000e-03" euler="0 0 0"><inertial mass="4.444444e-09" pos="0 0 0" fullinertia="8.888889e-13 8.888889e-13 8.888889e-13 0 0 0" /><joint name="slide_joint9" type="slide" axis="0 0 1" springdamper="0.002 0.9" frictionloss="1e-2" group="1" /><geom name="ball9" type="sphere" size="0.0005" class="collision" /><site name="tendon_site9" type="sphere" size="1e-5" group="1" /></body><body name="taxel10" pos="-1.450000e-02 4.142857e-03 1.000000e-03" euler="0 0 0"><inertial mass="4.444444e-09" pos="0 0 0" fullinertia="8.888889e-13 8.888889e-13 8.888889e-13 0 0 0" /><joint name="slide_joint10" type="slide" axis="0 0 1" springdamper="0.002 0.9" frictionloss="1e-2" group="1" /><geom name="ball10" type="sphere" size="0.0005" class="collision" /><site name="tendon_site10" type="sphere" size="1e-5" group="1" /></body><body name="taxel11" pos="-1.450000e-02 6.214286e-03 1.000000e-03" euler="0 0 0"><inertial mass="4.444444e-09" pos="0 0 0" fullinertia="8.888889e-13 8.888889e-13 8.888889e-13 0 0 0" /><joint name="slide_joint11" type="slide" axis="0 0 1" springdamper="0.002 0.9" frictionloss="1e-2" group="1" /><geom name="ball11" type="sphere" size="0.0005" class="collision" /><site name="tendon_site11" type="sphere" size="1e-5" group="1" /></body><body name="taxel12" pos="-1.450000e-02 8.285714e-03 1.000000e-03" euler="0 0 0"><inertial mass="4.444444e-09" pos="0 0 0" fullinertia="8.888889e-13 8.888889e-13 8.888889e-13 0 0 0" /><joint name="slide_joint12" type="slide" axis="0 0 1" springdamper="0.002 0.9" frictionloss="1e-2" group="1" /><geom name="ball12" type="sphere" size="0.0005" class="collision" /><site name="tendon_site12" type="sphere" size="1e-5" group="1" /></body><body name="taxel13" pos="-1.450000e-02 1.035714e-02 1.000000e-03" euler="0 0 0"><inertial mass="4.444444e-09" pos="0 0 0" fullinertia="8.888889e-13 8.888889e-13 8.888889e-13 0 0 0" /><joint name="slide_joint13" type="slide" axis="0 0 1" springdamper="0.002 0.9" frictionloss="1e-2" group="1" /><geom name="ball13" type="sphere" size="0.0005" class="collision" /><site name="tendon_site13" type="sphere" size="1e-5" group="1" /></body><body name="taxel14" pos="-1.450000e-02 1.242857e-02 1.000000e-03" euler="0 0 0"><inertial mass="4.444444e-09" pos="0 0 0" fullinertia="8.888889e-13 8.888889e-13 8.888889e-13 0 0 0" /><joint name="slide_joint14" type="slide" axis="0 0 1" springdamper="0.002 0.9" frictionloss="1e-2" group="1" /><geom name="ball14" type="sphere" size="0.0005" class="collision" /><site name="tendon_site14" type="sphere" size="1e-5" group="1" /></body><body name="taxel15" pos="-1.450000e-02 1.450000e-02 1.000000e-03" euler="0 0 0"><inertial mass="4.444444e-09" pos="0 0 0" fullinertia="8.888889e-13 8.888889e-13 8.888889e-13 0 0 0" /><joint name="slide_joint15" type="slide" axis="0 0 1" springdamper="0.002 0.9" frictionloss="1e-2" group="1" /><geom name="ball15" type="sphere" size="0.0005" class="collision" /><site name="tendon_site15" type="sphere" size="1e-5" group="1" /></body><body name="taxel16" pos="-1.242857e-02 -1.450000e-02 1.000000e-03" euler="0 0 0"><inertial mass="4.444444e-09" pos="0 0 0" fullinertia="8.888889e-13 8.888889e-13 8.888889e-13 0 0 0" /><joint name="slide_joint16" type="slide" axis="0 0 1" springdamper="0.002 0.9" frictionloss="1e-2" group="1" /><geom name="ball16" type="sphere" size="0.0005" class="collision" /><site name="tendon_site16" type="sphere" size="1e-5" group="1" /></body><body name="taxel17" pos="-1.242857e-02 -1.242857e-02 1.000000e-03" euler="0 0 0"><inertial mass="4.444444e-09" pos="0 0 0" fullinertia="8.888889e-13 8.888889e-13 8.888889e-13 0 0 0" /><joint name="slide_joint17" type="slide" axis="0 0 1" springdamper="0.002 0.9" frictionloss="1e-2" group="1" /><geom name="ball17" type="sphere" size="0.0005" class="collision" /><site name="tendon_site17" type="sphere" size="1e-5" group="1" /></body><body name="taxel18" pos="-1.242857e-02 -1.035714e-02 1.000000e-03" euler="0 0 0"><inertial mass="4.444444e-09" pos="0 0 0" fullinertia="8.888889e-13 8.888889e-13 8.888889e-13 0 0 0" /><joint name="slide_joint18" type="slide" axis="0 0 1" springdamper="0.002 0.9" frictionloss="1e-2" group="1" /><geom name="ball18" type="sphere" size="0.0005" class="collision" /><site name="tendon_site18" type="sphere" size="1e-5" group="1" /></body><body name="taxel19" pos="-1.242857e-02 -8.285714e-03 1.000000e-03" euler="0 0 0"><inertial mass="4.444444e-09" pos="0 0 0" fullinertia="8.888889e-13 8.888889e-13 8.888889e-13 0 0 0" /><joint name="slide_joint19" type="slide" axis="0 0 1" springdamper="0.002 0.9" frictionloss="1e-2" group="1" /><geom name="ball19" type="sphere" size="0.0005" class="collision" /><site name="tendon_site19" type="sphere" size="1e-5" group="1" /></body><body name="taxel20" pos="-1.242857e-02 -6.214286e-03 1.000000e-03" euler="0 0 0"><inertial mass="4.444444e-09" pos="0 0 0" fullinertia="8.888889e-13 8.888889e-13 8.888889e-13 0 0 0" /><joint name="slide_joint20" type="slide" axis="0 0 1" springdamper="0.002 0.9" frictionloss="1e-2" group="1" /><geom name="ball20" type="sphere" size="0.0005" class="collision" /><site name="tendon_site20" type="sphere" size="1e-5" group="1" /></body><body name="taxel21" pos="-1.242857e-02 -4.142857e-03 1.000000e-03" euler="0 0 0"><inertial mass="4.444444e-09" pos="0 0 0" fullinertia="8.888889e-13 8.888889e-13 8.888889e-13 0 0 0" /><joint name="slide_joint21" type="slide" axis="0 0 1" springdamper="0.002 0.9" frictionloss="1e-2" group="1" /><geom name="ball21" type="sphere" size="0.0005" class="collision" /><site name="tendon_site21" type="sphere" size="1e-5" group="1" /></body><body name="taxel22" pos="-1.242857e-02 -2.071429e-03 1.000000e-03" euler="0 0 0"><inertial mass="4.444444e-09" pos="0 0 0" fullinertia="8.888889e-13 8.888889e-13 8.888889e-13 0 0 0" /><joint name="slide_joint22" type="slide" axis="0 0 1" springdamper="0.002 0.9" frictionloss="1e-2" group="1" /><geom name="ball22" type="sphere" size="0.0005" class="collision" /><site name="tendon_site22" type="sphere" size="1e-5" group="1" /></body><body name="taxel23" pos="-1.242857e-02 0.000000e+00 1.000000e-03" euler="0 0 0"><inertial mass="4.444444e-09" pos="0 0 0" fullinertia="8.888889e-13 8.888889e-13 8.888889e-13 0 0 0" /><joint name="slide_joint23" type="slide" axis="0 0 1" springdamper="0.002 0.9" frictionloss="1e-2" group="1" /><geom name="ball23" type="sphere" size="0.0005" class="collision" /><site name="tendon_site23" type="sphere" size="1e-5" group="1" /></body><body name="taxel24" pos="-1.242857e-02 2.071429e-03 1.000000e-03" euler="0 0 0"><inertial mass="4.444444e-09" pos="0 0 0" fullinertia="8.888889e-13 8.888889e-13 8.888889e-13 0 0 0" /><joint name="slide_joint24" type="slide" axis="0 0 1" springdamper="0.002 0.9" frictionloss="1e-2" group="1" /><geom name="ball24" type="sphere" size="0.0005" class="collision" /><site name="tendon_site24" type="sphere" size="1e-5" group="1" /></body><body name="taxel25" pos="-1.242857e-02 4.142857e-03 1.000000e-03" euler="0 0 0"><inertial mass="4.444444e-09" pos="0 0 0" fullinertia="8.888889e-13 8.888889e-13 8.888889e-13 0 0 0" /><joint name="slide_joint25" type="slide" axis="0 0 1" springdamper="0.002 0.9" frictionloss="1e-2" group="1" /><geom name="ball25" type="sphere" size="0.0005" class="collision" /><site name="tendon_site25" type="sphere" size="1e-5" group="1" /></body><body name="taxel26" pos="-1.242857e-02 6.214286e-03 1.000000e-03" euler="0 0 0"><inertial mass="4.444444e-09" pos="0 0 0" fullinertia="8.888889e-13 8.888889e-13 8.888889e-13 0 0 0" /><joint name="slide_joint26" type="slide" axis="0 0 1" springdamper="0.002 0.9" frictionloss="1e-2" group="1" /><geom name="ball26" type="sphere" size="0.0005" class="collision" /><site name="tendon_site26" type="sphere" size="1e-5" group="1" /></body><body name="taxel27" pos="-1.242857e-02 8.285714e-03 1.000000e-03" euler="0 0 0"><inertial mass="4.444444e-09" pos="0 0 0" fullinertia="8.888889e-13 8.888889e-13 8.888889e-13 0 0 0" /><joint name="slide_joint27" type="slide" axis="0 0 1" springdamper="0.002 0.9" frictionloss="1e-2" group="1" /><geom name="ball27" type="sphere" size="0.0005" class="collision" /><site name="tendon_site27" type="sphere" size="1e-5" group="1" /></body><body name="taxel28" pos="-1.242857e-02 1.035714e-02 1.000000e-03" euler="0 0 0"><inertial mass="4.444444e-09" pos="0 0 0" fullinertia="8.888889e-13 8.888889e-13 8.888889e-13 0 0 0" /><joint name="slide_joint28" type="slide" axis="0 0 1" springdamper="0.002 0.9" frictionloss="1e-2" group="1" /><geom name="ball28" type="sphere" size="0.0005" class="collision" /><site name="tendon_site28" type="sphere" size="1e-5" group="1" /></body><body name="taxel29" pos="-1.242857e-02 1.242857e-02 1.000000e-03" euler="0 0 0"><inertial mass="4.444444e-09" pos="0 0 0" fullinertia="8.888889e-13 8.888889e-13 8.888889e-13 0 0 0" /><joint name="slide_joint29" type="slide" axis="0 0 1" springdamper="0.002 0.9" frictionloss="1e-2" group="1" /><geom name="ball29" type="sphere" size="0.0005" class="collision" /><site name="tendon_site29" type="sphere" size="1e-5" group="1" /></body><body name="taxel30" pos="-1.242857e-02 1.450000e-02 1.000000e-03" euler="0 0 0"><inertial mass="4.444444e-09" pos="0 0 0" fullinertia="8.888889e-13 8.888889e-13 8.888889e-13 0 0 0" /><joint name="slide_joint30" type="slide" axis="0 0 1" springdamper="0.002 0.9" frictionloss="1e-2" group="1" /><geom name="ball30" type="sphere" size="0.0005" class="collision" /><site name="tendon_site30" type="sphere" size="1e-5" group="1" /></body><body name="taxel31" pos="-1.035714e-02 -1.450000e-02 1.000000e-03" euler="0 0 0"><inertial mass="4.444444e-09" pos="0 0 0" fullinertia="8.888889e-13 8.888889e-13 8.888889e-13 0 0 0" /><joint name="slide_joint31" type="slide" axis="0 0 1" springdamper="0.002 0.9" frictionloss="1e-2" group="1" /><geom name="ball31" type="sphere" size="0.0005" class="collision" /><site name="tendon_site31" type="sphere" size="1e-5" group="1" /></body><body name="taxel32" pos="-1.035714e-02 -1.242857e-02 1.000000e-03" euler="0 0 0"><inertial mass="4.444444e-09" pos="0 0 0" fullinertia="8.888889e-13 8.888889e-13 8.888889e-13 0 0 0" /><joint name="slide_joint32" type="slide" axis="0 0 1" springdamper="0.002 0.9" frictionloss="1e-2" group="1" /><geom name="ball32" type="sphere" size="0.0005" class="collision" /><site name="tendon_site32" type="sphere" size="1e-5" group="1" /></body><body name="taxel33" pos="-1.035714e-02 -1.035714e-02 1.000000e-03" euler="0 0 0"><inertial mass="4.444444e-09" pos="0 0 0" fullinertia="8.888889e-13 8.888889e-13 8.888889e-13 0 0 0" /><joint name="slide_joint33" type="slide" axis="0 0 1" springdamper="0.002 0.9" frictionloss="1e-2" group="1" /><geom name="ball33" type="sphere" size="0.0005" class="collision" /><site name="tendon_site33" type="sphere" size="1e-5" group="1" /></body><body name="taxel34" pos="-1.035714e-02 -8.285714e-03 1.000000e-03" euler="0 0 0"><inertial mass="4.444444e-09" pos="0 0 0" fullinertia="8.888889e-13 8.888889e-13 8.888889e-13 0 0 0" /><joint name="slide_joint34" type="slide" axis="0 0 1" springdamper="0.002 0.9" frictionloss="1e-2" group="1" /><geom name="ball34" type="sphere" size="0.0005" class="collision" /><site name="tendon_site34" type="sphere" size="1e-5" group="1" /></body><body name="taxel35" pos="-1.035714e-02 -6.214286e-03 1.000000e-03" euler="0 0 0"><inertial mass="4.444444e-09" pos="0 0 0" fullinertia="8.888889e-13 8.888889e-13 8.888889e-13 0 0 0" /><joint name="slide_joint35" type="slide" axis="0 0 1" springdamper="0.002 0.9" frictionloss="1e-2" group="1" /><geom name="ball35" type="sphere" size="0.0005" class="collision" /><site name="tendon_site35" type="sphere" size="1e-5" group="1" /></body><body name="taxel36" pos="-1.035714e-02 -4.142857e-03 1.000000e-03" euler="0 0 0"><inertial mass="4.444444e-09" pos="0 0 0" fullinertia="8.888889e-13 8.888889e-13 8.888889e-13 0 0 0" /><joint name="slide_joint36" type="slide" axis="0 0 1" springdamper="0.002 0.9" frictionloss="1e-2" group="1" /><geom name="ball36" type="sphere" size="0.0005" class="collision" /><site name="tendon_site36" type="sphere" size="1e-5" group="1" /></body><body name="taxel37" pos="-1.035714e-02 -2.071429e-03 1.000000e-03" euler="0 0 0"><inertial mass="4.444444e-09" pos="0 0 0" fullinertia="8.888889e-13 8.888889e-13 8.888889e-13 0 0 0" /><joint name="slide_joint37" type="slide" axis="0 0 1" springdamper="0.002 0.9" frictionloss="1e-2" group="1" /><geom name="ball37" type="sphere" size="0.0005" class="collision" /><site name="tendon_site37" type="sphere" size="1e-5" group="1" /></body><body name="taxel38" pos="-1.035714e-02 0.000000e+00 1.000000e-03" euler="0 0 0"><inertial mass="4.444444e-09" pos="0 0 0" fullinertia="8.888889e-13 8.888889e-13 8.888889e-13 0 0 0" /><joint name="slide_joint38" type="slide" axis="0 0 1" springdamper="0.002 0.9" frictionloss="1e-2" group="1" /><geom name="ball38" type="sphere" size="0.0005" class="collision" /><site name="tendon_site38" type="sphere" size="1e-5" group="1" /></body><body name="taxel39" pos="-1.035714e-02 2.071429e-03 1.000000e-03" euler="0 0 0"><inertial mass="4.444444e-09" pos="0 0 0" fullinertia="8.888889e-13 8.888889e-13 8.888889e-13 0 0 0" /><joint name="slide_joint39" type="slide" axis="0 0 1" springdamper="0.002 0.9" frictionloss="1e-2" group="1" /><geom name="ball39" type="sphere" size="0.0005" class="collision" /><site name="tendon_site39" type="sphere" size="1e-5" group="1" /></body><body name="taxel40" pos="-1.035714e-02 4.142857e-03 1.000000e-03" euler="0 0 0"><inertial mass="4.444444e-09" pos="0 0 0" fullinertia="8.888889e-13 8.888889e-13 8.888889e-13 0 0 0" /><joint name="slide_joint40" type="slide" axis="0 0 1" springdamper="0.002 0.9" frictionloss="1e-2" group="1" /><geom name="ball40" type="sphere" size="0.0005" class="collision" /><site name="tendon_site40" type="sphere" size="1e-5" group="1" /></body><body name="taxel41" pos="-1.035714e-02 6.214286e-03 1.000000e-03" euler="0 0 0"><inertial mass="4.444444e-09" pos="0 0 0" fullinertia="8.888889e-13 8.888889e-13 8.888889e-13 0 0 0" /><joint name="slide_joint41" type="slide" axis="0 0 1" springdamper="0.002 0.9" frictionloss="1e-2" group="1" /><geom name="ball41" type="sphere" size="0.0005" class="collision" /><site name="tendon_site41" type="sphere" size="1e-5" group="1" /></body><body name="taxel42" pos="-1.035714e-02 8.285714e-03 1.000000e-03" euler="0 0 0"><inertial mass="4.444444e-09" pos="0 0 0" fullinertia="8.888889e-13 8.888889e-13 8.888889e-13 0 0 0" /><joint name="slide_joint42" type="slide" axis="0 0 1" springdamper="0.002 0.9" frictionloss="1e-2" group="1" /><geom name="ball42" type="sphere" size="0.0005" class="collision" /><site name="tendon_site42" type="sphere" size="1e-5" group="1" /></body><body name="taxel43" pos="-1.035714e-02 1.035714e-02 1.000000e-03" euler="0 0 0"><inertial mass="4.444444e-09" pos="0 0 0" fullinertia="8.888889e-13 8.888889e-13 8.888889e-13 0 0 0" /><joint name="slide_joint43" type="slide" axis="0 0 1" springdamper="0.002 0.9" frictionloss="1e-2" group="1" /><geom name="ball43" type="sphere" size="0.0005" class="collision" /><site name="tendon_site43" type="sphere" size="1e-5" group="1" /></body><body name="taxel44" pos="-1.035714e-02 1.242857e-02 1.000000e-03" euler="0 0 0"><inertial mass="4.444444e-09" pos="0 0 0" fullinertia="8.888889e-13 8.888889e-13 8.888889e-13 0 0 0" /><joint name="slide_joint44" type="slide" axis="0 0 1" springdamper="0.002 0.9" frictionloss="1e-2" group="1" /><geom name="ball44" type="sphere" size="0.0005" class="collision" /><site name="tendon_site44" type="sphere" size="1e-5" group="1" /></body><body name="taxel45" pos="-1.035714e-02 1.450000e-02 1.000000e-03" euler="0 0 0"><inertial mass="4.444444e-09" pos="0 0 0" fullinertia="8.888889e-13 8.888889e-13 8.888889e-13 0 0 0" /><joint name="slide_joint45" type="slide" axis="0 0 1" springdamper="0.002 0.9" frictionloss="1e-2" group="1" /><geom name="ball45" type="sphere" size="0.0005" class="collision" /><site name="tendon_site45" type="sphere" size="1e-5" group="1" /></body><body name="taxel46" pos="-8.285714e-03 -1.450000e-02 1.000000e-03" euler="0 0 0"><inertial mass="4.444444e-09" pos="0 0 0" fullinertia="8.888889e-13 8.888889e-13 8.888889e-13 0 0 0" /><joint name="slide_joint46" type="slide" axis="0 0 1" springdamper="0.002 0.9" frictionloss="1e-2" group="1" /><geom name="ball46" type="sphere" size="0.0005" class="collision" /><site name="tendon_site46" type="sphere" size="1e-5" group="1" /></body><body name="taxel47" pos="-8.285714e-03 -1.242857e-02 1.000000e-03" euler="0 0 0"><inertial mass="4.444444e-09" pos="0 0 0" fullinertia="8.888889e-13 8.888889e-13 8.888889e-13 0 0 0" /><joint name="slide_joint47" type="slide" axis="0 0 1" springdamper="0.002 0.9" frictionloss="1e-2" group="1" /><geom name="ball47" type="sphere" size="0.0005" class="collision" /><site name="tendon_site47" type="sphere" size="1e-5" group="1" /></body><body name="taxel48" pos="-8.285714e-03 -1.035714e-02 1.000000e-03" euler="0 0 0"><inertial mass="4.444444e-09" pos="0 0 0" fullinertia="8.888889e-13 8.888889e-13 8.888889e-13 0 0 0" /><joint name="slide_joint48" type="slide" axis="0 0 1" springdamper="0.002 0.9" frictionloss="1e-2" group="1" /><geom name="ball48" type="sphere" size="0.0005" class="collision" /><site name="tendon_site48" type="sphere" size="1e-5" group="1" /></body><body name="taxel49" pos="-8.285714e-03 -8.285714e-03 1.000000e-03" euler="0 0 0"><inertial mass="4.444444e-09" pos="0 0 0" fullinertia="8.888889e-13 8.888889e-13 8.888889e-13 0 0 0" /><joint name="slide_joint49" type="slide" axis="0 0 1" springdamper="0.002 0.9" frictionloss="1e-2" group="1" /><geom name="ball49" type="sphere" size="0.0005" class="collision" /><site name="tendon_site49" type="sphere" size="1e-5" group="1" /></body><body name="taxel50" pos="-8.285714e-03 -6.214286e-03 1.000000e-03" euler="0 0 0"><inertial mass="4.444444e-09" pos="0 0 0" fullinertia="8.888889e-13 8.888889e-13 8.888889e-13 0 0 0" /><joint name="slide_joint50" type="slide" axis="0 0 1" springdamper="0.002 0.9" frictionloss="1e-2" group="1" /><geom name="ball50" type="sphere" size="0.0005" class="collision" /><site name="tendon_site50" type="sphere" size="1e-5" group="1" /></body><body name="taxel51" pos="-8.285714e-03 -4.142857e-03 1.000000e-03" euler="0 0 0"><inertial mass="4.444444e-09" pos="0 0 0" fullinertia="8.888889e-13 8.888889e-13 8.888889e-13 0 0 0" /><joint name="slide_joint51" type="slide" axis="0 0 1" springdamper="0.002 0.9" frictionloss="1e-2" group="1" /><geom name="ball51" type="sphere" size="0.0005" class="collision" /><site name="tendon_site51" type="sphere" size="1e-5" group="1" /></body><body name="taxel52" pos="-8.285714e-03 -2.071429e-03 1.000000e-03" euler="0 0 0"><inertial mass="4.444444e-09" pos="0 0 0" fullinertia="8.888889e-13 8.888889e-13 8.888889e-13 0 0 0" /><joint name="slide_joint52" type="slide" axis="0 0 1" springdamper="0.002 0.9" frictionloss="1e-2" group="1" /><geom name="ball52" type="sphere" size="0.0005" class="collision" /><site name="tendon_site52" type="sphere" size="1e-5" group="1" /></body><body name="taxel53" pos="-8.285714e-03 0.000000e+00 1.000000e-03" euler="0 0 0"><inertial mass="4.444444e-09" pos="0 0 0" fullinertia="8.888889e-13 8.888889e-13 8.888889e-13 0 0 0" /><joint name="slide_joint53" type="slide" axis="0 0 1" springdamper="0.002 0.9" frictionloss="1e-2" group="1" /><geom name="ball53" type="sphere" size="0.0005" class="collision" /><site name="tendon_site53" type="sphere" size="1e-5" group="1" /></body><body name="taxel54" pos="-8.285714e-03 2.071429e-03 1.000000e-03" euler="0 0 0"><inertial mass="4.444444e-09" pos="0 0 0" fullinertia="8.888889e-13 8.888889e-13 8.888889e-13 0 0 0" /><joint name="slide_joint54" type="slide" axis="0 0 1" springdamper="0.002 0.9" frictionloss="1e-2" group="1" /><geom name="ball54" type="sphere" size="0.0005" class="collision" /><site name="tendon_site54" type="sphere" size="1e-5" group="1" /></body><body name="taxel55" pos="-8.285714e-03 4.142857e-03 1.000000e-03" euler="0 0 0"><inertial mass="4.444444e-09" pos="0 0 0" fullinertia="8.888889e-13 8.888889e-13 8.888889e-13 0 0 0" /><joint name="slide_joint55" type="slide" axis="0 0 1" springdamper="0.002 0.9" frictionloss="1e-2" group="1" /><geom name="ball55" type="sphere" size="0.0005" class="collision" /><site name="tendon_site55" type="sphere" size="1e-5" group="1" /></body><body name="taxel56" pos="-8.285714e-03 6.214286e-03 1.000000e-03" euler="0 0 0"><inertial mass="4.444444e-09" pos="0 0 0" fullinertia="8.888889e-13 8.888889e-13 8.888889e-13 0 0 0" /><joint name="slide_joint56" type="slide" axis="0 0 1" springdamper="0.002 0.9" frictionloss="1e-2" group="1" /><geom name="ball56" type="sphere" size="0.0005" class="collision" /><site name="tendon_site56" type="sphere" size="1e-5" group="1" /></body><body name="taxel57" pos="-8.285714e-03 8.285714e-03 1.000000e-03" euler="0 0 0"><inertial mass="4.444444e-09" pos="0 0 0" fullinertia="8.888889e-13 8.888889e-13 8.888889e-13 0 0 0" /><joint name="slide_joint57" type="slide" axis="0 0 1" springdamper="0.002 0.9" frictionloss="1e-2" group="1" /><geom name="ball57" type="sphere" size="0.0005" class="collision" /><site name="tendon_site57" type="sphere" size="1e-5" group="1" /></body><body name="taxel58" pos="-8.285714e-03 1.035714e-02 1.000000e-03" euler="0 0 0"><inertial mass="4.444444e-09" pos="0 0 0" fullinertia="8.888889e-13 8.888889e-13 8.888889e-13 0 0 0" /><joint name="slide_joint58" type="slide" axis="0 0 1" springdamper="0.002 0.9" frictionloss="1e-2" group="1" /><geom name="ball58" type="sphere" size="0.0005" class="collision" /><site name="tendon_site58" type="sphere" size="1e-5" group="1" /></body><body name="taxel59" pos="-8.285714e-03 1.242857e-02 1.000000e-03" euler="0 0 0"><inertial mass="4.444444e-09" pos="0 0 0" fullinertia="8.888889e-13 8.888889e-13 8.888889e-13 0 0 0" /><joint name="slide_joint59" type="slide" axis="0 0 1" springdamper="0.002 0.9" frictionloss="1e-2" group="1" /><geom name="ball59" type="sphere" size="0.0005" class="collision" /><site name="tendon_site59" type="sphere" size="1e-5" group="1" /></body><body name="taxel60" pos="-8.285714e-03 1.450000e-02 1.000000e-03" euler="0 0 0"><inertial mass="4.444444e-09" pos="0 0 0" fullinertia="8.888889e-13 8.888889e-13 8.888889e-13 0 0 0" /><joint name="slide_joint60" type="slide" axis="0 0 1" springdamper="0.002 0.9" frictionloss="1e-2" group="1" /><geom name="ball60" type="sphere" size="0.0005" class="collision" /><site name="tendon_site60" type="sphere" size="1e-5" group="1" /></body><body name="taxel61" pos="-6.214286e-03 -1.450000e-02 1.000000e-03" euler="0 0 0"><inertial mass="4.444444e-09" pos="0 0 0" fullinertia="8.888889e-13 8.888889e-13 8.888889e-13 0 0 0" /><joint name="slide_joint61" type="slide" axis="0 0 1" springdamper="0.002 0.9" frictionloss="1e-2" group="1" /><geom name="ball61" type="sphere" size="0.0005" class="collision" /><site name="tendon_site61" type="sphere" size="1e-5" group="1" /></body><body name="taxel62" pos="-6.214286e-03 -1.242857e-02 1.000000e-03" euler="0 0 0"><inertial mass="4.444444e-09" pos="0 0 0" fullinertia="8.888889e-13 8.888889e-13 8.888889e-13 0 0 0" /><joint name="slide_joint62" type="slide" axis="0 0 1" springdamper="0.002 0.9" frictionloss="1e-2" group="1" /><geom name="ball62" type="sphere" size="0.0005" class="collision" /><site name="tendon_site62" type="sphere" size="1e-5" group="1" /></body><body name="taxel63" pos="-6.214286e-03 -1.035714e-02 1.000000e-03" euler="0 0 0"><inertial mass="4.444444e-09" pos="0 0 0" fullinertia="8.888889e-13 8.888889e-13 8.888889e-13 0 0 0" /><joint name="slide_joint63" type="slide" axis="0 0 1" springdamper="0.002 0.9" frictionloss="1e-2" group="1" /><geom name="ball63" type="sphere" size="0.0005" class="collision" /><site name="tendon_site63" type="sphere" size="1e-5" group="1" /></body><body name="taxel64" pos="-6.214286e-03 -8.285714e-03 1.000000e-03" euler="0 0 0"><inertial mass="4.444444e-09" pos="0 0 0" fullinertia="8.888889e-13 8.888889e-13 8.888889e-13 0 0 0" /><joint name="slide_joint64" type="slide" axis="0 0 1" springdamper="0.002 0.9" frictionloss="1e-2" group="1" /><geom name="ball64" type="sphere" size="0.0005" class="collision" /><site name="tendon_site64" type="sphere" size="1e-5" group="1" /></body><body name="taxel65" pos="-6.214286e-03 -6.214286e-03 1.000000e-03" euler="0 0 0"><inertial mass="4.444444e-09" pos="0 0 0" fullinertia="8.888889e-13 8.888889e-13 8.888889e-13 0 0 0" /><joint name="slide_joint65" type="slide" axis="0 0 1" springdamper="0.002 0.9" frictionloss="1e-2" group="1" /><geom name="ball65" type="sphere" size="0.0005" class="collision" /><site name="tendon_site65" type="sphere" size="1e-5" group="1" /></body><body name="taxel66" pos="-6.214286e-03 -4.142857e-03 1.000000e-03" euler="0 0 0"><inertial mass="4.444444e-09" pos="0 0 0" fullinertia="8.888889e-13 8.888889e-13 8.888889e-13 0 0 0" /><joint name="slide_joint66" type="slide" axis="0 0 1" springdamper="0.002 0.9" frictionloss="1e-2" group="1" /><geom name="ball66" type="sphere" size="0.0005" class="collision" /><site name="tendon_site66" type="sphere" size="1e-5" group="1" /></body><body name="taxel67" pos="-6.214286e-03 -2.071429e-03 1.000000e-03" euler="0 0 0"><inertial mass="4.444444e-09" pos="0 0 0" fullinertia="8.888889e-13 8.888889e-13 8.888889e-13 0 0 0" /><joint name="slide_joint67" type="slide" axis="0 0 1" springdamper="0.002 0.9" frictionloss="1e-2" group="1" /><geom name="ball67" type="sphere" size="0.0005" class="collision" /><site name="tendon_site67" type="sphere" size="1e-5" group="1" /></body><body name="taxel68" pos="-6.214286e-03 0.000000e+00 1.000000e-03" euler="0 0 0"><inertial mass="4.444444e-09" pos="0 0 0" fullinertia="8.888889e-13 8.888889e-13 8.888889e-13 0 0 0" /><joint name="slide_joint68" type="slide" axis="0 0 1" springdamper="0.002 0.9" frictionloss="1e-2" group="1" /><geom name="ball68" type="sphere" size="0.0005" class="collision" /><site name="tendon_site68" type="sphere" size="1e-5" group="1" /></body><body name="taxel69" pos="-6.214286e-03 2.071429e-03 1.000000e-03" euler="0 0 0"><inertial mass="4.444444e-09" pos="0 0 0" fullinertia="8.888889e-13 8.888889e-13 8.888889e-13 0 0 0" /><joint name="slide_joint69" type="slide" axis="0 0 1" springdamper="0.002 0.9" frictionloss="1e-2" group="1" /><geom name="ball69" type="sphere" size="0.0005" class="collision" /><site name="tendon_site69" type="sphere" size="1e-5" group="1" /></body><body name="taxel70" pos="-6.214286e-03 4.142857e-03 1.000000e-03" euler="0 0 0"><inertial mass="4.444444e-09" pos="0 0 0" fullinertia="8.888889e-13 8.888889e-13 8.888889e-13 0 0 0" /><joint name="slide_joint70" type="slide" axis="0 0 1" springdamper="0.002 0.9" frictionloss="1e-2" group="1" /><geom name="ball70" type="sphere" size="0.0005" class="collision" /><site name="tendon_site70" type="sphere" size="1e-5" group="1" /></body><body name="taxel71" pos="-6.214286e-03 6.214286e-03 1.000000e-03" euler="0 0 0"><inertial mass="4.444444e-09" pos="0 0 0" fullinertia="8.888889e-13 8.888889e-13 8.888889e-13 0 0 0" /><joint name="slide_joint71" type="slide" axis="0 0 1" springdamper="0.002 0.9" frictionloss="1e-2" group="1" /><geom name="ball71" type="sphere" size="0.0005" class="collision" /><site name="tendon_site71" type="sphere" size="1e-5" group="1" /></body><body name="taxel72" pos="-6.214286e-03 8.285714e-03 1.000000e-03" euler="0 0 0"><inertial mass="4.444444e-09" pos="0 0 0" fullinertia="8.888889e-13 8.888889e-13 8.888889e-13 0 0 0" /><joint name="slide_joint72" type="slide" axis="0 0 1" springdamper="0.002 0.9" frictionloss="1e-2" group="1" /><geom name="ball72" type="sphere" size="0.0005" class="collision" /><site name="tendon_site72" type="sphere" size="1e-5" group="1" /></body><body name="taxel73" pos="-6.214286e-03 1.035714e-02 1.000000e-03" euler="0 0 0"><inertial mass="4.444444e-09" pos="0 0 0" fullinertia="8.888889e-13 8.888889e-13 8.888889e-13 0 0 0" /><joint name="slide_joint73" type="slide" axis="0 0 1" springdamper="0.002 0.9" frictionloss="1e-2" group="1" /><geom name="ball73" type="sphere" size="0.0005" class="collision" /><site name="tendon_site73" type="sphere" size="1e-5" group="1" /></body><body name="taxel74" pos="-6.214286e-03 1.242857e-02 1.000000e-03" euler="0 0 0"><inertial mass="4.444444e-09" pos="0 0 0" fullinertia="8.888889e-13 8.888889e-13 8.888889e-13 0 0 0" /><joint name="slide_joint74" type="slide" axis="0 0 1" springdamper="0.002 0.9" frictionloss="1e-2" group="1" /><geom name="ball74" type="sphere" size="0.0005" class="collision" /><site name="tendon_site74" type="sphere" size="1e-5" group="1" /></body><body name="taxel75" pos="-6.214286e-03 1.450000e-02 1.000000e-03" euler="0 0 0"><inertial mass="4.444444e-09" pos="0 0 0" fullinertia="8.888889e-13 8.888889e-13 8.888889e-13 0 0 0" /><joint name="slide_joint75" type="slide" axis="0 0 1" springdamper="0.002 0.9" frictionloss="1e-2" group="1" /><geom name="ball75" type="sphere" size="0.0005" class="collision" /><site name="tendon_site75" type="sphere" size="1e-5" group="1" /></body><body name="taxel76" pos="-4.142857e-03 -1.450000e-02 1.000000e-03" euler="0 0 0"><inertial mass="4.444444e-09" pos="0 0 0" fullinertia="8.888889e-13 8.888889e-13 8.888889e-13 0 0 0" /><joint name="slide_joint76" type="slide" axis="0 0 1" springdamper="0.002 0.9" frictionloss="1e-2" group="1" /><geom name="ball76" type="sphere" size="0.0005" class="collision" /><site name="tendon_site76" type="sphere" size="1e-5" group="1" /></body><body name="taxel77" pos="-4.142857e-03 -1.242857e-02 1.000000e-03" euler="0 0 0"><inertial mass="4.444444e-09" pos="0 0 0" fullinertia="8.888889e-13 8.888889e-13 8.888889e-13 0 0 0" /><joint name="slide_joint77" type="slide" axis="0 0 1" springdamper="0.002 0.9" frictionloss="1e-2" group="1" /><geom name="ball77" type="sphere" size="0.0005" class="collision" /><site name="tendon_site77" type="sphere" size="1e-5" group="1" /></body><body name="taxel78" pos="-4.142857e-03 -1.035714e-02 1.000000e-03" euler="0 0 0"><inertial mass="4.444444e-09" pos="0 0 0" fullinertia="8.888889e-13 8.888889e-13 8.888889e-13 0 0 0" /><joint name="slide_joint78" type="slide" axis="0 0 1" springdamper="0.002 0.9" frictionloss="1e-2" group="1" /><geom name="ball78" type="sphere" size="0.0005" class="collision" /><site name="tendon_site78" type="sphere" size="1e-5" group="1" /></body><body name="taxel79" pos="-4.142857e-03 -8.285714e-03 1.000000e-03" euler="0 0 0"><inertial mass="4.444444e-09" pos="0 0 0" fullinertia="8.888889e-13 8.888889e-13 8.888889e-13 0 0 0" /><joint name="slide_joint79" type="slide" axis="0 0 1" springdamper="0.002 0.9" frictionloss="1e-2" group="1" /><geom name="ball79" type="sphere" size="0.0005" class="collision" /><site name="tendon_site79" type="sphere" size="1e-5" group="1" /></body><body name="taxel80" pos="-4.142857e-03 -6.214286e-03 1.000000e-03" euler="0 0 0"><inertial mass="4.444444e-09" pos="0 0 0" fullinertia="8.888889e-13 8.888889e-13 8.888889e-13 0 0 0" /><joint name="slide_joint80" type="slide" axis="0 0 1" springdamper="0.002 0.9" frictionloss="1e-2" group="1" /><geom name="ball80" type="sphere" size="0.0005" class="collision" /><site name="tendon_site80" type="sphere" size="1e-5" group="1" /></body><body name="taxel81" pos="-4.142857e-03 -4.142857e-03 1.000000e-03" euler="0 0 0"><inertial mass="4.444444e-09" pos="0 0 0" fullinertia="8.888889e-13 8.888889e-13 8.888889e-13 0 0 0" /><joint name="slide_joint81" type="slide" axis="0 0 1" springdamper="0.002 0.9" frictionloss="1e-2" group="1" /><geom name="ball81" type="sphere" size="0.0005" class="collision" /><site name="tendon_site81" type="sphere" size="1e-5" group="1" /></body><body name="taxel82" pos="-4.142857e-03 -2.071429e-03 1.000000e-03" euler="0 0 0"><inertial mass="4.444444e-09" pos="0 0 0" fullinertia="8.888889e-13 8.888889e-13 8.888889e-13 0 0 0" /><joint name="slide_joint82" type="slide" axis="0 0 1" springdamper="0.002 0.9" frictionloss="1e-2" group="1" /><geom name="ball82" type="sphere" size="0.0005" class="collision" /><site name="tendon_site82" type="sphere" size="1e-5" group="1" /></body><body name="taxel83" pos="-4.142857e-03 0.000000e+00 1.000000e-03" euler="0 0 0"><inertial mass="4.444444e-09" pos="0 0 0" fullinertia="8.888889e-13 8.888889e-13 8.888889e-13 0 0 0" /><joint name="slide_joint83" type="slide" axis="0 0 1" springdamper="0.002 0.9" frictionloss="1e-2" group="1" /><geom name="ball83" type="sphere" size="0.0005" class="collision" /><site name="tendon_site83" type="sphere" size="1e-5" group="1" /></body><body name="taxel84" pos="-4.142857e-03 2.071429e-03 1.000000e-03" euler="0 0 0"><inertial mass="4.444444e-09" pos="0 0 0" fullinertia="8.888889e-13 8.888889e-13 8.888889e-13 0 0 0" /><joint name="slide_joint84" type="slide" axis="0 0 1" springdamper="0.002 0.9" frictionloss="1e-2" group="1" /><geom name="ball84" type="sphere" size="0.0005" class="collision" /><site name="tendon_site84" type="sphere" size="1e-5" group="1" /></body><body name="taxel85" pos="-4.142857e-03 4.142857e-03 1.000000e-03" euler="0 0 0"><inertial mass="4.444444e-09" pos="0 0 0" fullinertia="8.888889e-13 8.888889e-13 8.888889e-13 0 0 0" /><joint name="slide_joint85" type="slide" axis="0 0 1" springdamper="0.002 0.9" frictionloss="1e-2" group="1" /><geom name="ball85" type="sphere" size="0.0005" class="collision" /><site name="tendon_site85" type="sphere" size="1e-5" group="1" /></body><body name="taxel86" pos="-4.142857e-03 6.214286e-03 1.000000e-03" euler="0 0 0"><inertial mass="4.444444e-09" pos="0 0 0" fullinertia="8.888889e-13 8.888889e-13 8.888889e-13 0 0 0" /><joint name="slide_joint86" type="slide" axis="0 0 1" springdamper="0.002 0.9" frictionloss="1e-2" group="1" /><geom name="ball86" type="sphere" size="0.0005" class="collision" /><site name="tendon_site86" type="sphere" size="1e-5" group="1" /></body><body name="taxel87" pos="-4.142857e-03 8.285714e-03 1.000000e-03" euler="0 0 0"><inertial mass="4.444444e-09" pos="0 0 0" fullinertia="8.888889e-13 8.888889e-13 8.888889e-13 0 0 0" /><joint name="slide_joint87" type="slide" axis="0 0 1" springdamper="0.002 0.9" frictionloss="1e-2" group="1" /><geom name="ball87" type="sphere" size="0.0005" class="collision" /><site name="tendon_site87" type="sphere" size="1e-5" group="1" /></body><body name="taxel88" pos="-4.142857e-03 1.035714e-02 1.000000e-03" euler="0 0 0"><inertial mass="4.444444e-09" pos="0 0 0" fullinertia="8.888889e-13 8.888889e-13 8.888889e-13 0 0 0" /><joint name="slide_joint88" type="slide" axis="0 0 1" springdamper="0.002 0.9" frictionloss="1e-2" group="1" /><geom name="ball88" type="sphere" size="0.0005" class="collision" /><site name="tendon_site88" type="sphere" size="1e-5" group="1" /></body><body name="taxel89" pos="-4.142857e-03 1.242857e-02 1.000000e-03" euler="0 0 0"><inertial mass="4.444444e-09" pos="0 0 0" fullinertia="8.888889e-13 8.888889e-13 8.888889e-13 0 0 0" /><joint name="slide_joint89" type="slide" axis="0 0 1" springdamper="0.002 0.9" frictionloss="1e-2" group="1" /><geom name="ball89" type="sphere" size="0.0005" class="collision" /><site name="tendon_site89" type="sphere" size="1e-5" group="1" /></body><body name="taxel90" pos="-4.142857e-03 1.450000e-02 1.000000e-03" euler="0 0 0"><inertial mass="4.444444e-09" pos="0 0 0" fullinertia="8.888889e-13 8.888889e-13 8.888889e-13 0 0 0" /><joint name="slide_joint90" type="slide" axis="0 0 1" springdamper="0.002 0.9" frictionloss="1e-2" group="1" /><geom name="ball90" type="sphere" size="0.0005" class="collision" /><site name="tendon_site90" type="sphere" size="1e-5" group="1" /></body><body name="taxel91" pos="-2.071429e-03 -1.450000e-02 1.000000e-03" euler="0 0 0"><inertial mass="4.444444e-09" pos="0 0 0" fullinertia="8.888889e-13 8.888889e-13 8.888889e-13 0 0 0" /><joint name="slide_joint91" type="slide" axis="0 0 1" springdamper="0.002 0.9" frictionloss="1e-2" group="1" /><geom name="ball91" type="sphere" size="0.0005" class="collision" /><site name="tendon_site91" type="sphere" size="1e-5" group="1" /></body><body name="taxel92" pos="-2.071429e-03 -1.242857e-02 1.000000e-03" euler="0 0 0"><inertial mass="4.444444e-09" pos="0 0 0" fullinertia="8.888889e-13 8.888889e-13 8.888889e-13 0 0 0" /><joint name="slide_joint92" type="slide" axis="0 0 1" springdamper="0.002 0.9" frictionloss="1e-2" group="1" /><geom name="ball92" type="sphere" size="0.0005" class="collision" /><site name="tendon_site92" type="sphere" size="1e-5" group="1" /></body><body name="taxel93" pos="-2.071429e-03 -1.035714e-02 1.000000e-03" euler="0 0 0"><inertial mass="4.444444e-09" pos="0 0 0" fullinertia="8.888889e-13 8.888889e-13 8.888889e-13 0 0 0" /><joint name="slide_joint93" type="slide" axis="0 0 1" springdamper="0.002 0.9" frictionloss="1e-2" group="1" /><geom name="ball93" type="sphere" size="0.0005" class="collision" /><site name="tendon_site93" type="sphere" size="1e-5" group="1" /></body><body name="taxel94" pos="-2.071429e-03 -8.285714e-03 1.000000e-03" euler="0 0 0"><inertial mass="4.444444e-09" pos="0 0 0" fullinertia="8.888889e-13 8.888889e-13 8.888889e-13 0 0 0" /><joint name="slide_joint94" type="slide" axis="0 0 1" springdamper="0.002 0.9" frictionloss="1e-2" group="1" /><geom name="ball94" type="sphere" size="0.0005" class="collision" /><site name="tendon_site94" type="sphere" size="1e-5" group="1" /></body><body name="taxel95" pos="-2.071429e-03 -6.214286e-03 1.000000e-03" euler="0 0 0"><inertial mass="4.444444e-09" pos="0 0 0" fullinertia="8.888889e-13 8.888889e-13 8.888889e-13 0 0 0" /><joint name="slide_joint95" type="slide" axis="0 0 1" springdamper="0.002 0.9" frictionloss="1e-2" group="1" /><geom name="ball95" type="sphere" size="0.0005" class="collision" /><site name="tendon_site95" type="sphere" size="1e-5" group="1" /></body><body name="taxel96" pos="-2.071429e-03 -4.142857e-03 1.000000e-03" euler="0 0 0"><inertial mass="4.444444e-09" pos="0 0 0" fullinertia="8.888889e-13 8.888889e-13 8.888889e-13 0 0 0" /><joint name="slide_joint96" type="slide" axis="0 0 1" springdamper="0.002 0.9" frictionloss="1e-2" group="1" /><geom name="ball96" type="sphere" size="0.0005" class="collision" /><site name="tendon_site96" type="sphere" size="1e-5" group="1" /></body><body name="taxel97" pos="-2.071429e-03 -2.071429e-03 1.000000e-03" euler="0 0 0"><inertial mass="4.444444e-09" pos="0 0 0" fullinertia="8.888889e-13 8.888889e-13 8.888889e-13 0 0 0" /><joint name="slide_joint97" type="slide" axis="0 0 1" springdamper="0.002 0.9" frictionloss="1e-2" group="1" /><geom name="ball97" type="sphere" size="0.0005" class="collision" /><site name="tendon_site97" type="sphere" size="1e-5" group="1" /></body><body name="taxel98" pos="-2.071429e-03 0.000000e+00 1.000000e-03" euler="0 0 0"><inertial mass="4.444444e-09" pos="0 0 0" fullinertia="8.888889e-13 8.888889e-13 8.888889e-13 0 0 0" /><joint name="slide_joint98" type="slide" axis="0 0 1" springdamper="0.002 0.9" frictionloss="1e-2" group="1" /><geom name="ball98" type="sphere" size="0.0005" class="collision" /><site name="tendon_site98" type="sphere" size="1e-5" group="1" /></body><body name="taxel99" pos="-2.071429e-03 2.071429e-03 1.000000e-03" euler="0 0 0"><inertial mass="4.444444e-09" pos="0 0 0" fullinertia="8.888889e-13 8.888889e-13 8.888889e-13 0 0 0" /><joint name="slide_joint99" type="slide" axis="0 0 1" springdamper="0.002 0.9" frictionloss="1e-2" group="1" /><geom name="ball99" type="sphere" size="0.0005" class="collision" /><site name="tendon_site99" type="sphere" size="1e-5" group="1" /></body><body name="taxel100" pos="-2.071429e-03 4.142857e-03 1.000000e-03" euler="0 0 0"><inertial mass="4.444444e-09" pos="0 0 0" fullinertia="8.888889e-13 8.888889e-13 8.888889e-13 0 0 0" /><joint name="slide_joint100" type="slide" axis="0 0 1" springdamper="0.002 0.9" frictionloss="1e-2" group="1" /><geom name="ball100" type="sphere" size="0.0005" class="collision" /><site name="tendon_site100" type="sphere" size="1e-5" group="1" /></body><body name="taxel101" pos="-2.071429e-03 6.214286e-03 1.000000e-03" euler="0 0 0"><inertial mass="4.444444e-09" pos="0 0 0" fullinertia="8.888889e-13 8.888889e-13 8.888889e-13 0 0 0" /><joint name="slide_joint101" type="slide" axis="0 0 1" springdamper="0.002 0.9" frictionloss="1e-2" group="1" /><geom name="ball101" type="sphere" size="0.0005" class="collision" /><site name="tendon_site101" type="sphere" size="1e-5" group="1" /></body><body name="taxel102" pos="-2.071429e-03 8.285714e-03 1.000000e-03" euler="0 0 0"><inertial mass="4.444444e-09" pos="0 0 0" fullinertia="8.888889e-13 8.888889e-13 8.888889e-13 0 0 0" /><joint name="slide_joint102" type="slide" axis="0 0 1" springdamper="0.002 0.9" frictionloss="1e-2" group="1" /><geom name="ball102" type="sphere" size="0.0005" class="collision" /><site name="tendon_site102" type="sphere" size="1e-5" group="1" /></body><body name="taxel103" pos="-2.071429e-03 1.035714e-02 1.000000e-03" euler="0 0 0"><inertial mass="4.444444e-09" pos="0 0 0" fullinertia="8.888889e-13 8.888889e-13 8.888889e-13 0 0 0" /><joint name="slide_joint103" type="slide" axis="0 0 1" springdamper="0.002 0.9" frictionloss="1e-2" group="1" /><geom name="ball103" type="sphere" size="0.0005" class="collision" /><site name="tendon_site103" type="sphere" size="1e-5" group="1" /></body><body name="taxel104" pos="-2.071429e-03 1.242857e-02 1.000000e-03" euler="0 0 0"><inertial mass="4.444444e-09" pos="0 0 0" fullinertia="8.888889e-13 8.888889e-13 8.888889e-13 0 0 0" /><joint name="slide_joint104" type="slide" axis="0 0 1" springdamper="0.002 0.9" frictionloss="1e-2" group="1" /><geom name="ball104" type="sphere" size="0.0005" class="collision" /><site name="tendon_site104" type="sphere" size="1e-5" group="1" /></body><body name="taxel105" pos="-2.071429e-03 1.450000e-02 1.000000e-03" euler="0 0 0"><inertial mass="4.444444e-09" pos="0 0 0" fullinertia="8.888889e-13 8.888889e-13 8.888889e-13 0 0 0" /><joint name="slide_joint105" type="slide" axis="0 0 1" springdamper="0.002 0.9" frictionloss="1e-2" group="1" /><geom name="ball105" type="sphere" size="0.0005" class="collision" /><site name="tendon_site105" type="sphere" size="1e-5" group="1" /></body><body name="taxel106" pos="0.000000e+00 -1.450000e-02 1.000000e-03" euler="0 0 0"><inertial mass="4.444444e-09" pos="0 0 0" fullinertia="8.888889e-13 8.888889e-13 8.888889e-13 0 0 0" /><joint name="slide_joint106" type="slide" axis="0 0 1" springdamper="0.002 0.9" frictionloss="1e-2" group="1" /><geom name="ball106" type="sphere" size="0.0005" class="collision" /><site name="tendon_site106" type="sphere" size="1e-5" group="1" /></body><body name="taxel107" pos="0.000000e+00 -1.242857e-02 1.000000e-03" euler="0 0 0"><inertial mass="4.444444e-09" pos="0 0 0" fullinertia="8.888889e-13 8.888889e-13 8.888889e-13 0 0 0" /><joint name="slide_joint107" type="slide" axis="0 0 1" springdamper="0.002 0.9" frictionloss="1e-2" group="1" /><geom name="ball107" type="sphere" size="0.0005" class="collision" /><site name="tendon_site107" type="sphere" size="1e-5" group="1" /></body><body name="taxel108" pos="0.000000e+00 -1.035714e-02 1.000000e-03" euler="0 0 0"><inertial mass="4.444444e-09" pos="0 0 0" fullinertia="8.888889e-13 8.888889e-13 8.888889e-13 0 0 0" /><joint name="slide_joint108" type="slide" axis="0 0 1" springdamper="0.002 0.9" frictionloss="1e-2" group="1" /><geom name="ball108" type="sphere" size="0.0005" class="collision" /><site name="tendon_site108" type="sphere" size="1e-5" group="1" /></body><body name="taxel109" pos="0.000000e+00 -8.285714e-03 1.000000e-03" euler="0 0 0"><inertial mass="4.444444e-09" pos="0 0 0" fullinertia="8.888889e-13 8.888889e-13 8.888889e-13 0 0 0" /><joint name="slide_joint109" type="slide" axis="0 0 1" springdamper="0.002 0.9" frictionloss="1e-2" group="1" /><geom name="ball109" type="sphere" size="0.0005" class="collision" /><site name="tendon_site109" type="sphere" size="1e-5" group="1" /></body><body name="taxel110" pos="0.000000e+00 -6.214286e-03 1.000000e-03" euler="0 0 0"><inertial mass="4.444444e-09" pos="0 0 0" fullinertia="8.888889e-13 8.888889e-13 8.888889e-13 0 0 0" /><joint name="slide_joint110" type="slide" axis="0 0 1" springdamper="0.002 0.9" frictionloss="1e-2" group="1" /><geom name="ball110" type="sphere" size="0.0005" class="collision" /><site name="tendon_site110" type="sphere" size="1e-5" group="1" /></body><body name="taxel111" pos="0.000000e+00 -4.142857e-03 1.000000e-03" euler="0 0 0"><inertial mass="4.444444e-09" pos="0 0 0" fullinertia="8.888889e-13 8.888889e-13 8.888889e-13 0 0 0" /><joint name="slide_joint111" type="slide" axis="0 0 1" springdamper="0.002 0.9" frictionloss="1e-2" group="1" /><geom name="ball111" type="sphere" size="0.0005" class="collision" /><site name="tendon_site111" type="sphere" size="1e-5" group="1" /></body><body name="taxel112" pos="0.000000e+00 -2.071429e-03 1.000000e-03" euler="0 0 0"><inertial mass="4.444444e-09" pos="0 0 0" fullinertia="8.888889e-13 8.888889e-13 8.888889e-13 0 0 0" /><joint name="slide_joint112" type="slide" axis="0 0 1" springdamper="0.002 0.9" frictionloss="1e-2" group="1" /><geom name="ball112" type="sphere" size="0.0005" class="collision" /><site name="tendon_site112" type="sphere" size="1e-5" group="1" /></body><body name="taxel113" pos="0.000000e+00 0.000000e+00 1.000000e-03" euler="0 0 0"><inertial mass="4.444444e-09" pos="0 0 0" fullinertia="8.888889e-13 8.888889e-13 8.888889e-13 0 0 0" /><joint name="slide_joint113" type="slide" axis="0 0 1" springdamper="0.002 0.9" frictionloss="1e-2" group="1" /><geom name="ball113" type="sphere" size="0.0005" class="collision" /><site name="tendon_site113" type="sphere" size="1e-5" group="1" /></body><body name="taxel114" pos="0.000000e+00 2.071429e-03 1.000000e-03" euler="0 0 0"><inertial mass="4.444444e-09" pos="0 0 0" fullinertia="8.888889e-13 8.888889e-13 8.888889e-13 0 0 0" /><joint name="slide_joint114" type="slide" axis="0 0 1" springdamper="0.002 0.9" frictionloss="1e-2" group="1" /><geom name="ball114" type="sphere" size="0.0005" class="collision" /><site name="tendon_site114" type="sphere" size="1e-5" group="1" /></body><body name="taxel115" pos="0.000000e+00 4.142857e-03 1.000000e-03" euler="0 0 0"><inertial mass="4.444444e-09" pos="0 0 0" fullinertia="8.888889e-13 8.888889e-13 8.888889e-13 0 0 0" /><joint name="slide_joint115" type="slide" axis="0 0 1" springdamper="0.002 0.9" frictionloss="1e-2" group="1" /><geom name="ball115" type="sphere" size="0.0005" class="collision" /><site name="tendon_site115" type="sphere" size="1e-5" group="1" /></body><body name="taxel116" pos="0.000000e+00 6.214286e-03 1.000000e-03" euler="0 0 0"><inertial mass="4.444444e-09" pos="0 0 0" fullinertia="8.888889e-13 8.888889e-13 8.888889e-13 0 0 0" /><joint name="slide_joint116" type="slide" axis="0 0 1" springdamper="0.002 0.9" frictionloss="1e-2" group="1" /><geom name="ball116" type="sphere" size="0.0005" class="collision" /><site name="tendon_site116" type="sphere" size="1e-5" group="1" /></body><body name="taxel117" pos="0.000000e+00 8.285714e-03 1.000000e-03" euler="0 0 0"><inertial mass="4.444444e-09" pos="0 0 0" fullinertia="8.888889e-13 8.888889e-13 8.888889e-13 0 0 0" /><joint name="slide_joint117" type="slide" axis="0 0 1" springdamper="0.002 0.9" frictionloss="1e-2" group="1" /><geom name="ball117" type="sphere" size="0.0005" class="collision" /><site name="tendon_site117" type="sphere" size="1e-5" group="1" /></body><body name="taxel118" pos="0.000000e+00 1.035714e-02 1.000000e-03" euler="0 0 0"><inertial mass="4.444444e-09" pos="0 0 0" fullinertia="8.888889e-13 8.888889e-13 8.888889e-13 0 0 0" /><joint name="slide_joint118" type="slide" axis="0 0 1" springdamper="0.002 0.9" frictionloss="1e-2" group="1" /><geom name="ball118" type="sphere" size="0.0005" class="collision" /><site name="tendon_site118" type="sphere" size="1e-5" group="1" /></body><body name="taxel119" pos="0.000000e+00 1.242857e-02 1.000000e-03" euler="0 0 0"><inertial mass="4.444444e-09" pos="0 0 0" fullinertia="8.888889e-13 8.888889e-13 8.888889e-13 0 0 0" /><joint name="slide_joint119" type="slide" axis="0 0 1" springdamper="0.002 0.9" frictionloss="1e-2" group="1" /><geom name="ball119" type="sphere" size="0.0005" class="collision" /><site name="tendon_site119" type="sphere" size="1e-5" group="1" /></body><body name="taxel120" pos="0.000000e+00 1.450000e-02 1.000000e-03" euler="0 0 0"><inertial mass="4.444444e-09" pos="0 0 0" fullinertia="8.888889e-13 8.888889e-13 8.888889e-13 0 0 0" /><joint name="slide_joint120" type="slide" axis="0 0 1" springdamper="0.002 0.9" frictionloss="1e-2" group="1" /><geom name="ball120" type="sphere" size="0.0005" class="collision" /><site name="tendon_site120" type="sphere" size="1e-5" group="1" /></body><body name="taxel121" pos="2.071429e-03 -1.450000e-02 1.000000e-03" euler="0 0 0"><inertial mass="4.444444e-09" pos="0 0 0" fullinertia="8.888889e-13 8.888889e-13 8.888889e-13 0 0 0" /><joint name="slide_joint121" type="slide" axis="0 0 1" springdamper="0.002 0.9" frictionloss="1e-2" group="1" /><geom name="ball121" type="sphere" size="0.0005" class="collision" /><site name="tendon_site121" type="sphere" size="1e-5" group="1" /></body><body name="taxel122" pos="2.071429e-03 -1.242857e-02 1.000000e-03" euler="0 0 0"><inertial mass="4.444444e-09" pos="0 0 0" fullinertia="8.888889e-13 8.888889e-13 8.888889e-13 0 0 0" /><joint name="slide_joint122" type="slide" axis="0 0 1" springdamper="0.002 0.9" frictionloss="1e-2" group="1" /><geom name="ball122" type="sphere" size="0.0005" class="collision" /><site name="tendon_site122" type="sphere" size="1e-5" group="1" /></body><body name="taxel123" pos="2.071429e-03 -1.035714e-02 1.000000e-03" euler="0 0 0"><inertial mass="4.444444e-09" pos="0 0 0" fullinertia="8.888889e-13 8.888889e-13 8.888889e-13 0 0 0" /><joint name="slide_joint123" type="slide" axis="0 0 1" springdamper="0.002 0.9" frictionloss="1e-2" group="1" /><geom name="ball123" type="sphere" size="0.0005" class="collision" /><site name="tendon_site123" type="sphere" size="1e-5" group="1" /></body><body name="taxel124" pos="2.071429e-03 -8.285714e-03 1.000000e-03" euler="0 0 0"><inertial mass="4.444444e-09" pos="0 0 0" fullinertia="8.888889e-13 8.888889e-13 8.888889e-13 0 0 0" /><joint name="slide_joint124" type="slide" axis="0 0 1" springdamper="0.002 0.9" frictionloss="1e-2" group="1" /><geom name="ball124" type="sphere" size="0.0005" class="collision" /><site name="tendon_site124" type="sphere" size="1e-5" group="1" /></body><body name="taxel125" pos="2.071429e-03 -6.214286e-03 1.000000e-03" euler="0 0 0"><inertial mass="4.444444e-09" pos="0 0 0" fullinertia="8.888889e-13 8.888889e-13 8.888889e-13 0 0 0" /><joint name="slide_joint125" type="slide" axis="0 0 1" springdamper="0.002 0.9" frictionloss="1e-2" group="1" /><geom name="ball125" type="sphere" size="0.0005" class="collision" /><site name="tendon_site125" type="sphere" size="1e-5" group="1" /></body><body name="taxel126" pos="2.071429e-03 -4.142857e-03 1.000000e-03" euler="0 0 0"><inertial mass="4.444444e-09" pos="0 0 0" fullinertia="8.888889e-13 8.888889e-13 8.888889e-13 0 0 0" /><joint name="slide_joint126" type="slide" axis="0 0 1" springdamper="0.002 0.9" frictionloss="1e-2" group="1" /><geom name="ball126" type="sphere" size="0.0005" class="collision" /><site name="tendon_site126" type="sphere" size="1e-5" group="1" /></body><body name="taxel127" pos="2.071429e-03 -2.071429e-03 1.000000e-03" euler="0 0 0"><inertial mass="4.444444e-09" pos="0 0 0" fullinertia="8.888889e-13 8.888889e-13 8.888889e-13 0 0 0" /><joint name="slide_joint127" type="slide" axis="0 0 1" springdamper="0.002 0.9" frictionloss="1e-2" group="1" /><geom name="ball127" type="sphere" size="0.0005" class="collision" /><site name="tendon_site127" type="sphere" size="1e-5" group="1" /></body><body name="taxel128" pos="2.071429e-03 0.000000e+00 1.000000e-03" euler="0 0 0"><inertial mass="4.444444e-09" pos="0 0 0" fullinertia="8.888889e-13 8.888889e-13 8.888889e-13 0 0 0" /><joint name="slide_joint128" type="slide" axis="0 0 1" springdamper="0.002 0.9" frictionloss="1e-2" group="1" /><geom name="ball128" type="sphere" size="0.0005" class="collision" /><site name="tendon_site128" type="sphere" size="1e-5" group="1" /></body><body name="taxel129" pos="2.071429e-03 2.071429e-03 1.000000e-03" euler="0 0 0"><inertial mass="4.444444e-09" pos="0 0 0" fullinertia="8.888889e-13 8.888889e-13 8.888889e-13 0 0 0" /><joint name="slide_joint129" type="slide" axis="0 0 1" springdamper="0.002 0.9" frictionloss="1e-2" group="1" /><geom name="ball129" type="sphere" size="0.0005" class="collision" /><site name="tendon_site129" type="sphere" size="1e-5" group="1" /></body><body name="taxel130" pos="2.071429e-03 4.142857e-03 1.000000e-03" euler="0 0 0"><inertial mass="4.444444e-09" pos="0 0 0" fullinertia="8.888889e-13 8.888889e-13 8.888889e-13 0 0 0" /><joint name="slide_joint130" type="slide" axis="0 0 1" springdamper="0.002 0.9" frictionloss="1e-2" group="1" /><geom name="ball130" type="sphere" size="0.0005" class="collision" /><site name="tendon_site130" type="sphere" size="1e-5" group="1" /></body><body name="taxel131" pos="2.071429e-03 6.214286e-03 1.000000e-03" euler="0 0 0"><inertial mass="4.444444e-09" pos="0 0 0" fullinertia="8.888889e-13 8.888889e-13 8.888889e-13 0 0 0" /><joint name="slide_joint131" type="slide" axis="0 0 1" springdamper="0.002 0.9" frictionloss="1e-2" group="1" /><geom name="ball131" type="sphere" size="0.0005" class="collision" /><site name="tendon_site131" type="sphere" size="1e-5" group="1" /></body><body name="taxel132" pos="2.071429e-03 8.285714e-03 1.000000e-03" euler="0 0 0"><inertial mass="4.444444e-09" pos="0 0 0" fullinertia="8.888889e-13 8.888889e-13 8.888889e-13 0 0 0" /><joint name="slide_joint132" type="slide" axis="0 0 1" springdamper="0.002 0.9" frictionloss="1e-2" group="1" /><geom name="ball132" type="sphere" size="0.0005" class="collision" /><site name="tendon_site132" type="sphere" size="1e-5" group="1" /></body><body name="taxel133" pos="2.071429e-03 1.035714e-02 1.000000e-03" euler="0 0 0"><inertial mass="4.444444e-09" pos="0 0 0" fullinertia="8.888889e-13 8.888889e-13 8.888889e-13 0 0 0" /><joint name="slide_joint133" type="slide" axis="0 0 1" springdamper="0.002 0.9" frictionloss="1e-2" group="1" /><geom name="ball133" type="sphere" size="0.0005" class="collision" /><site name="tendon_site133" type="sphere" size="1e-5" group="1" /></body><body name="taxel134" pos="2.071429e-03 1.242857e-02 1.000000e-03" euler="0 0 0"><inertial mass="4.444444e-09" pos="0 0 0" fullinertia="8.888889e-13 8.888889e-13 8.888889e-13 0 0 0" /><joint name="slide_joint134" type="slide" axis="0 0 1" springdamper="0.002 0.9" frictionloss="1e-2" group="1" /><geom name="ball134" type="sphere" size="0.0005" class="collision" /><site name="tendon_site134" type="sphere" size="1e-5" group="1" /></body><body name="taxel135" pos="2.071429e-03 1.450000e-02 1.000000e-03" euler="0 0 0"><inertial mass="4.444444e-09" pos="0 0 0" fullinertia="8.888889e-13 8.888889e-13 8.888889e-13 0 0 0" /><joint name="slide_joint135" type="slide" axis="0 0 1" springdamper="0.002 0.9" frictionloss="1e-2" group="1" /><geom name="ball135" type="sphere" size="0.0005" class="collision" /><site name="tendon_site135" type="sphere" size="1e-5" group="1" /></body><body name="taxel136" pos="4.142857e-03 -1.450000e-02 1.000000e-03" euler="0 0 0"><inertial mass="4.444444e-09" pos="0 0 0" fullinertia="8.888889e-13 8.888889e-13 8.888889e-13 0 0 0" /><joint name="slide_joint136" type="slide" axis="0 0 1" springdamper="0.002 0.9" frictionloss="1e-2" group="1" /><geom name="ball136" type="sphere" size="0.0005" class="collision" /><site name="tendon_site136" type="sphere" size="1e-5" group="1" /></body><body name="taxel137" pos="4.142857e-03 -1.242857e-02 1.000000e-03" euler="0 0 0"><inertial mass="4.444444e-09" pos="0 0 0" fullinertia="8.888889e-13 8.888889e-13 8.888889e-13 0 0 0" /><joint name="slide_joint137" type="slide" axis="0 0 1" springdamper="0.002 0.9" frictionloss="1e-2" group="1" /><geom name="ball137" type="sphere" size="0.0005" class="collision" /><site name="tendon_site137" type="sphere" size="1e-5" group="1" /></body><body name="taxel138" pos="4.142857e-03 -1.035714e-02 1.000000e-03" euler="0 0 0"><inertial mass="4.444444e-09" pos="0 0 0" fullinertia="8.888889e-13 8.888889e-13 8.888889e-13 0 0 0" /><joint name="slide_joint138" type="slide" axis="0 0 1" springdamper="0.002 0.9" frictionloss="1e-2" group="1" /><geom name="ball138" type="sphere" size="0.0005" class="collision" /><site name="tendon_site138" type="sphere" size="1e-5" group="1" /></body><body name="taxel139" pos="4.142857e-03 -8.285714e-03 1.000000e-03" euler="0 0 0"><inertial mass="4.444444e-09" pos="0 0 0" fullinertia="8.888889e-13 8.888889e-13 8.888889e-13 0 0 0" /><joint name="slide_joint139" type="slide" axis="0 0 1" springdamper="0.002 0.9" frictionloss="1e-2" group="1" /><geom name="ball139" type="sphere" size="0.0005" class="collision" /><site name="tendon_site139" type="sphere" size="1e-5" group="1" /></body><body name="taxel140" pos="4.142857e-03 -6.214286e-03 1.000000e-03" euler="0 0 0"><inertial mass="4.444444e-09" pos="0 0 0" fullinertia="8.888889e-13 8.888889e-13 8.888889e-13 0 0 0" /><joint name="slide_joint140" type="slide" axis="0 0 1" springdamper="0.002 0.9" frictionloss="1e-2" group="1" /><geom name="ball140" type="sphere" size="0.0005" class="collision" /><site name="tendon_site140" type="sphere" size="1e-5" group="1" /></body><body name="taxel141" pos="4.142857e-03 -4.142857e-03 1.000000e-03" euler="0 0 0"><inertial mass="4.444444e-09" pos="0 0 0" fullinertia="8.888889e-13 8.888889e-13 8.888889e-13 0 0 0" /><joint name="slide_joint141" type="slide" axis="0 0 1" springdamper="0.002 0.9" frictionloss="1e-2" group="1" /><geom name="ball141" type="sphere" size="0.0005" class="collision" /><site name="tendon_site141" type="sphere" size="1e-5" group="1" /></body><body name="taxel142" pos="4.142857e-03 -2.071429e-03 1.000000e-03" euler="0 0 0"><inertial mass="4.444444e-09" pos="0 0 0" fullinertia="8.888889e-13 8.888889e-13 8.888889e-13 0 0 0" /><joint name="slide_joint142" type="slide" axis="0 0 1" springdamper="0.002 0.9" frictionloss="1e-2" group="1" /><geom name="ball142" type="sphere" size="0.0005" class="collision" /><site name="tendon_site142" type="sphere" size="1e-5" group="1" /></body><body name="taxel143" pos="4.142857e-03 0.000000e+00 1.000000e-03" euler="0 0 0"><inertial mass="4.444444e-09" pos="0 0 0" fullinertia="8.888889e-13 8.888889e-13 8.888889e-13 0 0 0" /><joint name="slide_joint143" type="slide" axis="0 0 1" springdamper="0.002 0.9" frictionloss="1e-2" group="1" /><geom name="ball143" type="sphere" size="0.0005" class="collision" /><site name="tendon_site143" type="sphere" size="1e-5" group="1" /></body><body name="taxel144" pos="4.142857e-03 2.071429e-03 1.000000e-03" euler="0 0 0"><inertial mass="4.444444e-09" pos="0 0 0" fullinertia="8.888889e-13 8.888889e-13 8.888889e-13 0 0 0" /><joint name="slide_joint144" type="slide" axis="0 0 1" springdamper="0.002 0.9" frictionloss="1e-2" group="1" /><geom name="ball144" type="sphere" size="0.0005" class="collision" /><site name="tendon_site144" type="sphere" size="1e-5" group="1" /></body><body name="taxel145" pos="4.142857e-03 4.142857e-03 1.000000e-03" euler="0 0 0"><inertial mass="4.444444e-09" pos="0 0 0" fullinertia="8.888889e-13 8.888889e-13 8.888889e-13 0 0 0" /><joint name="slide_joint145" type="slide" axis="0 0 1" springdamper="0.002 0.9" frictionloss="1e-2" group="1" /><geom name="ball145" type="sphere" size="0.0005" class="collision" /><site name="tendon_site145" type="sphere" size="1e-5" group="1" /></body><body name="taxel146" pos="4.142857e-03 6.214286e-03 1.000000e-03" euler="0 0 0"><inertial mass="4.444444e-09" pos="0 0 0" fullinertia="8.888889e-13 8.888889e-13 8.888889e-13 0 0 0" /><joint name="slide_joint146" type="slide" axis="0 0 1" springdamper="0.002 0.9" frictionloss="1e-2" group="1" /><geom name="ball146" type="sphere" size="0.0005" class="collision" /><site name="tendon_site146" type="sphere" size="1e-5" group="1" /></body><body name="taxel147" pos="4.142857e-03 8.285714e-03 1.000000e-03" euler="0 0 0"><inertial mass="4.444444e-09" pos="0 0 0" fullinertia="8.888889e-13 8.888889e-13 8.888889e-13 0 0 0" /><joint name="slide_joint147" type="slide" axis="0 0 1" springdamper="0.002 0.9" frictionloss="1e-2" group="1" /><geom name="ball147" type="sphere" size="0.0005" class="collision" /><site name="tendon_site147" type="sphere" size="1e-5" group="1" /></body><body name="taxel148" pos="4.142857e-03 1.035714e-02 1.000000e-03" euler="0 0 0"><inertial mass="4.444444e-09" pos="0 0 0" fullinertia="8.888889e-13 8.888889e-13 8.888889e-13 0 0 0" /><joint name="slide_joint148" type="slide" axis="0 0 1" springdamper="0.002 0.9" frictionloss="1e-2" group="1" /><geom name="ball148" type="sphere" size="0.0005" class="collision" /><site name="tendon_site148" type="sphere" size="1e-5" group="1" /></body><body name="taxel149" pos="4.142857e-03 1.242857e-02 1.000000e-03" euler="0 0 0"><inertial mass="4.444444e-09" pos="0 0 0" fullinertia="8.888889e-13 8.888889e-13 8.888889e-13 0 0 0" /><joint name="slide_joint149" type="slide" axis="0 0 1" springdamper="0.002 0.9" frictionloss="1e-2" group="1" /><geom name="ball149" type="sphere" size="0.0005" class="collision" /><site name="tendon_site149" type="sphere" size="1e-5" group="1" /></body><body name="taxel150" pos="4.142857e-03 1.450000e-02 1.000000e-03" euler="0 0 0"><inertial mass="4.444444e-09" pos="0 0 0" fullinertia="8.888889e-13 8.888889e-13 8.888889e-13 0 0 0" /><joint name="slide_joint150" type="slide" axis="0 0 1" springdamper="0.002 0.9" frictionloss="1e-2" group="1" /><geom name="ball150" type="sphere" size="0.0005" class="collision" /><site name="tendon_site150" type="sphere" size="1e-5" group="1" /></body><body name="taxel151" pos="6.214286e-03 -1.450000e-02 1.000000e-03" euler="0 0 0"><inertial mass="4.444444e-09" pos="0 0 0" fullinertia="8.888889e-13 8.888889e-13 8.888889e-13 0 0 0" /><joint name="slide_joint151" type="slide" axis="0 0 1" springdamper="0.002 0.9" frictionloss="1e-2" group="1" /><geom name="ball151" type="sphere" size="0.0005" class="collision" /><site name="tendon_site151" type="sphere" size="1e-5" group="1" /></body><body name="taxel152" pos="6.214286e-03 -1.242857e-02 1.000000e-03" euler="0 0 0"><inertial mass="4.444444e-09" pos="0 0 0" fullinertia="8.888889e-13 8.888889e-13 8.888889e-13 0 0 0" /><joint name="slide_joint152" type="slide" axis="0 0 1" springdamper="0.002 0.9" frictionloss="1e-2" group="1" /><geom name="ball152" type="sphere" size="0.0005" class="collision" /><site name="tendon_site152" type="sphere" size="1e-5" group="1" /></body><body name="taxel153" pos="6.214286e-03 -1.035714e-02 1.000000e-03" euler="0 0 0"><inertial mass="4.444444e-09" pos="0 0 0" fullinertia="8.888889e-13 8.888889e-13 8.888889e-13 0 0 0" /><joint name="slide_joint153" type="slide" axis="0 0 1" springdamper="0.002 0.9" frictionloss="1e-2" group="1" /><geom name="ball153" type="sphere" size="0.0005" class="collision" /><site name="tendon_site153" type="sphere" size="1e-5" group="1" /></body><body name="taxel154" pos="6.214286e-03 -8.285714e-03 1.000000e-03" euler="0 0 0"><inertial mass="4.444444e-09" pos="0 0 0" fullinertia="8.888889e-13 8.888889e-13 8.888889e-13 0 0 0" /><joint name="slide_joint154" type="slide" axis="0 0 1" springdamper="0.002 0.9" frictionloss="1e-2" group="1" /><geom name="ball154" type="sphere" size="0.0005" class="collision" /><site name="tendon_site154" type="sphere" size="1e-5" group="1" /></body><body name="taxel155" pos="6.214286e-03 -6.214286e-03 1.000000e-03" euler="0 0 0"><inertial mass="4.444444e-09" pos="0 0 0" fullinertia="8.888889e-13 8.888889e-13 8.888889e-13 0 0 0" /><joint name="slide_joint155" type="slide" axis="0 0 1" springdamper="0.002 0.9" frictionloss="1e-2" group="1" /><geom name="ball155" type="sphere" size="0.0005" class="collision" /><site name="tendon_site155" type="sphere" size="1e-5" group="1" /></body><body name="taxel156" pos="6.214286e-03 -4.142857e-03 1.000000e-03" euler="0 0 0"><inertial mass="4.444444e-09" pos="0 0 0" fullinertia="8.888889e-13 8.888889e-13 8.888889e-13 0 0 0" /><joint name="slide_joint156" type="slide" axis="0 0 1" springdamper="0.002 0.9" frictionloss="1e-2" group="1" /><geom name="ball156" type="sphere" size="0.0005" class="collision" /><site name="tendon_site156" type="sphere" size="1e-5" group="1" /></body><body name="taxel157" pos="6.214286e-03 -2.071429e-03 1.000000e-03" euler="0 0 0"><inertial mass="4.444444e-09" pos="0 0 0" fullinertia="8.888889e-13 8.888889e-13 8.888889e-13 0 0 0" /><joint name="slide_joint157" type="slide" axis="0 0 1" springdamper="0.002 0.9" frictionloss="1e-2" group="1" /><geom name="ball157" type="sphere" size="0.0005" class="collision" /><site name="tendon_site157" type="sphere" size="1e-5" group="1" /></body><body name="taxel158" pos="6.214286e-03 0.000000e+00 1.000000e-03" euler="0 0 0"><inertial mass="4.444444e-09" pos="0 0 0" fullinertia="8.888889e-13 8.888889e-13 8.888889e-13 0 0 0" /><joint name="slide_joint158" type="slide" axis="0 0 1" springdamper="0.002 0.9" frictionloss="1e-2" group="1" /><geom name="ball158" type="sphere" size="0.0005" class="collision" /><site name="tendon_site158" type="sphere" size="1e-5" group="1" /></body><body name="taxel159" pos="6.214286e-03 2.071429e-03 1.000000e-03" euler="0 0 0"><inertial mass="4.444444e-09" pos="0 0 0" fullinertia="8.888889e-13 8.888889e-13 8.888889e-13 0 0 0" /><joint name="slide_joint159" type="slide" axis="0 0 1" springdamper="0.002 0.9" frictionloss="1e-2" group="1" /><geom name="ball159" type="sphere" size="0.0005" class="collision" /><site name="tendon_site159" type="sphere" size="1e-5" group="1" /></body><body name="taxel160" pos="6.214286e-03 4.142857e-03 1.000000e-03" euler="0 0 0"><inertial mass="4.444444e-09" pos="0 0 0" fullinertia="8.888889e-13 8.888889e-13 8.888889e-13 0 0 0" /><joint name="slide_joint160" type="slide" axis="0 0 1" springdamper="0.002 0.9" frictionloss="1e-2" group="1" /><geom name="ball160" type="sphere" size="0.0005" class="collision" /><site name="tendon_site160" type="sphere" size="1e-5" group="1" /></body><body name="taxel161" pos="6.214286e-03 6.214286e-03 1.000000e-03" euler="0 0 0"><inertial mass="4.444444e-09" pos="0 0 0" fullinertia="8.888889e-13 8.888889e-13 8.888889e-13 0 0 0" /><joint name="slide_joint161" type="slide" axis="0 0 1" springdamper="0.002 0.9" frictionloss="1e-2" group="1" /><geom name="ball161" type="sphere" size="0.0005" class="collision" /><site name="tendon_site161" type="sphere" size="1e-5" group="1" /></body><body name="taxel162" pos="6.214286e-03 8.285714e-03 1.000000e-03" euler="0 0 0"><inertial mass="4.444444e-09" pos="0 0 0" fullinertia="8.888889e-13 8.888889e-13 8.888889e-13 0 0 0" /><joint name="slide_joint162" type="slide" axis="0 0 1" springdamper="0.002 0.9" frictionloss="1e-2" group="1" /><geom name="ball162" type="sphere" size="0.0005" class="collision" /><site name="tendon_site162" type="sphere" size="1e-5" group="1" /></body><body name="taxel163" pos="6.214286e-03 1.035714e-02 1.000000e-03" euler="0 0 0"><inertial mass="4.444444e-09" pos="0 0 0" fullinertia="8.888889e-13 8.888889e-13 8.888889e-13 0 0 0" /><joint name="slide_joint163" type="slide" axis="0 0 1" springdamper="0.002 0.9" frictionloss="1e-2" group="1" /><geom name="ball163" type="sphere" size="0.0005" class="collision" /><site name="tendon_site163" type="sphere" size="1e-5" group="1" /></body><body name="taxel164" pos="6.214286e-03 1.242857e-02 1.000000e-03" euler="0 0 0"><inertial mass="4.444444e-09" pos="0 0 0" fullinertia="8.888889e-13 8.888889e-13 8.888889e-13 0 0 0" /><joint name="slide_joint164" type="slide" axis="0 0 1" springdamper="0.002 0.9" frictionloss="1e-2" group="1" /><geom name="ball164" type="sphere" size="0.0005" class="collision" /><site name="tendon_site164" type="sphere" size="1e-5" group="1" /></body><body name="taxel165" pos="6.214286e-03 1.450000e-02 1.000000e-03" euler="0 0 0"><inertial mass="4.444444e-09" pos="0 0 0" fullinertia="8.888889e-13 8.888889e-13 8.888889e-13 0 0 0" /><joint name="slide_joint165" type="slide" axis="0 0 1" springdamper="0.002 0.9" frictionloss="1e-2" group="1" /><geom name="ball165" type="sphere" size="0.0005" class="collision" /><site name="tendon_site165" type="sphere" size="1e-5" group="1" /></body><body name="taxel166" pos="8.285714e-03 -1.450000e-02 1.000000e-03" euler="0 0 0"><inertial mass="4.444444e-09" pos="0 0 0" fullinertia="8.888889e-13 8.888889e-13 8.888889e-13 0 0 0" /><joint name="slide_joint166" type="slide" axis="0 0 1" springdamper="0.002 0.9" frictionloss="1e-2" group="1" /><geom name="ball166" type="sphere" size="0.0005" class="collision" /><site name="tendon_site166" type="sphere" size="1e-5" group="1" /></body><body name="taxel167" pos="8.285714e-03 -1.242857e-02 1.000000e-03" euler="0 0 0"><inertial mass="4.444444e-09" pos="0 0 0" fullinertia="8.888889e-13 8.888889e-13 8.888889e-13 0 0 0" /><joint name="slide_joint167" type="slide" axis="0 0 1" springdamper="0.002 0.9" frictionloss="1e-2" group="1" /><geom name="ball167" type="sphere" size="0.0005" class="collision" /><site name="tendon_site167" type="sphere" size="1e-5" group="1" /></body><body name="taxel168" pos="8.285714e-03 -1.035714e-02 1.000000e-03" euler="0 0 0"><inertial mass="4.444444e-09" pos="0 0 0" fullinertia="8.888889e-13 8.888889e-13 8.888889e-13 0 0 0" /><joint name="slide_joint168" type="slide" axis="0 0 1" springdamper="0.002 0.9" frictionloss="1e-2" group="1" /><geom name="ball168" type="sphere" size="0.0005" class="collision" /><site name="tendon_site168" type="sphere" size="1e-5" group="1" /></body><body name="taxel169" pos="8.285714e-03 -8.285714e-03 1.000000e-03" euler="0 0 0"><inertial mass="4.444444e-09" pos="0 0 0" fullinertia="8.888889e-13 8.888889e-13 8.888889e-13 0 0 0" /><joint name="slide_joint169" type="slide" axis="0 0 1" springdamper="0.002 0.9" frictionloss="1e-2" group="1" /><geom name="ball169" type="sphere" size="0.0005" class="collision" /><site name="tendon_site169" type="sphere" size="1e-5" group="1" /></body><body name="taxel170" pos="8.285714e-03 -6.214286e-03 1.000000e-03" euler="0 0 0"><inertial mass="4.444444e-09" pos="0 0 0" fullinertia="8.888889e-13 8.888889e-13 8.888889e-13 0 0 0" /><joint name="slide_joint170" type="slide" axis="0 0 1" springdamper="0.002 0.9" frictionloss="1e-2" group="1" /><geom name="ball170" type="sphere" size="0.0005" class="collision" /><site name="tendon_site170" type="sphere" size="1e-5" group="1" /></body><body name="taxel171" pos="8.285714e-03 -4.142857e-03 1.000000e-03" euler="0 0 0"><inertial mass="4.444444e-09" pos="0 0 0" fullinertia="8.888889e-13 8.888889e-13 8.888889e-13 0 0 0" /><joint name="slide_joint171" type="slide" axis="0 0 1" springdamper="0.002 0.9" frictionloss="1e-2" group="1" /><geom name="ball171" type="sphere" size="0.0005" class="collision" /><site name="tendon_site171" type="sphere" size="1e-5" group="1" /></body><body name="taxel172" pos="8.285714e-03 -2.071429e-03 1.000000e-03" euler="0 0 0"><inertial mass="4.444444e-09" pos="0 0 0" fullinertia="8.888889e-13 8.888889e-13 8.888889e-13 0 0 0" /><joint name="slide_joint172" type="slide" axis="0 0 1" springdamper="0.002 0.9" frictionloss="1e-2" group="1" /><geom name="ball172" type="sphere" size="0.0005" class="collision" /><site name="tendon_site172" type="sphere" size="1e-5" group="1" /></body><body name="taxel173" pos="8.285714e-03 0.000000e+00 1.000000e-03" euler="0 0 0"><inertial mass="4.444444e-09" pos="0 0 0" fullinertia="8.888889e-13 8.888889e-13 8.888889e-13 0 0 0" /><joint name="slide_joint173" type="slide" axis="0 0 1" springdamper="0.002 0.9" frictionloss="1e-2" group="1" /><geom name="ball173" type="sphere" size="0.0005" class="collision" /><site name="tendon_site173" type="sphere" size="1e-5" group="1" /></body><body name="taxel174" pos="8.285714e-03 2.071429e-03 1.000000e-03" euler="0 0 0"><inertial mass="4.444444e-09" pos="0 0 0" fullinertia="8.888889e-13 8.888889e-13 8.888889e-13 0 0 0" /><joint name="slide_joint174" type="slide" axis="0 0 1" springdamper="0.002 0.9" frictionloss="1e-2" group="1" /><geom name="ball174" type="sphere" size="0.0005" class="collision" /><site name="tendon_site174" type="sphere" size="1e-5" group="1" /></body><body name="taxel175" pos="8.285714e-03 4.142857e-03 1.000000e-03" euler="0 0 0"><inertial mass="4.444444e-09" pos="0 0 0" fullinertia="8.888889e-13 8.888889e-13 8.888889e-13 0 0 0" /><joint name="slide_joint175" type="slide" axis="0 0 1" springdamper="0.002 0.9" frictionloss="1e-2" group="1" /><geom name="ball175" type="sphere" size="0.0005" class="collision" /><site name="tendon_site175" type="sphere" size="1e-5" group="1" /></body><body name="taxel176" pos="8.285714e-03 6.214286e-03 1.000000e-03" euler="0 0 0"><inertial mass="4.444444e-09" pos="0 0 0" fullinertia="8.888889e-13 8.888889e-13 8.888889e-13 0 0 0" /><joint name="slide_joint176" type="slide" axis="0 0 1" springdamper="0.002 0.9" frictionloss="1e-2" group="1" /><geom name="ball176" type="sphere" size="0.0005" class="collision" /><site name="tendon_site176" type="sphere" size="1e-5" group="1" /></body><body name="taxel177" pos="8.285714e-03 8.285714e-03 1.000000e-03" euler="0 0 0"><inertial mass="4.444444e-09" pos="0 0 0" fullinertia="8.888889e-13 8.888889e-13 8.888889e-13 0 0 0" /><joint name="slide_joint177" type="slide" axis="0 0 1" springdamper="0.002 0.9" frictionloss="1e-2" group="1" /><geom name="ball177" type="sphere" size="0.0005" class="collision" /><site name="tendon_site177" type="sphere" size="1e-5" group="1" /></body><body name="taxel178" pos="8.285714e-03 1.035714e-02 1.000000e-03" euler="0 0 0"><inertial mass="4.444444e-09" pos="0 0 0" fullinertia="8.888889e-13 8.888889e-13 8.888889e-13 0 0 0" /><joint name="slide_joint178" type="slide" axis="0 0 1" springdamper="0.002 0.9" frictionloss="1e-2" group="1" /><geom name="ball178" type="sphere" size="0.0005" class="collision" /><site name="tendon_site178" type="sphere" size="1e-5" group="1" /></body><body name="taxel179" pos="8.285714e-03 1.242857e-02 1.000000e-03" euler="0 0 0"><inertial mass="4.444444e-09" pos="0 0 0" fullinertia="8.888889e-13 8.888889e-13 8.888889e-13 0 0 0" /><joint name="slide_joint179" type="slide" axis="0 0 1" springdamper="0.002 0.9" frictionloss="1e-2" group="1" /><geom name="ball179" type="sphere" size="0.0005" class="collision" /><site name="tendon_site179" type="sphere" size="1e-5" group="1" /></body><body name="taxel180" pos="8.285714e-03 1.450000e-02 1.000000e-03" euler="0 0 0"><inertial mass="4.444444e-09" pos="0 0 0" fullinertia="8.888889e-13 8.888889e-13 8.888889e-13 0 0 0" /><joint name="slide_joint180" type="slide" axis="0 0 1" springdamper="0.002 0.9" frictionloss="1e-2" group="1" /><geom name="ball180" type="sphere" size="0.0005" class="collision" /><site name="tendon_site180" type="sphere" size="1e-5" group="1" /></body><body name="taxel181" pos="1.035714e-02 -1.450000e-02 1.000000e-03" euler="0 0 0"><inertial mass="4.444444e-09" pos="0 0 0" fullinertia="8.888889e-13 8.888889e-13 8.888889e-13 0 0 0" /><joint name="slide_joint181" type="slide" axis="0 0 1" springdamper="0.002 0.9" frictionloss="1e-2" group="1" /><geom name="ball181" type="sphere" size="0.0005" class="collision" /><site name="tendon_site181" type="sphere" size="1e-5" group="1" /></body><body name="taxel182" pos="1.035714e-02 -1.242857e-02 1.000000e-03" euler="0 0 0"><inertial mass="4.444444e-09" pos="0 0 0" fullinertia="8.888889e-13 8.888889e-13 8.888889e-13 0 0 0" /><joint name="slide_joint182" type="slide" axis="0 0 1" springdamper="0.002 0.9" frictionloss="1e-2" group="1" /><geom name="ball182" type="sphere" size="0.0005" class="collision" /><site name="tendon_site182" type="sphere" size="1e-5" group="1" /></body><body name="taxel183" pos="1.035714e-02 -1.035714e-02 1.000000e-03" euler="0 0 0"><inertial mass="4.444444e-09" pos="0 0 0" fullinertia="8.888889e-13 8.888889e-13 8.888889e-13 0 0 0" /><joint name="slide_joint183" type="slide" axis="0 0 1" springdamper="0.002 0.9" frictionloss="1e-2" group="1" /><geom name="ball183" type="sphere" size="0.0005" class="collision" /><site name="tendon_site183" type="sphere" size="1e-5" group="1" /></body><body name="taxel184" pos="1.035714e-02 -8.285714e-03 1.000000e-03" euler="0 0 0"><inertial mass="4.444444e-09" pos="0 0 0" fullinertia="8.888889e-13 8.888889e-13 8.888889e-13 0 0 0" /><joint name="slide_joint184" type="slide" axis="0 0 1" springdamper="0.002 0.9" frictionloss="1e-2" group="1" /><geom name="ball184" type="sphere" size="0.0005" class="collision" /><site name="tendon_site184" type="sphere" size="1e-5" group="1" /></body><body name="taxel185" pos="1.035714e-02 -6.214286e-03 1.000000e-03" euler="0 0 0"><inertial mass="4.444444e-09" pos="0 0 0" fullinertia="8.888889e-13 8.888889e-13 8.888889e-13 0 0 0" /><joint name="slide_joint185" type="slide" axis="0 0 1" springdamper="0.002 0.9" frictionloss="1e-2" group="1" /><geom name="ball185" type="sphere" size="0.0005" class="collision" /><site name="tendon_site185" type="sphere" size="1e-5" group="1" /></body><body name="taxel186" pos="1.035714e-02 -4.142857e-03 1.000000e-03" euler="0 0 0"><inertial mass="4.444444e-09" pos="0 0 0" fullinertia="8.888889e-13 8.888889e-13 8.888889e-13 0 0 0" /><joint name="slide_joint186" type="slide" axis="0 0 1" springdamper="0.002 0.9" frictionloss="1e-2" group="1" /><geom name="ball186" type="sphere" size="0.0005" class="collision" /><site name="tendon_site186" type="sphere" size="1e-5" group="1" /></body><body name="taxel187" pos="1.035714e-02 -2.071429e-03 1.000000e-03" euler="0 0 0"><inertial mass="4.444444e-09" pos="0 0 0" fullinertia="8.888889e-13 8.888889e-13 8.888889e-13 0 0 0" /><joint name="slide_joint187" type="slide" axis="0 0 1" springdamper="0.002 0.9" frictionloss="1e-2" group="1" /><geom name="ball187" type="sphere" size="0.0005" class="collision" /><site name="tendon_site187" type="sphere" size="1e-5" group="1" /></body><body name="taxel188" pos="1.035714e-02 0.000000e+00 1.000000e-03" euler="0 0 0"><inertial mass="4.444444e-09" pos="0 0 0" fullinertia="8.888889e-13 8.888889e-13 8.888889e-13 0 0 0" /><joint name="slide_joint188" type="slide" axis="0 0 1" springdamper="0.002 0.9" frictionloss="1e-2" group="1" /><geom name="ball188" type="sphere" size="0.0005" class="collision" /><site name="tendon_site188" type="sphere" size="1e-5" group="1" /></body><body name="taxel189" pos="1.035714e-02 2.071429e-03 1.000000e-03" euler="0 0 0"><inertial mass="4.444444e-09" pos="0 0 0" fullinertia="8.888889e-13 8.888889e-13 8.888889e-13 0 0 0" /><joint name="slide_joint189" type="slide" axis="0 0 1" springdamper="0.002 0.9" frictionloss="1e-2" group="1" /><geom name="ball189" type="sphere" size="0.0005" class="collision" /><site name="tendon_site189" type="sphere" size="1e-5" group="1" /></body><body name="taxel190" pos="1.035714e-02 4.142857e-03 1.000000e-03" euler="0 0 0"><inertial mass="4.444444e-09" pos="0 0 0" fullinertia="8.888889e-13 8.888889e-13 8.888889e-13 0 0 0" /><joint name="slide_joint190" type="slide" axis="0 0 1" springdamper="0.002 0.9" frictionloss="1e-2" group="1" /><geom name="ball190" type="sphere" size="0.0005" class="collision" /><site name="tendon_site190" type="sphere" size="1e-5" group="1" /></body><body name="taxel191" pos="1.035714e-02 6.214286e-03 1.000000e-03" euler="0 0 0"><inertial mass="4.444444e-09" pos="0 0 0" fullinertia="8.888889e-13 8.888889e-13 8.888889e-13 0 0 0" /><joint name="slide_joint191" type="slide" axis="0 0 1" springdamper="0.002 0.9" frictionloss="1e-2" group="1" /><geom name="ball191" type="sphere" size="0.0005" class="collision" /><site name="tendon_site191" type="sphere" size="1e-5" group="1" /></body><body name="taxel192" pos="1.035714e-02 8.285714e-03 1.000000e-03" euler="0 0 0"><inertial mass="4.444444e-09" pos="0 0 0" fullinertia="8.888889e-13 8.888889e-13 8.888889e-13 0 0 0" /><joint name="slide_joint192" type="slide" axis="0 0 1" springdamper="0.002 0.9" frictionloss="1e-2" group="1" /><geom name="ball192" type="sphere" size="0.0005" class="collision" /><site name="tendon_site192" type="sphere" size="1e-5" group="1" /></body><body name="taxel193" pos="1.035714e-02 1.035714e-02 1.000000e-03" euler="0 0 0"><inertial mass="4.444444e-09" pos="0 0 0" fullinertia="8.888889e-13 8.888889e-13 8.888889e-13 0 0 0" /><joint name="slide_joint193" type="slide" axis="0 0 1" springdamper="0.002 0.9" frictionloss="1e-2" group="1" /><geom name="ball193" type="sphere" size="0.0005" class="collision" /><site name="tendon_site193" type="sphere" size="1e-5" group="1" /></body><body name="taxel194" pos="1.035714e-02 1.242857e-02 1.000000e-03" euler="0 0 0"><inertial mass="4.444444e-09" pos="0 0 0" fullinertia="8.888889e-13 8.888889e-13 8.888889e-13 0 0 0" /><joint name="slide_joint194" type="slide" axis="0 0 1" springdamper="0.002 0.9" frictionloss="1e-2" group="1" /><geom name="ball194" type="sphere" size="0.0005" class="collision" /><site name="tendon_site194" type="sphere" size="1e-5" group="1" /></body><body name="taxel195" pos="1.035714e-02 1.450000e-02 1.000000e-03" euler="0 0 0"><inertial mass="4.444444e-09" pos="0 0 0" fullinertia="8.888889e-13 8.888889e-13 8.888889e-13 0 0 0" /><joint name="slide_joint195" type="slide" axis="0 0 1" springdamper="0.002 0.9" frictionloss="1e-2" group="1" /><geom name="ball195" type="sphere" size="0.0005" class="collision" /><site name="tendon_site195" type="sphere" size="1e-5" group="1" /></body><body name="taxel196" pos="1.242857e-02 -1.450000e-02 1.000000e-03" euler="0 0 0"><inertial mass="4.444444e-09" pos="0 0 0" fullinertia="8.888889e-13 8.888889e-13 8.888889e-13 0 0 0" /><joint name="slide_joint196" type="slide" axis="0 0 1" springdamper="0.002 0.9" frictionloss="1e-2" group="1" /><geom name="ball196" type="sphere" size="0.0005" class="collision" /><site name="tendon_site196" type="sphere" size="1e-5" group="1" /></body><body name="taxel197" pos="1.242857e-02 -1.242857e-02 1.000000e-03" euler="0 0 0"><inertial mass="4.444444e-09" pos="0 0 0" fullinertia="8.888889e-13 8.888889e-13 8.888889e-13 0 0 0" /><joint name="slide_joint197" type="slide" axis="0 0 1" springdamper="0.002 0.9" frictionloss="1e-2" group="1" /><geom name="ball197" type="sphere" size="0.0005" class="collision" /><site name="tendon_site197" type="sphere" size="1e-5" group="1" /></body><body name="taxel198" pos="1.242857e-02 -1.035714e-02 1.000000e-03" euler="0 0 0"><inertial mass="4.444444e-09" pos="0 0 0" fullinertia="8.888889e-13 8.888889e-13 8.888889e-13 0 0 0" /><joint name="slide_joint198" type="slide" axis="0 0 1" springdamper="0.002 0.9" frictionloss="1e-2" group="1" /><geom name="ball198" type="sphere" size="0.0005" class="collision" /><site name="tendon_site198" type="sphere" size="1e-5" group="1" /></body><body name="taxel199" pos="1.242857e-02 -8.285714e-03 1.000000e-03" euler="0 0 0"><inertial mass="4.444444e-09" pos="0 0 0" fullinertia="8.888889e-13 8.888889e-13 8.888889e-13 0 0 0" /><joint name="slide_joint199" type="slide" axis="0 0 1" springdamper="0.002 0.9" frictionloss="1e-2" group="1" /><geom name="ball199" type="sphere" size="0.0005" class="collision" /><site name="tendon_site199" type="sphere" size="1e-5" group="1" /></body><body name="taxel200" pos="1.242857e-02 -6.214286e-03 1.000000e-03" euler="0 0 0"><inertial mass="4.444444e-09" pos="0 0 0" fullinertia="8.888889e-13 8.888889e-13 8.888889e-13 0 0 0" /><joint name="slide_joint200" type="slide" axis="0 0 1" springdamper="0.002 0.9" frictionloss="1e-2" group="1" /><geom name="ball200" type="sphere" size="0.0005" class="collision" /><site name="tendon_site200" type="sphere" size="1e-5" group="1" /></body><body name="taxel201" pos="1.242857e-02 -4.142857e-03 1.000000e-03" euler="0 0 0"><inertial mass="4.444444e-09" pos="0 0 0" fullinertia="8.888889e-13 8.888889e-13 8.888889e-13 0 0 0" /><joint name="slide_joint201" type="slide" axis="0 0 1" springdamper="0.002 0.9" frictionloss="1e-2" group="1" /><geom name="ball201" type="sphere" size="0.0005" class="collision" /><site name="tendon_site201" type="sphere" size="1e-5" group="1" /></body><body name="taxel202" pos="1.242857e-02 -2.071429e-03 1.000000e-03" euler="0 0 0"><inertial mass="4.444444e-09" pos="0 0 0" fullinertia="8.888889e-13 8.888889e-13 8.888889e-13 0 0 0" /><joint name="slide_joint202" type="slide" axis="0 0 1" springdamper="0.002 0.9" frictionloss="1e-2" group="1" /><geom name="ball202" type="sphere" size="0.0005" class="collision" /><site name="tendon_site202" type="sphere" size="1e-5" group="1" /></body><body name="taxel203" pos="1.242857e-02 0.000000e+00 1.000000e-03" euler="0 0 0"><inertial mass="4.444444e-09" pos="0 0 0" fullinertia="8.888889e-13 8.888889e-13 8.888889e-13 0 0 0" /><joint name="slide_joint203" type="slide" axis="0 0 1" springdamper="0.002 0.9" frictionloss="1e-2" group="1" /><geom name="ball203" type="sphere" size="0.0005" class="collision" /><site name="tendon_site203" type="sphere" size="1e-5" group="1" /></body><body name="taxel204" pos="1.242857e-02 2.071429e-03 1.000000e-03" euler="0 0 0"><inertial mass="4.444444e-09" pos="0 0 0" fullinertia="8.888889e-13 8.888889e-13 8.888889e-13 0 0 0" /><joint name="slide_joint204" type="slide" axis="0 0 1" springdamper="0.002 0.9" frictionloss="1e-2" group="1" /><geom name="ball204" type="sphere" size="0.0005" class="collision" /><site name="tendon_site204" type="sphere" size="1e-5" group="1" /></body><body name="taxel205" pos="1.242857e-02 4.142857e-03 1.000000e-03" euler="0 0 0"><inertial mass="4.444444e-09" pos="0 0 0" fullinertia="8.888889e-13 8.888889e-13 8.888889e-13 0 0 0" /><joint name="slide_joint205" type="slide" axis="0 0 1" springdamper="0.002 0.9" frictionloss="1e-2" group="1" /><geom name="ball205" type="sphere" size="0.0005" class="collision" /><site name="tendon_site205" type="sphere" size="1e-5" group="1" /></body><body name="taxel206" pos="1.242857e-02 6.214286e-03 1.000000e-03" euler="0 0 0"><inertial mass="4.444444e-09" pos="0 0 0" fullinertia="8.888889e-13 8.888889e-13 8.888889e-13 0 0 0" /><joint name="slide_joint206" type="slide" axis="0 0 1" springdamper="0.002 0.9" frictionloss="1e-2" group="1" /><geom name="ball206" type="sphere" size="0.0005" class="collision" /><site name="tendon_site206" type="sphere" size="1e-5" group="1" /></body><body name="taxel207" pos="1.242857e-02 8.285714e-03 1.000000e-03" euler="0 0 0"><inertial mass="4.444444e-09" pos="0 0 0" fullinertia="8.888889e-13 8.888889e-13 8.888889e-13 0 0 0" /><joint name="slide_joint207" type="slide" axis="0 0 1" springdamper="0.002 0.9" frictionloss="1e-2" group="1" /><geom name="ball207" type="sphere" size="0.0005" class="collision" /><site name="tendon_site207" type="sphere" size="1e-5" group="1" /></body><body name="taxel208" pos="1.242857e-02 1.035714e-02 1.000000e-03" euler="0 0 0"><inertial mass="4.444444e-09" pos="0 0 0" fullinertia="8.888889e-13 8.888889e-13 8.888889e-13 0 0 0" /><joint name="slide_joint208" type="slide" axis="0 0 1" springdamper="0.002 0.9" frictionloss="1e-2" group="1" /><geom name="ball208" type="sphere" size="0.0005" class="collision" /><site name="tendon_site208" type="sphere" size="1e-5" group="1" /></body><body name="taxel209" pos="1.242857e-02 1.242857e-02 1.000000e-03" euler="0 0 0"><inertial mass="4.444444e-09" pos="0 0 0" fullinertia="8.888889e-13 8.888889e-13 8.888889e-13 0 0 0" /><joint name="slide_joint209" type="slide" axis="0 0 1" springdamper="0.002 0.9" frictionloss="1e-2" group="1" /><geom name="ball209" type="sphere" size="0.0005" class="collision" /><site name="tendon_site209" type="sphere" size="1e-5" group="1" /></body><body name="taxel210" pos="1.242857e-02 1.450000e-02 1.000000e-03" euler="0 0 0"><inertial mass="4.444444e-09" pos="0 0 0" fullinertia="8.888889e-13 8.888889e-13 8.888889e-13 0 0 0" /><joint name="slide_joint210" type="slide" axis="0 0 1" springdamper="0.002 0.9" frictionloss="1e-2" group="1" /><geom name="ball210" type="sphere" size="0.0005" class="collision" /><site name="tendon_site210" type="sphere" size="1e-5" group="1" /></body><body name="taxel211" pos="1.450000e-02 -1.450000e-02 1.000000e-03" euler="0 0 0"><inertial mass="4.444444e-09" pos="0 0 0" fullinertia="8.888889e-13 8.888889e-13 8.888889e-13 0 0 0" /><joint name="slide_joint211" type="slide" axis="0 0 1" springdamper="0.002 0.9" frictionloss="1e-2" group="1" /><geom name="ball211" type="sphere" size="0.0005" class="collision" /><site name="tendon_site211" type="sphere" size="1e-5" group="1" /></body><body name="taxel212" pos="1.450000e-02 -1.242857e-02 1.000000e-03" euler="0 0 0"><inertial mass="4.444444e-09" pos="0 0 0" fullinertia="8.888889e-13 8.888889e-13 8.888889e-13 0 0 0" /><joint name="slide_joint212" type="slide" axis="0 0 1" springdamper="0.002 0.9" frictionloss="1e-2" group="1" /><geom name="ball212" type="sphere" size="0.0005" class="collision" /><site name="tendon_site212" type="sphere" size="1e-5" group="1" /></body><body name="taxel213" pos="1.450000e-02 -1.035714e-02 1.000000e-03" euler="0 0 0"><inertial mass="4.444444e-09" pos="0 0 0" fullinertia="8.888889e-13 8.888889e-13 8.888889e-13 0 0 0" /><joint name="slide_joint213" type="slide" axis="0 0 1" springdamper="0.002 0.9" frictionloss="1e-2" group="1" /><geom name="ball213" type="sphere" size="0.0005" class="collision" /><site name="tendon_site213" type="sphere" size="1e-5" group="1" /></body><body name="taxel214" pos="1.450000e-02 -8.285714e-03 1.000000e-03" euler="0 0 0"><inertial mass="4.444444e-09" pos="0 0 0" fullinertia="8.888889e-13 8.888889e-13 8.888889e-13 0 0 0" /><joint name="slide_joint214" type="slide" axis="0 0 1" springdamper="0.002 0.9" frictionloss="1e-2" group="1" /><geom name="ball214" type="sphere" size="0.0005" class="collision" /><site name="tendon_site214" type="sphere" size="1e-5" group="1" /></body><body name="taxel215" pos="1.450000e-02 -6.214286e-03 1.000000e-03" euler="0 0 0"><inertial mass="4.444444e-09" pos="0 0 0" fullinertia="8.888889e-13 8.888889e-13 8.888889e-13 0 0 0" /><joint name="slide_joint215" type="slide" axis="0 0 1" springdamper="0.002 0.9" frictionloss="1e-2" group="1" /><geom name="ball215" type="sphere" size="0.0005" class="collision" /><site name="tendon_site215" type="sphere" size="1e-5" group="1" /></body><body name="taxel216" pos="1.450000e-02 -4.142857e-03 1.000000e-03" euler="0 0 0"><inertial mass="4.444444e-09" pos="0 0 0" fullinertia="8.888889e-13 8.888889e-13 8.888889e-13 0 0 0" /><joint name="slide_joint216" type="slide" axis="0 0 1" springdamper="0.002 0.9" frictionloss="1e-2" group="1" /><geom name="ball216" type="sphere" size="0.0005" class="collision" /><site name="tendon_site216" type="sphere" size="1e-5" group="1" /></body><body name="taxel217" pos="1.450000e-02 -2.071429e-03 1.000000e-03" euler="0 0 0"><inertial mass="4.444444e-09" pos="0 0 0" fullinertia="8.888889e-13 8.888889e-13 8.888889e-13 0 0 0" /><joint name="slide_joint217" type="slide" axis="0 0 1" springdamper="0.002 0.9" frictionloss="1e-2" group="1" /><geom name="ball217" type="sphere" size="0.0005" class="collision" /><site name="tendon_site217" type="sphere" size="1e-5" group="1" /></body><body name="taxel218" pos="1.450000e-02 0.000000e+00 1.000000e-03" euler="0 0 0"><inertial mass="4.444444e-09" pos="0 0 0" fullinertia="8.888889e-13 8.888889e-13 8.888889e-13 0 0 0" /><joint name="slide_joint218" type="slide" axis="0 0 1" springdamper="0.002 0.9" frictionloss="1e-2" group="1" /><geom name="ball218" type="sphere" size="0.0005" class="collision" /><site name="tendon_site218" type="sphere" size="1e-5" group="1" /></body><body name="taxel219" pos="1.450000e-02 2.071429e-03 1.000000e-03" euler="0 0 0"><inertial mass="4.444444e-09" pos="0 0 0" fullinertia="8.888889e-13 8.888889e-13 8.888889e-13 0 0 0" /><joint name="slide_joint219" type="slide" axis="0 0 1" springdamper="0.002 0.9" frictionloss="1e-2" group="1" /><geom name="ball219" type="sphere" size="0.0005" class="collision" /><site name="tendon_site219" type="sphere" size="1e-5" group="1" /></body><body name="taxel220" pos="1.450000e-02 4.142857e-03 1.000000e-03" euler="0 0 0"><inertial mass="4.444444e-09" pos="0 0 0" fullinertia="8.888889e-13 8.888889e-13 8.888889e-13 0 0 0" /><joint name="slide_joint220" type="slide" axis="0 0 1" springdamper="0.002 0.9" frictionloss="1e-2" group="1" /><geom name="ball220" type="sphere" size="0.0005" class="collision" /><site name="tendon_site220" type="sphere" size="1e-5" group="1" /></body><body name="taxel221" pos="1.450000e-02 6.214286e-03 1.000000e-03" euler="0 0 0"><inertial mass="4.444444e-09" pos="0 0 0" fullinertia="8.888889e-13 8.888889e-13 8.888889e-13 0 0 0" /><joint name="slide_joint221" type="slide" axis="0 0 1" springdamper="0.002 0.9" frictionloss="1e-2" group="1" /><geom name="ball221" type="sphere" size="0.0005" class="collision" /><site name="tendon_site221" type="sphere" size="1e-5" group="1" /></body><body name="taxel222" pos="1.450000e-02 8.285714e-03 1.000000e-03" euler="0 0 0"><inertial mass="4.444444e-09" pos="0 0 0" fullinertia="8.888889e-13 8.888889e-13 8.888889e-13 0 0 0" /><joint name="slide_joint222" type="slide" axis="0 0 1" springdamper="0.002 0.9" frictionloss="1e-2" group="1" /><geom name="ball222" type="sphere" size="0.0005" class="collision" /><site name="tendon_site222" type="sphere" size="1e-5" group="1" /></body><body name="taxel223" pos="1.450000e-02 1.035714e-02 1.000000e-03" euler="0 0 0"><inertial mass="4.444444e-09" pos="0 0 0" fullinertia="8.888889e-13 8.888889e-13 8.888889e-13 0 0 0" /><joint name="slide_joint223" type="slide" axis="0 0 1" springdamper="0.002 0.9" frictionloss="1e-2" group="1" /><geom name="ball223" type="sphere" size="0.0005" class="collision" /><site name="tendon_site223" type="sphere" size="1e-5" group="1" /></body><body name="taxel224" pos="1.450000e-02 1.242857e-02 1.000000e-03" euler="0 0 0"><inertial mass="4.444444e-09" pos="0 0 0" fullinertia="8.888889e-13 8.888889e-13 8.888889e-13 0 0 0" /><joint name="slide_joint224" type="slide" axis="0 0 1" springdamper="0.002 0.9" frictionloss="1e-2" group="1" /><geom name="ball224" type="sphere" size="0.0005" class="collision" /><site name="tendon_site224" type="sphere" size="1e-5" group="1" /></body><body name="taxel225" pos="1.450000e-02 1.450000e-02 1.000000e-03" euler="0 0 0"><inertial mass="4.444444e-09" pos="0 0 0" fullinertia="8.888889e-13 8.888889e-13 8.888889e-13 0 0 0" /><joint name="slide_joint225" type="slide" axis="0 0 1" springdamper="0.002 0.9" frictionloss="1e-2" group="1" /><geom name="ball225" type="sphere" size="0.0005" class="collision" /><site name="tendon_site225" type="sphere" size="1e-5" group="1" /></body></body>
                        <site name="attachment_site" pos="0 -6e-3 0" euler="3.1415926 0 0" class="ik" />
                      </body>
                    </body>
                  </body>
                </body>
              </body>
            </body>
          </body>
        </body>
      </body>
    </body>
  </worldbody>

  <actuator>
    <general class="panda" name="actuator1" joint="joint1" gainprm="4500" biasprm="0 -4500 -450" />
    <general class="panda" name="actuator2" joint="joint2" gainprm="4500" biasprm="0 -4500 -450" ctrlrange="-1.7628 1.7628" />
    <general class="panda" name="actuator3" joint="joint3" gainprm="3500" biasprm="0 -3500 -350" />
    <general class="panda" name="actuator4" joint="joint4" gainprm="3500" biasprm="0 -3500 -350" ctrlrange="-3.0718 -0.0698" />
    <general class="panda" name="actuator5" joint="joint5" gainprm="2000" biasprm="0 -2000 -200" forcerange="-12 12" />
    <general class="panda" name="actuator6" joint="joint6" gainprm="2000" biasprm="0 -2000 -200" forcerange="-12 12" ctrlrange="-0.0175 3.7525" />
    <general class="panda" name="actuator7" joint="joint7" gainprm="2000" biasprm="0 -2000 -200" forcerange="-12 12" />
  </actuator>
  <tendon /><sensor /></mujoco>